Workbook

Sheet Ring
A1: STT (SP) | B1: Khách hàng | C1: Mã Khách hàng | D1: Tên sản phẩm | E1: Mã sản phẩm | F1: Mã VF mới | G1: Giá sản phẩm | J1: Nguyên liệu | K1: Đường kính | L1: Chiều dài | M1: Giá nguyên liệu sản phẩm | T1: Giá gia công | Z1: Giá xi mạ | AC1: Tình trạng đặt hàng
G2: VND | H2: USD | M2: Chiều dài tổng | N2: Đường kính sử dụng | O2: Hệ số tương ứng với đường kính | P2: Trọng lượng sản phẩm đầu vào (gam ) | Q2: Giá nguyên liệu | R2: Giá nguyên liệu của sản phẩm | S2: Tỉ lệ nguyên liệu so với giá bán | T2: Gia công 1 | U2: năng suất | V2: Thành tiền | W2: Gia công 2 | X2: Thành tiền | Y2: Tổng giá gia công | Z2: Y/c xi mạ | AA2: giá xi mạ ( VNd/kg) | AB2: Giá xi mạ từng sản phẩm
A3: 1 | C3: D2B | E3: 741632100 | F3: R2100 | H3: 0.5141 | J3: A6061-T6 | K3: ø 19.8 (ø 17.9) | L3: 4 | M3: =(L3+(IF(K3<=4,1.5,IF(K3<=7,2,IF(K3<=11,2.5,IF(K3<=19,3,IF(K3<=25,3.5,4)))))))*1.1 -> 8.8 | O3: =2*2*0.66 -> 2.64 | P3: =M3*O3 -> 23.232 | Q3: 120000 | R3: =Q3/1000*P3 -> 2787.84 | S3: =IF(G3<>0,R3/G3*100,R3/(H3*21000)*100) -> 25.822658
A4: =1+A3 -> 2 | C4: D2B | E4: 741623100 | F4: R3100 | H4: 0.273 | J4: A6061-T6 | K4: ø 15 (ø 13) | L4: 4 | M4: =(L4+(IF(K4<=4,1.5,IF(K4<=7,2,IF(K4<=11,2.5,IF(K4<=19,3,IF(K4<=25,3.5,4)))))))*1.1 -> 8.8 | N4: 15 | O4: =1.5*1.5*0.66 -> 1.485 | P4: =M4*O4 -> 13.068 | Q4: 120000 | R4: =Q4/1000*P4 -> 1568.16 | S4: =IF(G4<>0,R4/G4*100,R4/(H4*21000)*100) -> 27.353218
A5: =1+A4 -> 3 | C5: D2B | E5: 751623100 | F5: R3100A | H5: 0.43 | J5: A6061-T6 | K5: ø 15 (ø 13) | L5: 4 | M5: =(L5+(IF(K5<=4,1.5,IF(K5<=7,2,IF(K5<=11,2.5,IF(K5<=19,3,IF(K5<=25,3.5,4)))))))*1.1 -> 8.8 | N5: 15 | O5: =1.5*1.5*0.66 -> 1.485 | P5: =M5*O5 -> 13.068 | Q5: 120000 | R5: =Q5/1000*P5 -> 1568.16 | S5: =IF(G5<>0,R5/G5*100,R5/(H5*21000)*100) -> 17.366113
A6: =1+A5 -> 4 | C6: D2B | E6: 741633600 | F6: R3600B | H6: 0.55 | J6: A6061-T6 | K6: ø 22 (ø 18.5) | L6: 16.5 | M6: =(L6+(IF(K6<=4,1.5,IF(K6<=7,2,IF(K6<=11,2.5,IF(K6<=19,3,IF(K6<=25,3.5,4)))))))*1.1 -> 22.55 | N6: 22 | O6: =2.2*2.2*0.66 -> 3.1944 | P6: =M6*O6 -> 72.03372 | Q6: 120000 | R6: =Q6/1000*P6 -> 8644.0464 | S6: =IF(G6<>0,R6/G6*100,R6/(H6*21000)*100) -> 74.840229
A7: =1+A6 -> 5 | C7: D2B | E7: 741633610 | F7: R3610 | H7: 0.55 | J7: A6061-T6 | K7: ø 22 (ø 18.5) | L7: 16.5 | M7: =(L7+(IF(K7<=4,1.5,IF(K7<=7,2,IF(K7<=11,2.5,IF(K7<=19,3,IF(K7<=25,3.5,4)))))))*1.1 -> 22.55 | N7: 22 | O7: =2.2*2.2*0.66 -> 3.1944 | P7: =M7*O7 -> 72.03372 | Q7: 120000 | R7: =Q7/1000*P7 -> 8644.0464 | S7: =IF(G7<>0,R7/G7*100,R7/(H7*21000)*100) -> 74.840229
A8: =1+A7 -> 6 | C8: D2B | E8: 741633700 | F8: R3700A | H8: 0.34 | J8: A6061-T6 | K8: ø 25.4 (ø 23.2) | L8: 5 | M8: =(L8+(IF(K8<=4,1.5,IF(K8<=7,2,IF(K8<=11,2.5,IF(K8<=19,3,IF(K8<=25,3.5,4)))))))*1.1 -> 9.9 | O8: =2.55*2.55*0.66 -> 4.29165 | P8: =M8*O8 -> 42.487335 | Q8: 120000 | R8: =Q8/1000*P8 -> 5098.4802 | S8: =IF(G8<>0,R8/G8*100,R8/(H8*21000)*100) -> 71.407286
A9: =1+A8 -> 7 | C9: D2B | E9: 741633701 | F9: R3701 | H9: 0.79 | J9: A6061-T6 | K9: ø 25.4 | L9: 5 | M9: =(L9+(IF(K9<=4,1.5,IF(K9<=7,2,IF(K9<=11,2.5,IF(K9<=19,3,IF(K9<=25,3.5,4)))))))*1.1 -> 9.9 | O9: =2.55*2.55*0.66 -> 4.29165 | P9: =M9*O9 -> 42.487335 | Q9: 120000 | R9: =Q9/1000*P9 -> 5098.4802 | S9: =IF(G9<>0,R9/G9*100,R9/(H9*21000)*100) -> 30.73225
A10: =1+A9 -> 8 | C10: D2B | E10: 741633800 | F10: R3800A | H10: 0.19 | J10: A6061-T6 | K10: ø 12.4 (ø 10) | L10: 6 | M10: =(L10+(IF(K10<=4,1.5,IF(K10<=7,2,IF(K10<=11,2.5,IF(K10<=19,3,IF(K10<=25,3.5,4)))))))*1.1 -> 11 | O10: =1.25*1.25*0.66 -> 1.03125 | P10: =M10*O10 -> 11.34375 | Q10: 120000 | R10: =Q10/1000*P10 -> 1361.25 | S10: =IF(G10<>0,R10/G10*100,R10/(H10*21000)*100) -> 34.116541
A11: =1+A10 -> 9 | C11: D2B | E11: 741633801 | F11: R3801 | H11: 0.42 | J11: A6061-T6 | K11: ø 12.4 (ø 10) | L11: 6 | M11: =(L11+(IF(K11<=4,1.5,IF(K11<=7,2,IF(K11<=11,2.5,IF(K11<=19,3,IF(K11<=25,3.5,4)))))))*1.1 -> 11 | O11: =1.25*1.25*0.66 -> 1.03125 | P11: =M11*O11 -> 11.34375 | Q11: 120000 | R11: =Q11/1000*P11 -> 1361.25 | S11: =IF(G11<>0,R11/G11*100,R11/(H11*21000)*100) -> 15.433673
A12: =1+A11 -> 10 | C12: D2B | E12: 741633810 | F12: R3810 | H12: 0.19 | J12: A6061-T6 | K12: ø 12.4 (ø 9) | L12: 6 | M12: =(L12+(IF(K12<=4,1.5,IF(K12<=7,2,IF(K12<=11,2.5,IF(K12<=19,3,IF(K12<=25,3.5,4)))))))*1.1 -> 11 | O12: =1.25*1.25*0.66 -> 1.03125 | P12: =M12*O12 -> 11.34375 | Q12: 120000 | R12: =Q12/1000*P12 -> 1361.25 | S12: =IF(G12<>0,R12/G12*100,R12/(H12*21000)*100) -> 34.116541
A13: =1+A12 -> 11 | C13: D2B | E13: 741633811 | F13: R3811 | H13: 0.44 | J13: A6061-T6 | K13: ø 12.4 (ø 9) | L13: 6 | M13: =(L13+(IF(K13<=4,1.5,IF(K13<=7,2,IF(K13<=11,2.5,IF(K13<=19,3,IF(K13<=25,3.5,4)))))))*1.1 -> 11 | O13: =1.25*1.25*0.66 -> 1.03125 | P13: =M13*O13 -> 11.34375 | Q13: 120000 | R13: =Q13/1000*P13 -> 1361.25 | S13: =IF(G13<>0,R13/G13*100,R13/(H13*21000)*100) -> 14.732143
A14: =1+A13 -> 12 | C14: D2B | E14: 741633820 | F14: R3820 | H14: 0.19 | J14: A6061-T6 | K14: ø 12.4 (ø 9.5) | L14: 6 | M14: =(L14+(IF(K14<=4,1.5,IF(K14<=7,2,IF(K14<=11,2.5,IF(K14<=19,3,IF(K14<=25,3.5,4)))))))*1.1 -> 11 | O14: =1.25*1.25*0.66 -> 1.03125 | P14: =M14*O14 -> 11.34375 | Q14: 120000 | R14: =Q14/1000*P14 -> 1361.25 | S14: =IF(G14<>0,R14/G14*100,R14/(H14*21000)*100) -> 34.116541
A15: =1+A14 -> 13 | C15: D2B | E15: 741633821 | F15: R3821 | H15: 0.43 | J15: A6061-T6 | K15: ø 12.4 (ø 9.5) | L15: 6 | M15: =(L15+(IF(K15<=4,1.5,IF(K15<=7,2,IF(K15<=11,2.5,IF(K15<=19,3,IF(K15<=25,3.5,4)))))))*1.1 -> 11 | O15: =1.25*1.25*0.66 -> 1.03125 | P15: =M15*O15 -> 11.34375 | Q15: 120000 | R15: =Q15/1000*P15 -> 1361.25 | S15: =IF(G15<>0,R15/G15*100,R15/(H15*21000)*100) -> 15.074751
A16: =1+A15 -> 14 | C16: D2B | E16: 741633900 | F16: R3900A | H16: 0.33 | J16: A6061-T6 | K16: ø 23.7 (ø 21.8) | L16: 5 | M16: =(L16+(IF(K16<=4,1.5,IF(K16<=7,2,IF(K16<=11,2.5,IF(K16<=19,3,IF(K16<=25,3.5,4)))))))*1.1 -> 9.9 | O16: =2.37*2.37*0.66 -> 3.707154 | P16: =M16*O16 -> 36.700825 | Q16: 120000 | R16: =Q16/1000*P16 -> 4404.099 | S16: =IF(G16<>0,R16/G16*100,R16/(H16*21000)*100) -> 63.551211
A17: =1+A16 -> 15 | C17: D2B | E17: 741624200 | F17: R4200 | H17: 0.556 | J17: A6061-T6 | K17: ø 23.8 (ø 18) | L17: 2 | M17: =(L17+(IF(K17<=4,1.5,IF(K17<=7,2,IF(K17<=11,2.5,IF(K17<=19,3,IF(K17<=25,3.5,4)))))))*1.1 -> 6.6 | O17: =2.38*2.38*0.66 -> 3.738504 | P17: =M17*O17 -> 24.674126 | Q17: 120000 | R17: =Q17/1000*P17 -> 2960.8952 | S17: =IF(G17<>0,R17/G17*100,R17/(H17*21000)*100) -> 25.358814
A18: =1+A17 -> 16 | C18: D2B | E18: 741634800 | F18: R4800A | H18: 0.57 | J18: A6061-T6 | K18: ø 8 (ø 6.05) | L18: 24 | M18: =(L18+(IF(K18<=4,1.5,IF(K18<=7,2,IF(K18<=11,2.5,IF(K18<=19,3,IF(K18<=25,3.5,4)))))))*1.1 -> 30.8 | N18: 8 | O18: 0.42 | P18: =M18*O18 -> 12.936 | Q18: 120000 | R18: =Q18/1000*P18 -> 1552.32 | S18: =IF(G18<>0,R18/G18*100,R18/(H18*21000)*100) -> 12.968421
A19: =1+A18 -> 17 | C19: D2B | E19: 741634900 | F19: R4900A | H19: 0.32 | J19: A6061-T6 | K19: ø 11 (ø 6.05) | L19: 2.5 | M19: =(L19+(IF(K19<=4,1.5,IF(K19<=7,2,IF(K19<=11,2.5,IF(K19<=19,3,IF(K19<=25,3.5,4)))))))*1.1 -> 7.15 | N19: 11 | O19: =1.1*1.1*0.66 -> 0.7986 | P19: =M19*O19 -> 5.70999 | Q19: 120000 | R19: =Q19/1000*P19 -> 685.1988 | S19: =IF(G19<>0,R19/G19*100,R19/(H19*21000)*100) -> 10.196411
A20: =1+A19 -> 18 | C20: D2B | E20: 741634910 | F20: R4910 | H20: 0.32 | J20: A6061-T6 | K20: ø 11 (ø 7.05) | L20: 2.5 | M20: =(L20+(IF(K20<=4,1.5,IF(K20<=7,2,IF(K20<=11,2.5,IF(K20<=19,3,IF(K20<=25,3.5,4)))))))*1.1 -> 7.15 | N20: 11 | O20: =1.1*1.1*0.66 -> 0.7986 | P20: =M20*O20 -> 5.70999 | Q20: 120000 | R20: =Q20/1000*P20 -> 685.1988 | S20: =IF(G20<>0,R20/G20*100,R20/(H20*21000)*100) -> 10.196411
A21: =1+A20 -> 19 | C21: D2B | E21: 741634920 | F21: R4920 | H21: 0.32 | J21: A6061-T6 | K21: ø 11 (ø 7.55) | L21: 2.5 | M21: =(L21+(IF(K21<=4,1.5,IF(K21<=7,2,IF(K21<=11,2.5,IF(K21<=19,3,IF(K21<=25,3.5,4)))))))*1.1 -> 7.15 | N21: 11 | O21: =1.1*1.1*0.66 -> 0.7986 | P21: =M21*O21 -> 5.70999 | Q21: 120000 | R21: =Q21/1000*P21 -> 685.1988 | S21: =IF(G21<>0,R21/G21*100,R21/(H21*21000)*100) -> 10.196411
A22: =1+A21 -> 20 | C22: D2B | E22: 746095600 | F22: R5600 | H22: 1.52 | J22: A6061-T6 | K22: ø 24.4+ (ø 21.1) | L22: 20.6 | M22: =(L22+(IF(K22<=4,1.5,IF(K22<=7,2,IF(K22<=11,2.5,IF(K22<=19,3,IF(K22<=25,3.5,4)))))))*1.1 -> 27.06 | O22: =2.44*2.44*0.66 -> 3.929376 | P22: =M22*O22 -> 106.32891 | Q22: 120000 | R22: =Q22/1000*P22 -> 12759.47 | S22: =IF(G22<>0,R22/G22*100,R22/(H22*21000)*100) -> 39.973276
A23: =1+A22 -> 21 | C23: D2B | E23: 746095700 | F23: R5700 | H23: 1.28 | J23: A6061-T6 | K23: ø 24.8+ (ø 23.4) | L23: 16 | M23: =(L23+(IF(K23<=4,1.5,IF(K23<=7,2,IF(K23<=11,2.5,IF(K23<=19,3,IF(K23<=25,3.5,4)))))))*1.1 -> 22 | O23: =2.48*2.48*0.66 -> 4.059264 | P23: =M23*O23 -> 89.303808 | Q23: 120000 | R23: =Q23/1000*P23 -> 10716.457 | S23: =IF(G23<>0,R23/G23*100,R23/(H23*21000)*100) -> 39.867771
A24: =1+A23 -> 22 | C24: D2B | E24: 741636300 | F24: R6300 | H24: 0.61 | J24: A6061-T6 | K24: ø 9 (ø 7.05) | L24: 24 | M24: =(L24+(IF(K24<=4,1.5,IF(K24<=7,2,IF(K24<=11,2.5,IF(K24<=19,3,IF(K24<=25,3.5,4)))))))*1.1 -> 30.8 | N24: 9 | O24: 0.54 | P24: =M24*O24 -> 16.632 | Q24: 120000 | R24: =Q24/1000*P24 -> 1995.84 | S24: =IF(G24<>0,R24/G24*100,R24/(H24*21000)*100) -> 15.580328
A25: =1+A24 -> 23 | C25: D2B | E25: 805806301 | F25: R6301 | H25: 0.18 | J25: A6061-T6 | K25: ø 20.5+ (ø17) | L25: 4 | M25: =(L25+(IF(K25<=4,1.5,IF(K25<=7,2,IF(K25<=11,2.5,IF(K25<=19,3,IF(K25<=25,3.5,4)))))))*1.1 -> 8.8 | O25: =2.05*2.05*0.66 -> 2.77365 | P25: =M25*O25 -> 24.40812 | Q25: 120000 | R25: =Q25/1000*P25 -> 2928.9744 | S25: =IF(G25<>0,R25/G25*100,R25/(H25*21000)*100) -> 77.486095
A26: =1+A25 -> 24 | C26: D2B | E26: 741636400 | F26: R6400 | H26: 0.63 | J26: A6061-T6 | K26: ø 9.5 (ø 7.55) | L26: 24 | M26: =(L26+(IF(K26<=4,1.5,IF(K26<=7,2,IF(K26<=11,2.5,IF(K26<=19,3,IF(K26<=25,3.5,4)))))))*1.1 -> 30.8 | N26: 9.5 | O26: 0.6 | P26: =M26*O26 -> 18.48 | Q26: 120000 | R26: =Q26/1000*P26 -> 2217.6 | S26: =IF(G26<>0,R26/G26*100,R26/(H26*21000)*100) -> 16.761905
A27: =1+A26 -> 25 | C27: D2B | E27: 805806500 | F27: R6500 | H27: 0.185 | J27: A6061-T6 | K27: ø 22 (ø19.7) | L27: 4 | M27: =(L27+(IF(K27<=4,1.5,IF(K27<=7,2,IF(K27<=11,2.5,IF(K27<=19,3,IF(K27<=25,3.5,4)))))))*1.1 -> 8.8 | N27: 22 | O27: =2.2*2.2*0.66 -> 3.1944 | P27: =M27*O27 -> 28.11072 | Q27: 120000 | R27: =Q27/1000*P27 -> 3373.2864 | S27: =IF(G27<>0,R27/G27*100,R27/(H27*21000)*100) -> 86.828479
A28: =1+A27 -> 26 | C28: D2B | E28: 741626800 | F28: R6800 | H28: 0.3491 | J28: A6061-T6 | K28: ø 9 (ø 6.05) | L28: 4 | M28: =(L28+(IF(K28<=4,1.5,IF(K28<=7,2,IF(K28<=11,2.5,IF(K28<=19,3,IF(K28<=25,3.5,4)))))))*1.1 -> 8.8 | N28: 9 | O28: 0.54 | P28: =M28*O28 -> 4.752 | Q28: 120000 | R28: =Q28/1000*P28 -> 570.24 | S28: =IF(G28<>0,R28/G28*100,R28/(H28*21000)*100) -> 7.7783689
A29: =1+A28 -> 27 | C29: D2B | E29: 741627000 | F29: R7000 | H29: 0.44 | J29: A6061-T6 | K29: ø 13.5 (ø 9.05) | L29: 5 | M29: =(L29+(IF(K29<=4,1.5,IF(K29<=7,2,IF(K29<=11,2.5,IF(K29<=19,3,IF(K29<=25,3.5,4)))))))*1.1 -> 9.9 | N29: 13.5 | O29: =1.35*1.35*0.66 -> 1.20285 | P29: =M29*O29 -> 11.908215 | Q29: 120000 | R29: =Q29/1000*P29 -> 1428.9858 | S29: =IF(G29<>0,R29/G29*100,R29/(H29*21000)*100) -> 15.465214
A30: =1+A29 -> 28 | C30: D2B | E30: 741627010 | F30: R7010 | H30: 0.44 | M30: =(L30+(IF(K30<=4,1.5,IF(K30<=7,2,IF(K30<=11,2.5,IF(K30<=19,3,IF(K30<=25,3.5,4)))))))*1.1 -> 1.65 | P30: =M30*O30 -> 0 | R30: =Q30/1000*P30 -> 0 | S30: =IF(G30<>0,R30/G30*100,R30/(H30*21000)*100) -> 0
A31: =1+A30 -> 29 | C31: D2B | E31: 741627020 | F31: R7020 | H31: 0.44 | M31: =(L31+(IF(K31<=4,1.5,IF(K31<=7,2,IF(K31<=11,2.5,IF(K31<=19,3,IF(K31<=25,3.5,4)))))))*1.1 -> 1.65 | P31: =M31*O31 -> 0 | R31: =Q31/1000*P31 -> 0 | S31: =IF(G31<>0,R31/G31*100,R31/(H31*21000)*100) -> 0
A32: =1+A31 -> 30 | C32: D2B | E32: 741627400 | F32: R7400A | H32: 0.4 | J32: A6061-T6 | K32: ø 14 (ø 10.05) | L32: 5 | M32: =(L32+(IF(K32<=4,1.5,IF(K32<=7,2,IF(K32<=11,2.5,IF(K32<=19,3,IF(K32<=25,3.5,4)))))))*1.1 -> 9.9 | N32: 14 | O32: =1.4*1.4*0.66 -> 1.2936 | P32: =M32*O32 -> 12.80664 | Q32: 120000 | R32: =Q32/1000*P32 -> 1536.7968 | S32: =IF(G32<>0,R32/G32*100,R32/(H32*21000)*100) -> 18.2952
A33: =1+A32 -> 31 | C33: D2B | E33: 741627410 | F33: R7410A | H33: 0.39 | J33: A6061-T6 | K33: ø 14 (ø 10.55) | L33: 5 | M33: =(L33+(IF(K33<=4,1.5,IF(K33<=7,2,IF(K33<=11,2.5,IF(K33<=19,3,IF(K33<=25,3.5,4)))))))*1.1 -> 9.9 | N33: 14 | O33: =1.4*1.4*0.66 -> 1.2936 | P33: =M33*O33 -> 12.80664 | Q33: 120000 | R33: =Q33/1000*P33 -> 1536.7968 | S33: =IF(G33<>0,R33/G33*100,R33/(H33*21000)*100) -> 18.764308
A34: =1+A33 -> 32 | C34: D2B | E34: 741627600 | F34: R7600 | H34: 0.3105 | J34: A6061-T6 | K34: ø 16.5 (ø 12.55) | L34: 5 | M34: =(L34+(IF(K34<=4,1.5,IF(K34<=7,2,IF(K34<=11,2.5,IF(K34<=19,3,IF(K34<=25,3.5,4)))))))*1.1 -> 9.9 | N34: 16.5 | O34: =1.65*1.65*0.66 -> 1.79685 | P34: =M34*O34 -> 17.788815 | Q34: 120000 | R34: =Q34/1000*P34 -> 2134.6578 | S34: =IF(G34<>0,R34/G34*100,R34/(H34*21000)*100) -> 32.73764
A35: =1+A34 -> 33 | C35: D2B | E35: 741497830 | F35: R7830 | H35: 0.4044 | J35: A6061-T6 | K35: ø 17 (ø 12.05) | L35: 5 | M35: =(L35+(IF(K35<=4,1.5,IF(K35<=7,2,IF(K35<=11,2.5,IF(K35<=19,3,IF(K35<=25,3.5,4)))))))*1.1 -> 9.9 | N35: 17 | O35: =1.7*1.7*0.66 -> 1.9074 | P35: =M35*O35 -> 18.88326 | Q35: 120000 | R35: =Q35/1000*P35 -> 2265.9912 | S35: =IF(G35<>0,R35/G35*100,R35/(H35*21000)*100) -> 26.682577
A36: =1+A35 -> 34 | C36: D2B | E36: 741488100 | F36: R8100 | H36: 0.5756 | J36: A6061-T6 | K36: ø 23.8 (ø 18.1) | L36: 4 | M36: =(L36+(IF(K36<=4,1.5,IF(K36<=7,2,IF(K36<=11,2.5,IF(K36<=19,3,IF(K36<=25,3.5,4)))))))*1.1 -> 8.8 | O36: =2.38*2.38*0.66 -> 3.738504 | P36: =M36*O36 -> 32.898835 | Q36: 120000 | R36: =Q36/1000*P36 -> 3947.8602 | S36: =IF(G36<>0,R36/G36*100,R36/(H36*21000)*100) -> 32.660414
A37: =1+A36 -> 35 | C37: D2B | E37: 741628600 | F37: R8600 | H37: 0.3332 | J37: A6061-T6 | K37: ø 15 (ø11.05) | L37: 3 | M37: =(L37+(IF(K37<=4,1.5,IF(K37<=7,2,IF(K37<=11,2.5,IF(K37<=19,3,IF(K37<=25,3.5,4)))))))*1.1 -> 7.7 | N37: 15 | O37: =1.5*1.5*0.66 -> 1.485 | P37: =M37*O37 -> 11.4345 | Q37: 120000 | R37: =Q37/1000*P37 -> 1372.14 | S37: =IF(G37<>0,R37/G37*100,R37/(H37*21000)*100) -> 19.609844
A38: =1+A37 -> 36 | C38: D2B | E38: 741499020 | F38: R9020 | H38: 0.4 | J38: A6061-T6 | K38: ø 15 (ø 10.15) | L38: 3 | M38: =(L38+(IF(K38<=4,1.5,IF(K38<=7,2,IF(K38<=11,2.5,IF(K38<=19,3,IF(K38<=25,3.5,4)))))))*1.1 -> 7.7 | N38: 15 | O38: =1.5*1.5*0.66 -> 1.485 | P38: =M38*O38 -> 11.4345 | Q38: 120000 | R38: =Q38/1000*P38 -> 1372.14 | S38: =IF(G38<>0,R38/G38*100,R38/(H38*21000)*100) -> 16.335
A39: =1+A38 -> 37 | C39: D2B | E39: 741499030 | F39: R9030 | H39: 0.4 | J39: A6061-T6 | K39: ø 15 (ø7.65) | L39: 3 | M39: =(L39+(IF(K39<=4,1.5,IF(K39<=7,2,IF(K39<=11,2.5,IF(K39<=19,3,IF(K39<=25,3.5,4)))))))*1.1 -> 7.7 | N39: 15 | O39: =1.5*1.5*0.66 -> 1.485 | P39: =M39*O39 -> 11.4345 | Q39: 120000 | R39: =Q39/1000*P39 -> 1372.14 | S39: =IF(G39<>0,R39/G39*100,R39/(H39*21000)*100) -> 16.335
A40: =1+A39 -> 38 | C40: D2B | E40: 741619200 | F40: R9200 | H40: 0.52 | J40: A6061-T6 | K40: ø 25.3 (ø 20) | L40: 2 | M40: =(L40+(IF(K40<=4,1.5,IF(K40<=7,2,IF(K40<=11,2.5,IF(K40<=19,3,IF(K40<=25,3.5,4)))))))*1.1 -> 6.6 | O40: =2.53*2.53*0.66 -> 4.224594 | P40: =M40*O40 -> 27.88232 | Q40: 120000 | R40: =Q40/1000*P40 -> 3345.8784 | S40: =IF(G40<>0,R40/G40*100,R40/(H40*21000)*100) -> 30.639913
...

Sheet don hang
A1: PO No | B1: KH Code | C1: VF Code | D1: Đơn giá | E1: =Info!B16 -> 43221 | F1: =Info!B19 -> 43252 | G1: =Info!B22 -> 43282 | H1: TOTAL | I1: Order Price
E2: =SUM(E3:E920) -> #REF! | F2: =SUM(F3:F920) -> #REF! | G2: =SUM(G3:G920) -> #REF! | H2: =SUM(E2:G2) -> #REF!
A3: =IF(B3="","", Info!$B$2) -> DVN-FP3330-180404 | B3: 6G1525020 | C3: =IF(B3="","",IFERROR(VLOOKUP(B3,Reel!$E$3:$F$1013,2,0),VLOOKUP(B3,Ring!$E$3:$F$1000,2,0))) -> #N/A | D3: =IF(C3="","",IFERROR(VLOOKUP(C3,Reel!$F$2:$H$1013,3,0),VLOOKUP(C3,Ring!$F$3:$H$1000,3,0))) -> #N/A | E3: =IF(B3="","",SUMIFS(INDIRECT("'["&Info!$B$5&"]"&Info!$B$6&"'!"&Info!$B$11),INDIRECT("'["&Info!$B$5&"]"&Info!$B$6&"'!"&Info!$B$9),B3,INDIRECT("'["&Info!$B$5&"]"&Info!$B$6&"'!"&Info!$B$15),">="&Info!$B$17,INDIRECT("'["&Info!$B$5&"]"&Info!$B$6&"'!"&Info!$B$15),"<="&Info!$B$18)) -> #REF! | F3: =IF(B3="","",SUMIFS(INDIRECT("'["&Info!$B$5&"]"&Info!$B$6&"'!"&Info!$B$11),INDIRECT("'["&Info!$B$5&"]"&Info!$B$6&"'!"&Info!$B$9),B3,INDIRECT("'["&Info!$B$5&"]"&Info!$B$6&"'!"&Info!$B$15),">="&Info!$B$20,INDIRECT("'["&Info!$B$5&"]"&Info!$B$6&"'!"&Info!$B$15),"<="&Info!$B$21)) -> #REF! | G3: =IF(B3="","",SUMIFS(INDIRECT("'["&Info!$B$5&"]"&Info!$B$6&"'!"&Info!$B$11),INDIRECT("'["&Info!$B$5&"]"&Info!$B$6&"'!"&Info!$B$9),B3,INDIRECT("'["&Info!$B$5&"]"&Info!$B$6&"'!"&Info!$B$15),">="&Info!$B$23,INDIRECT("'["&Info!$B$5&"]"&Info!$B$6&"'!"&Info!$B$15),"<="&Info!$B$24)) -> #REF! | H3: =SUM(E3:G3) -> #REF! | I3: =IF(B3="","",IFERROR(SUMIF(INDIRECT("'["&Info!$B$5&"]"&Info!$B$6&"'!"&Info!$B$9),B3,INDIRECT("'["&Info!$B$5&"]"&Info!$B$6&"'!"&Info!$B$13))/COUNTIF(INDIRECT("'["&Info!$B$5&"]"&Info!$B$6&"'!"&Info!$B$9),B3),D3)) -> #N/A
A4: =IF(B4="","", Info!$B$2) -> DVN-FP3330-180404 | B4: 6H0191011 | C4: =IF(B4="","",IFERROR(VLOOKUP(B4,Reel!$E$3:$F$1013,2,0),VLOOKUP(B4,Ring!$E$3:$F$1000,2,0))) -> #N/A | D4: =IF(C4="","",IFERROR(VLOOKUP(C4,Reel!$F$2:$H$1013,3,0),VLOOKUP(C4,Ring!$F$3:$H$1000,3,0))) -> #N/A | E4: =IF(B4="","",SUMIFS(INDIRECT("'["&Info!$B$5&"]"&Info!$B$6&"'!"&Info!$B$11),INDIRECT("'["&Info!$B$5&"]"&Info!$B$6&"'!"&Info!$B$9),B4,INDIRECT("'["&Info!$B$5&"]"&Info!$B$6&"'!"&Info!$B$15),">="&Info!$B$17,INDIRECT("'["&Info!$B$5&"]"&Info!$B$6&"'!"&Info!$B$15),"<="&Info!$B$18)) -> #REF! | F4: =IF(B4="","",SUMIFS(INDIRECT("'["&Info!$B$5&"]"&Info!$B$6&"'!"&Info!$B$11),INDIRECT("'["&Info!$B$5&"]"&Info!$B$6&"'!"&Info!$B$9),B4,INDIRECT("'["&Info!$B$5&"]"&Info!$B$6&"'!"&Info!$B$15),">="&Info!$B$20,INDIRECT("'["&Info!$B$5&"]"&Info!$B$6&"'!"&Info!$B$15),"<="&Info!$B$21)) -> #REF! | G4: =IF(B4="","",SUMIFS(INDIRECT("'["&Info!$B$5&"]"&Info!$B$6&"'!"&Info!$B$11),INDIRECT("'["&Info!$B$5&"]"&Info!$B$6&"'!"&Info!$B$9),B4,INDIRECT("'["&Info!$B$5&"]"&Info!$B$6&"'!"&Info!$B$15),">="&Info!$B$23,INDIRECT("'["&Info!$B$5&"]"&Info!$B$6&"'!"&Info!$B$15),"<="&Info!$B$24)) -> #REF! | H4: =SUM(E4:G4) -> #REF! | I4: =IF(B4="","",IFERROR(SUMIF(INDIRECT("'["&Info!$B$5&"]"&Info!$B$6&"'!"&Info!$B$9),B4,INDIRECT("'["&Info!$B$5&"]"&Info!$B$6&"'!"&Info!$B$13))/COUNTIF(INDIRECT("'["&Info!$B$5&"]"&Info!$B$6&"'!"&Info!$B$9),B4),D4)) -> #N/A
A5: =IF(B5="","", Info!$B$2) -> DVN-FP3330-180404 | B5: 6G9810011 | C5: =IF(B5="","",IFERROR(VLOOKUP(B5,Reel!$E$3:$F$1013,2,0),VLOOKUP(B5,Ring!$E$3:$F$1000,2,0))) -> #N/A | D5: =IF(C5="","",IFERROR(VLOOKUP(C5,Reel!$F$2:$H$1013,3,0),VLOOKUP(C5,Ring!$F$3:$H$1000,3,0))) -> #N/A | E5: =IF(B5="","",SUMIFS(INDIRECT("'["&Info!$B$5&"]"&Info!$B$6&"'!"&Info!$B$11),INDIRECT("'["&Info!$B$5&"]"&Info!$B$6&"'!"&Info!$B$9),B5,INDIRECT("'["&Info!$B$5&"]"&Info!$B$6&"'!"&Info!$B$15),">="&Info!$B$17,INDIRECT("'["&Info!$B$5&"]"&Info!$B$6&"'!"&Info!$B$15),"<="&Info!$B$18)) -> #REF! | F5: =IF(B5="","",SUMIFS(INDIRECT("'["&Info!$B$5&"]"&Info!$B$6&"'!"&Info!$B$11),INDIRECT("'["&Info!$B$5&"]"&Info!$B$6&"'!"&Info!$B$9),B5,INDIRECT("'["&Info!$B$5&"]"&Info!$B$6&"'!"&Info!$B$15),">="&Info!$B$20,INDIRECT("'["&Info!$B$5&"]"&Info!$B$6&"'!"&Info!$B$15),"<="&Info!$B$21)) -> #REF! | G5: =IF(B5="","",SUMIFS(INDIRECT("'["&Info!$B$5&"]"&Info!$B$6&"'!"&Info!$B$11),INDIRECT("'["&Info!$B$5&"]"&Info!$B$6&"'!"&Info!$B$9),B5,INDIRECT("'["&Info!$B$5&"]"&Info!$B$6&"'!"&Info!$B$15),">="&Info!$B$23,INDIRECT("'["&Info!$B$5&"]"&Info!$B$6&"'!"&Info!$B$15),"<="&Info!$B$24)) -> #REF! | H5: =SUM(E5:G5) -> #REF! | I5: =IF(B5="","",IFERROR(SUMIF(INDIRECT("'["&Info!$B$5&"]"&Info!$B$6&"'!"&Info!$B$9),B5,INDIRECT("'["&Info!$B$5&"]"&Info!$B$6&"'!"&Info!$B$13))/COUNTIF(INDIRECT("'["&Info!$B$5&"]"&Info!$B$6&"'!"&Info!$B$9),B5),D5)) -> #N/A
A6: =IF(B6="","", Info!$B$2) -> DVN-FP3330-180404 | B6: 6H3544011 | C6: =IF(B6="","",IFERROR(VLOOKUP(B6,Reel!$E$3:$F$1013,2,0),VLOOKUP(B6,Ring!$E$3:$F$1000,2,0))) -> #N/A | D6: =IF(C6="","",IFERROR(VLOOKUP(C6,Reel!$F$2:$H$1013,3,0),VLOOKUP(C6,Ring!$F$3:$H$1000,3,0))) -> #N/A | E6: =IF(B6="","",SUMIFS(INDIRECT("'["&Info!$B$5&"]"&Info!$B$6&"'!"&Info!$B$11),INDIRECT("'["&Info!$B$5&"]"&Info!$B$6&"'!"&Info!$B$9),B6,INDIRECT("'["&Info!$B$5&"]"&Info!$B$6&"'!"&Info!$B$15),">="&Info!$B$17,INDIRECT("'["&Info!$B$5&"]"&Info!$B$6&"'!"&Info!$B$15),"<="&Info!$B$18)) -> #REF! | F6: =IF(B6="","",SUMIFS(INDIRECT("'["&Info!$B$5&"]"&Info!$B$6&"'!"&Info!$B$11),INDIRECT("'["&Info!$B$5&"]"&Info!$B$6&"'!"&Info!$B$9),B6,INDIRECT("'["&Info!$B$5&"]"&Info!$B$6&"'!"&Info!$B$15),">="&Info!$B$20,INDIRECT("'["&Info!$B$5&"]"&Info!$B$6&"'!"&Info!$B$15),"<="&Info!$B$21)) -> #REF! | G6: =IF(B6="","",SUMIFS(INDIRECT("'["&Info!$B$5&"]"&Info!$B$6&"'!"&Info!$B$11),INDIRECT("'["&Info!$B$5&"]"&Info!$B$6&"'!"&Info!$B$9),B6,INDIRECT("'["&Info!$B$5&"]"&Info!$B$6&"'!"&Info!$B$15),">="&Info!$B$23,INDIRECT("'["&Info!$B$5&"]"&Info!$B$6&"'!"&Info!$B$15),"<="&Info!$B$24)) -> #REF! | H6: =SUM(E6:G6) -> #REF! | I6: =IF(B6="","",IFERROR(SUMIF(INDIRECT("'["&Info!$B$5&"]"&Info!$B$6&"'!"&Info!$B$9),B6,INDIRECT("'["&Info!$B$5&"]"&Info!$B$6&"'!"&Info!$B$13))/COUNTIF(INDIRECT("'["&Info!$B$5&"]"&Info!$B$6&"'!"&Info!$B$9),B6),D6)) -> #N/A
A7: =IF(B7="","", Info!$B$2) -> DVN-FP3330-180404 | B7: 6H0499010 | C7: =IF(B7="","",IFERROR(VLOOKUP(B7,Reel!$E$3:$F$1013,2,0),VLOOKUP(B7,Ring!$E$3:$F$1000,2,0))) -> #N/A | D7: =IF(C7="","",IFERROR(VLOOKUP(C7,Reel!$F$2:$H$1013,3,0),VLOOKUP(C7,Ring!$F$3:$H$1000,3,0))) -> #N/A | E7: =IF(B7="","",SUMIFS(INDIRECT("'["&Info!$B$5&"]"&Info!$B$6&"'!"&Info!$B$11),INDIRECT("'["&Info!$B$5&"]"&Info!$B$6&"'!"&Info!$B$9),B7,INDIRECT("'["&Info!$B$5&"]"&Info!$B$6&"'!"&Info!$B$15),">="&Info!$B$17,INDIRECT("'["&Info!$B$5&"]"&Info!$B$6&"'!"&Info!$B$15),"<="&Info!$B$18)) -> #REF! | F7: =IF(B7="","",SUMIFS(INDIRECT("'["&Info!$B$5&"]"&Info!$B$6&"'!"&Info!$B$11),INDIRECT("'["&Info!$B$5&"]"&Info!$B$6&"'!"&Info!$B$9),B7,INDIRECT("'["&Info!$B$5&"]"&Info!$B$6&"'!"&Info!$B$15),">="&Info!$B$20,INDIRECT("'["&Info!$B$5&"]"&Info!$B$6&"'!"&Info!$B$15),"<="&Info!$B$21)) -> #REF! | G7: =IF(B7="","",SUMIFS(INDIRECT("'["&Info!$B$5&"]"&Info!$B$6&"'!"&Info!$B$11),INDIRECT("'["&Info!$B$5&"]"&Info!$B$6&"'!"&Info!$B$9),B7,INDIRECT("'["&Info!$B$5&"]"&Info!$B$6&"'!"&Info!$B$15),">="&Info!$B$23,INDIRECT("'["&Info!$B$5&"]"&Info!$B$6&"'!"&Info!$B$15),"<="&Info!$B$24)) -> #REF! | H7: =SUM(E7:G7) -> #REF! | I7: =IF(B7="","",IFERROR(SUMIF(INDIRECT("'["&Info!$B$5&"]"&Info!$B$6&"'!"&Info!$B$9),B7,INDIRECT("'["&Info!$B$5&"]"&Info!$B$6&"'!"&Info!$B$13))/COUNTIF(INDIRECT("'["&Info!$B$5&"]"&Info!$B$6&"'!"&Info!$B$9),B7),D7)) -> #N/A
A8: =IF(B8="","", Info!$B$2) -> DVN-FP3330-180404 | B8: 6G1768020 | C8: =IF(B8="","",IFERROR(VLOOKUP(B8,Reel!$E$3:$F$1013,2,0),VLOOKUP(B8,Ring!$E$3:$F$1000,2,0))) -> #N/A | D8: =IF(C8="","",IFERROR(VLOOKUP(C8,Reel!$F$2:$H$1013,3,0),VLOOKUP(C8,Ring!$F$3:$H$1000,3,0))) -> #N/A | E8: =IF(B8="","",SUMIFS(INDIRECT("'["&Info!$B$5&"]"&Info!$B$6&"'!"&Info!$B$11),INDIRECT("'["&Info!$B$5&"]"&Info!$B$6&"'!"&Info!$B$9),B8,INDIRECT("'["&Info!$B$5&"]"&Info!$B$6&"'!"&Info!$B$15),">="&Info!$B$17,INDIRECT("'["&Info!$B$5&"]"&Info!$B$6&"'!"&Info!$B$15),"<="&Info!$B$18)) -> #REF! | F8: =IF(B8="","",SUMIFS(INDIRECT("'["&Info!$B$5&"]"&Info!$B$6&"'!"&Info!$B$11),INDIRECT("'["&Info!$B$5&"]"&Info!$B$6&"'!"&Info!$B$9),B8,INDIRECT("'["&Info!$B$5&"]"&Info!$B$6&"'!"&Info!$B$15),">="&Info!$B$20,INDIRECT("'["&Info!$B$5&"]"&Info!$B$6&"'!"&Info!$B$15),"<="&Info!$B$21)) -> #REF! | G8: =IF(B8="","",SUMIFS(INDIRECT("'["&Info!$B$5&"]"&Info!$B$6&"'!"&Info!$B$11),INDIRECT("'["&Info!$B$5&"]"&Info!$B$6&"'!"&Info!$B$9),B8,INDIRECT("'["&Info!$B$5&"]"&Info!$B$6&"'!"&Info!$B$15),">="&Info!$B$23,INDIRECT("'["&Info!$B$5&"]"&Info!$B$6&"'!"&Info!$B$15),"<="&Info!$B$24)) -> #REF! | H8: =SUM(E8:G8) -> #REF! | I8: =IF(B8="","",IFERROR(SUMIF(INDIRECT("'["&Info!$B$5&"]"&Info!$B$6&"'!"&Info!$B$9),B8,INDIRECT("'["&Info!$B$5&"]"&Info!$B$6&"'!"&Info!$B$13))/COUNTIF(INDIRECT("'["&Info!$B$5&"]"&Info!$B$6&"'!"&Info!$B$9),B8),D8)) -> #N/A
A9: =IF(B9="","", Info!$B$2) -> DVN-FP3330-180404 | B9: 6H3554010 | C9: =IF(B9="","",IFERROR(VLOOKUP(B9,Reel!$E$3:$F$1013,2,0),VLOOKUP(B9,Ring!$E$3:$F$1000,2,0))) -> #N/A | D9: =IF(C9="","",IFERROR(VLOOKUP(C9,Reel!$F$2:$H$1013,3,0),VLOOKUP(C9,Ring!$F$3:$H$1000,3,0))) -> #N/A | E9: =IF(B9="","",SUMIFS(INDIRECT("'["&Info!$B$5&"]"&Info!$B$6&"'!"&Info!$B$11),INDIRECT("'["&Info!$B$5&"]"&Info!$B$6&"'!"&Info!$B$9),B9,INDIRECT("'["&Info!$B$5&"]"&Info!$B$6&"'!"&Info!$B$15),">="&Info!$B$17,INDIRECT("'["&Info!$B$5&"]"&Info!$B$6&"'!"&Info!$B$15),"<="&Info!$B$18)) -> #REF! | F9: =IF(B9="","",SUMIFS(INDIRECT("'["&Info!$B$5&"]"&Info!$B$6&"'!"&Info!$B$11),INDIRECT("'["&Info!$B$5&"]"&Info!$B$6&"'!"&Info!$B$9),B9,INDIRECT("'["&Info!$B$5&"]"&Info!$B$6&"'!"&Info!$B$15),">="&Info!$B$20,INDIRECT("'["&Info!$B$5&"]"&Info!$B$6&"'!"&Info!$B$15),"<="&Info!$B$21)) -> #REF! | G9: =IF(B9="","",SUMIFS(INDIRECT("'["&Info!$B$5&"]"&Info!$B$6&"'!"&Info!$B$11),INDIRECT("'["&Info!$B$5&"]"&Info!$B$6&"'!"&Info!$B$9),B9,INDIRECT("'["&Info!$B$5&"]"&Info!$B$6&"'!"&Info!$B$15),">="&Info!$B$23,INDIRECT("'["&Info!$B$5&"]"&Info!$B$6&"'!"&Info!$B$15),"<="&Info!$B$24)) -> #REF! | H9: =SUM(E9:G9) -> #REF! | I9: =IF(B9="","",IFERROR(SUMIF(INDIRECT("'["&Info!$B$5&"]"&Info!$B$6&"'!"&Info!$B$9),B9,INDIRECT("'["&Info!$B$5&"]"&Info!$B$6&"'!"&Info!$B$13))/COUNTIF(INDIRECT("'["&Info!$B$5&"]"&Info!$B$6&"'!"&Info!$B$9),B9),D9)) -> #N/A
A10: =IF(B10="","", Info!$B$2) -> DVN-FP3330-180404 | B10: 6G5101010 | C10: =IF(B10="","",IFERROR(VLOOKUP(B10,Reel!$E$3:$F$1013,2,0),VLOOKUP(B10,Ring!$E$3:$F$1000,2,0))) -> #N/A | D10: =IF(C10="","",IFERROR(VLOOKUP(C10,Reel!$F$2:$H$1013,3,0),VLOOKUP(C10,Ring!$F$3:$H$1000,3,0))) -> #N/A | E10: =IF(B10="","",SUMIFS(INDIRECT("'["&Info!$B$5&"]"&Info!$B$6&"'!"&Info!$B$11),INDIRECT("'["&Info!$B$5&"]"&Info!$B$6&"'!"&Info!$B$9),B10,INDIRECT("'["&Info!$B$5&"]"&Info!$B$6&"'!"&Info!$B$15),">="&Info!$B$17,INDIRECT("'["&Info!$B$5&"]"&Info!$B$6&"'!"&Info!$B$15),"<="&Info!$B$18)) -> #REF! | F10: =IF(B10="","",SUMIFS(INDIRECT("'["&Info!$B$5&"]"&Info!$B$6&"'!"&Info!$B$11),INDIRECT("'["&Info!$B$5&"]"&Info!$B$6&"'!"&Info!$B$9),B10,INDIRECT("'["&Info!$B$5&"]"&Info!$B$6&"'!"&Info!$B$15),">="&Info!$B$20,INDIRECT("'["&Info!$B$5&"]"&Info!$B$6&"'!"&Info!$B$15),"<="&Info!$B$21)) -> #REF! | G10: =IF(B10="","",SUMIFS(INDIRECT("'["&Info!$B$5&"]"&Info!$B$6&"'!"&Info!$B$11),INDIRECT("'["&Info!$B$5&"]"&Info!$B$6&"'!"&Info!$B$9),B10,INDIRECT("'["&Info!$B$5&"]"&Info!$B$6&"'!"&Info!$B$15),">="&Info!$B$23,INDIRECT("'["&Info!$B$5&"]"&Info!$B$6&"'!"&Info!$B$15),"<="&Info!$B$24)) -> #REF! | H10: =SUM(E10:G10) -> #REF! | I10: =IF(B10="","",IFERROR(SUMIF(INDIRECT("'["&Info!$B$5&"]"&Info!$B$6&"'!"&Info!$B$9),B10,INDIRECT("'["&Info!$B$5&"]"&Info!$B$6&"'!"&Info!$B$13))/COUNTIF(INDIRECT("'["&Info!$B$5&"]"&Info!$B$6&"'!"&Info!$B$9),B10),D10)) -> #N/A
A11: =IF(B11="","", Info!$B$2) -> DVN-FP3330-180404 | B11: 6B6854010 | C11: =IF(B11="","",IFERROR(VLOOKUP(B11,Reel!$E$3:$F$1013,2,0),VLOOKUP(B11,Ring!$E$3:$F$1000,2,0))) -> #N/A | D11: =IF(C11="","",IFERROR(VLOOKUP(C11,Reel!$F$2:$H$1013,3,0),VLOOKUP(C11,Ring!$F$3:$H$1000,3,0))) -> #N/A | E11: =IF(B11="","",SUMIFS(INDIRECT("'["&Info!$B$5&"]"&Info!$B$6&"'!"&Info!$B$11),INDIRECT("'["&Info!$B$5&"]"&Info!$B$6&"'!"&Info!$B$9),B11,INDIRECT("'["&Info!$B$5&"]"&Info!$B$6&"'!"&Info!$B$15),">="&Info!$B$17,INDIRECT("'["&Info!$B$5&"]"&Info!$B$6&"'!"&Info!$B$15),"<="&Info!$B$18)) -> #REF! | F11: =IF(B11="","",SUMIFS(INDIRECT("'["&Info!$B$5&"]"&Info!$B$6&"'!"&Info!$B$11),INDIRECT("'["&Info!$B$5&"]"&Info!$B$6&"'!"&Info!$B$9),B11,INDIRECT("'["&Info!$B$5&"]"&Info!$B$6&"'!"&Info!$B$15),">="&Info!$B$20,INDIRECT("'["&Info!$B$5&"]"&Info!$B$6&"'!"&Info!$B$15),"<="&Info!$B$21)) -> #REF! | G11: =IF(B11="","",SUMIFS(INDIRECT("'["&Info!$B$5&"]"&Info!$B$6&"'!"&Info!$B$11),INDIRECT("'["&Info!$B$5&"]"&Info!$B$6&"'!"&Info!$B$9),B11,INDIRECT("'["&Info!$B$5&"]"&Info!$B$6&"'!"&Info!$B$15),">="&Info!$B$23,INDIRECT("'["&Info!$B$5&"]"&Info!$B$6&"'!"&Info!$B$15),"<="&Info!$B$24)) -> #REF! | H11: =SUM(E11:G11) -> #REF! | I11: =IF(B11="","",IFERROR(SUMIF(INDIRECT("'["&Info!$B$5&"]"&Info!$B$6&"'!"&Info!$B$9),B11,INDIRECT("'["&Info!$B$5&"]"&Info!$B$6&"'!"&Info!$B$13))/COUNTIF(INDIRECT("'["&Info!$B$5&"]"&Info!$B$6&"'!"&Info!$B$9),B11),D11)) -> #N/A
A12: =IF(B12="","", Info!$B$2) -> DVN-FP3330-180404 | B12: 6H5762011 | C12: =IF(B12="","",IFERROR(VLOOKUP(B12,Reel!$E$3:$F$1013,2,0),VLOOKUP(B12,Ring!$E$3:$F$1000,2,0))) -> #N/A | D12: =IF(C12="","",IFERROR(VLOOKUP(C12,Reel!$F$2:$H$1013,3,0),VLOOKUP(C12,Ring!$F$3:$H$1000,3,0))) -> #N/A | E12: =IF(B12="","",SUMIFS(INDIRECT("'["&Info!$B$5&"]"&Info!$B$6&"'!"&Info!$B$11),INDIRECT("'["&Info!$B$5&"]"&Info!$B$6&"'!"&Info!$B$9),B12,INDIRECT("'["&Info!$B$5&"]"&Info!$B$6&"'!"&Info!$B$15),">="&Info!$B$17,INDIRECT("'["&Info!$B$5&"]"&Info!$B$6&"'!"&Info!$B$15),"<="&Info!$B$18)) -> #REF! | F12: =IF(B12="","",SUMIFS(INDIRECT("'["&Info!$B$5&"]"&Info!$B$6&"'!"&Info!$B$11),INDIRECT("'["&Info!$B$5&"]"&Info!$B$6&"'!"&Info!$B$9),B12,INDIRECT("'["&Info!$B$5&"]"&Info!$B$6&"'!"&Info!$B$15),">="&Info!$B$20,INDIRECT("'["&Info!$B$5&"]"&Info!$B$6&"'!"&Info!$B$15),"<="&Info!$B$21)) -> #REF! | G12: =IF(B12="","",SUMIFS(INDIRECT("'["&Info!$B$5&"]"&Info!$B$6&"'!"&Info!$B$11),INDIRECT("'["&Info!$B$5&"]"&Info!$B$6&"'!"&Info!$B$9),B12,INDIRECT("'["&Info!$B$5&"]"&Info!$B$6&"'!"&Info!$B$15),">="&Info!$B$23,INDIRECT("'["&Info!$B$5&"]"&Info!$B$6&"'!"&Info!$B$15),"<="&Info!$B$24)) -> #REF! | H12: =SUM(E12:G12) -> #REF! | I12: =IF(B12="","",IFERROR(SUMIF(INDIRECT("'["&Info!$B$5&"]"&Info!$B$6&"'!"&Info!$B$9),B12,INDIRECT("'["&Info!$B$5&"]"&Info!$B$6&"'!"&Info!$B$13))/COUNTIF(INDIRECT("'["&Info!$B$5&"]"&Info!$B$6&"'!"&Info!$B$9),B12),D12)) -> #N/A
A13: =IF(B13="","", Info!$B$2) -> DVN-FP3330-180404 | B13: 6B6825010 | C13: =IF(B13="","",IFERROR(VLOOKUP(B13,Reel!$E$3:$F$1013,2,0),VLOOKUP(B13,Ring!$E$3:$F$1000,2,0))) -> #N/A | D13: =IF(C13="","",IFERROR(VLOOKUP(C13,Reel!$F$2:$H$1013,3,0),VLOOKUP(C13,Ring!$F$3:$H$1000,3,0))) -> #N/A | E13: =IF(B13="","",SUMIFS(INDIRECT("'["&Info!$B$5&"]"&Info!$B$6&"'!"&Info!$B$11),INDIRECT("'["&Info!$B$5&"]"&Info!$B$6&"'!"&Info!$B$9),B13,INDIRECT("'["&Info!$B$5&"]"&Info!$B$6&"'!"&Info!$B$15),">="&Info!$B$17,INDIRECT("'["&Info!$B$5&"]"&Info!$B$6&"'!"&Info!$B$15),"<="&Info!$B$18)) -> #REF! | F13: =IF(B13="","",SUMIFS(INDIRECT("'["&Info!$B$5&"]"&Info!$B$6&"'!"&Info!$B$11),INDIRECT("'["&Info!$B$5&"]"&Info!$B$6&"'!"&Info!$B$9),B13,INDIRECT("'["&Info!$B$5&"]"&Info!$B$6&"'!"&Info!$B$15),">="&Info!$B$20,INDIRECT("'["&Info!$B$5&"]"&Info!$B$6&"'!"&Info!$B$15),"<="&Info!$B$21)) -> #REF! | G13: =IF(B13="","",SUMIFS(INDIRECT("'["&Info!$B$5&"]"&Info!$B$6&"'!"&Info!$B$11),INDIRECT("'["&Info!$B$5&"]"&Info!$B$6&"'!"&Info!$B$9),B13,INDIRECT("'["&Info!$B$5&"]"&Info!$B$6&"'!"&Info!$B$15),">="&Info!$B$23,INDIRECT("'["&Info!$B$5&"]"&Info!$B$6&"'!"&Info!$B$15),"<="&Info!$B$24)) -> #REF! | H13: =SUM(E13:G13) -> #REF! | I13: =IF(B13="","",IFERROR(SUMIF(INDIRECT("'["&Info!$B$5&"]"&Info!$B$6&"'!"&Info!$B$9),B13,INDIRECT("'["&Info!$B$5&"]"&Info!$B$6&"'!"&Info!$B$13))/COUNTIF(INDIRECT("'["&Info!$B$5&"]"&Info!$B$6&"'!"&Info!$B$9),B13),D13)) -> #N/A
A14: =IF(B14="","", Info!$B$2) -> DVN-FP3330-180404 | B14: 6G3686010 | C14: =IF(B14="","",IFERROR(VLOOKUP(B14,Reel!$E$3:$F$1013,2,0),VLOOKUP(B14,Ring!$E$3:$F$1000,2,0))) -> #N/A | D14: =IF(C14="","",IFERROR(VLOOKUP(C14,Reel!$F$2:$H$1013,3,0),VLOOKUP(C14,Ring!$F$3:$H$1000,3,0))) -> #N/A | E14: =IF(B14="","",SUMIFS(INDIRECT("'["&Info!$B$5&"]"&Info!$B$6&"'!"&Info!$B$11),INDIRECT("'["&Info!$B$5&"]"&Info!$B$6&"'!"&Info!$B$9),B14,INDIRECT("'["&Info!$B$5&"]"&Info!$B$6&"'!"&Info!$B$15),">="&Info!$B$17,INDIRECT("'["&Info!$B$5&"]"&Info!$B$6&"'!"&Info!$B$15),"<="&Info!$B$18)) -> #REF! | F14: =IF(B14="","",SUMIFS(INDIRECT("'["&Info!$B$5&"]"&Info!$B$6&"'!"&Info!$B$11),INDIRECT("'["&Info!$B$5&"]"&Info!$B$6&"'!"&Info!$B$9),B14,INDIRECT("'["&Info!$B$5&"]"&Info!$B$6&"'!"&Info!$B$15),">="&Info!$B$20,INDIRECT("'["&Info!$B$5&"]"&Info!$B$6&"'!"&Info!$B$15),"<="&Info!$B$21)) -> #REF! | G14: =IF(B14="","",SUMIFS(INDIRECT("'["&Info!$B$5&"]"&Info!$B$6&"'!"&Info!$B$11),INDIRECT("'["&Info!$B$5&"]"&Info!$B$6&"'!"&Info!$B$9),B14,INDIRECT("'["&Info!$B$5&"]"&Info!$B$6&"'!"&Info!$B$15),">="&Info!$B$23,INDIRECT("'["&Info!$B$5&"]"&Info!$B$6&"'!"&Info!$B$15),"<="&Info!$B$24)) -> #REF! | H14: =SUM(E14:G14) -> #REF! | I14: =IF(B14="","",IFERROR(SUMIF(INDIRECT("'["&Info!$B$5&"]"&Info!$B$6&"'!"&Info!$B$9),B14,INDIRECT("'["&Info!$B$5&"]"&Info!$B$6&"'!"&Info!$B$13))/COUNTIF(INDIRECT("'["&Info!$B$5&"]"&Info!$B$6&"'!"&Info!$B$9),B14),D14)) -> #N/A
... A116: =IF(B116="","", Info!$B$2) -> DVN-FP3330-180404 | B116: 6H7265060 | C116: =IF(B116="","",IFERROR(VLOOKUP(B116,Reel!$E$3:$F$1013,2,0),VLOOKUP(B116,Ring!$E$3:$F$1000,2,0))) -> #N/A | D116: =IF(C116="","",IFERROR(VLOOKUP(C116,Reel!$F$2:$H$1013,3,0),VLOOKUP(C116,Ring!$F$3:$H$1000,3,0))) -> #N/A | E116: =IF(B116="","",SUMIFS(INDIRECT("'["&Info!$B$5&"]"&Info!$B$6&"'!"&Info!$B$11),INDIRECT("'["&Info!$B$5&"]"&Info!$B$6&"'!"&Info!$B$9),B116,INDIRECT("'["&Info!$B$5&"]"&Info!$B$6&"'!"&Info!$B$15),">="&Info!$B$17,INDIRECT("'["&Info!$B$5&"]"&Info!$B$6&"'!"&Info!$B$15),"<="&Info!$B$18)) -> #REF! | F116: =IF(B116="","",SUMIFS(INDIRECT("'["&Info!$B$5&"]"&Info!$B$6&"'!"&Info!$B$11),INDIRECT("'["&Info!$B$5&"]"&Info!$B$6&"'!"&Info!$B$9),B116,INDIRECT("'["&Info!$B$5&"]"&Info!$B$6&"'!"&Info!$B$15),">="&Info!$B$20,INDIRECT("'["&Info!$B$5&"]"&Info!$B$6&"'!"&Info!$B$15),"<="&Info!$B$21)) -> #REF! | G116: =IF(B116="","",SUMIFS(INDIRECT("'["&Info!$B$5&"]"&Info!$B$6&"'!"&Info!$B$11),INDIRECT("'["&Info!$B$5&"]"&Info!$B$6&"'!"&Info!$B$9),B116,INDIRECT("'["&Info!$B$5&"]"&Info!$B$6&"'!"&Info!$B$15),">="&Info!$B$23,INDIRECT("'["&Info!$B$5&"]"&Info!$B$6&"'!"&Info!$B$15),"<="&Info!$B$24)) -> #REF! | H116: =SUM(E116:G116) -> #REF! | I116: =IF(B116="","",IFERROR(SUMIF(INDIRECT("'["&Info!$B$5&"]"&Info!$B$6&"'!"&Info!$B$9),B116,INDIRECT("'["&Info!$B$5&"]"&Info!$B$6&"'!"&Info!$B$13))/COUNTIF(INDIRECT("'["&Info!$B$5&"]"&Info!$B$6&"'!"&Info!$B$9),B116),D116)) -> #N/A
A117: =IF(B117="","", Info!$B$2) -> DVN-FP3330-180404 | B117: 6H7265061 | C117: =IF(B117="","",IFERROR(VLOOKUP(B117,Reel!$E$3:$F$1013,2,0),VLOOKUP(B117,Ring!$E$3:$F$1000,2,0))) -> #N/A | D117: =IF(C117="","",IFERROR(VLOOKUP(C117,Reel!$F$2:$H$1013,3,0),VLOOKUP(C117,Ring!$F$3:$H$1000,3,0))) -> #N/A | E117: =IF(B117="","",SUMIFS(INDIRECT("'["&Info!$B$5&"]"&Info!$B$6&"'!"&Info!$B$11),INDIRECT("'["&Info!$B$5&"]"&Info!$B$6&"'!"&Info!$B$9),B117,INDIRECT("'["&Info!$B$5&"]"&Info!$B$6&"'!"&Info!$B$15),">="&Info!$B$17,INDIRECT("'["&Info!$B$5&"]"&Info!$B$6&"'!"&Info!$B$15),"<="&Info!$B$18)) -> #REF! | F117: =IF(B117="","",SUMIFS(INDIRECT("'["&Info!$B$5&"]"&Info!$B$6&"'!"&Info!$B$11),INDIRECT("'["&Info!$B$5&"]"&Info!$B$6&"'!"&Info!$B$9),B117,INDIRECT("'["&Info!$B$5&"]"&Info!$B$6&"'!"&Info!$B$15),">="&Info!$B$20,INDIRECT("'["&Info!$B$5&"]"&Info!$B$6&"'!"&Info!$B$15),"<="&Info!$B$21)) -> #REF! | G117: =IF(B117="","",SUMIFS(INDIRECT("'["&Info!$B$5&"]"&Info!$B$6&"'!"&Info!$B$11),INDIRECT("'["&Info!$B$5&"]"&Info!$B$6&"'!"&Info!$B$9),B117,INDIRECT("'["&Info!$B$5&"]"&Info!$B$6&"'!"&Info!$B$15),">="&Info!$B$23,INDIRECT("'["&Info!$B$5&"]"&Info!$B$6&"'!"&Info!$B$15),"<="&Info!$B$24)) -> #REF! | H117: =SUM(E117:G117) -> #REF! | I117: =IF(B117="","",IFERROR(SUMIF(INDIRECT("'["&Info!$B$5&"]"&Info!$B$6&"'!"&Info!$B$9),B117,INDIRECT("'["&Info!$B$5&"]"&Info!$B$6&"'!"&Info!$B$13))/COUNTIF(INDIRECT("'["&Info!$B$5&"]"&Info!$B$6&"'!"&Info!$B$9),B117),D117)) -> #N/A | M117: =24669+E2 -> #REF!
A118: =IF(B118="","", Info!$B$2) -> DVN-FP3330-180404 | B118: 6H7265071 | C118: =IF(B118="","",IFERROR(VLOOKUP(B118,Reel!$E$3:$F$1013,2,0),VLOOKUP(B118,Ring!$E$3:$F$1000,2,0))) -> #N/A | D118: =IF(C118="","",IFERROR(VLOOKUP(C118,Reel!$F$2:$H$1013,3,0),VLOOKUP(C118,Ring!$F$3:$H$1000,3,0))) -> #N/A | E118: =IF(B118="","",SUMIFS(INDIRECT("'["&Info!$B$5&"]"&Info!$B$6&"'!"&Info!$B$11),INDIRECT("'["&Info!$B$5&"]"&Info!$B$6&"'!"&Info!$B$9),B118,INDIRECT("'["&Info!$B$5&"]"&Info!$B$6&"'!"&Info!$B$15),">="&Info!$B$17,INDIRECT("'["&Info!$B$5&"]"&Info!$B$6&"'!"&Info!$B$15),"<="&Info!$B$18)) -> #REF! | F118: =IF(B118="","",SUMIFS(INDIRECT("'["&Info!$B$5&"]"&Info!$B$6&"'!"&Info!$B$11),INDIRECT("'["&Info!$B$5&"]"&Info!$B$6&"'!"&Info!$B$9),B118,INDIRECT("'["&Info!$B$5&"]"&Info!$B$6&"'!"&Info!$B$15),">="&Info!$B$20,INDIRECT("'["&Info!$B$5&"]"&Info!$B$6&"'!"&Info!$B$15),"<="&Info!$B$21)) -> #REF! | G118: =IF(B118="","",SUMIFS(INDIRECT("'["&Info!$B$5&"]"&Info!$B$6&"'!"&Info!$B$11),INDIRECT("'["&Info!$B$5&"]"&Info!$B$6&"'!"&Info!$B$9),B118,INDIRECT("'["&Info!$B$5&"]"&Info!$B$6&"'!"&Info!$B$15),">="&Info!$B$23,INDIRECT("'["&Info!$B$5&"]"&Info!$B$6&"'!"&Info!$B$15),"<="&Info!$B$24)) -> #REF! | H118: =SUM(E118:G118) -> #REF! | I118: =IF(B118="","",IFERROR(SUMIF(INDIRECT("'["&Info!$B$5&"]"&Info!$B$6&"'!"&Info!$B$9),B118,INDIRECT("'["&Info!$B$5&"]"&Info!$B$6&"'!"&Info!$B$13))/COUNTIF(INDIRECT("'["&Info!$B$5&"]"&Info!$B$6&"'!"&Info!$B$9),B118),D118)) -> #N/A
A119: =IF(B119="","", Info!$B$2) -> DVN-FP3330-180404 | B119: 6H1978020 | C119: =IF(B119="","",IFERROR(VLOOKUP(B119,Reel!$E$3:$F$1013,2,0),VLOOKUP(B119,Ring!$E$3:$F$1000,2,0))) -> #N/A | D119: =IF(C119="","",IFERROR(VLOOKUP(C119,Reel!$F$2:$H$1013,3,0),VLOOKUP(C119,Ring!$F$3:$H$1000,3,0))) -> #N/A | E119: =IF(B119="","",SUMIFS(INDIRECT("'["&Info!$B$5&"]"&Info!$B$6&"'!"&Info!$B$11),INDIRECT("'["&Info!$B$5&"]"&Info!$B$6&"'!"&Info!$B$9),B119,INDIRECT("'["&Info!$B$5&"]"&Info!$B$6&"'!"&Info!$B$15),">="&Info!$B$17,INDIRECT("'["&Info!$B$5&"]"&Info!$B$6&"'!"&Info!$B$15),"<="&Info!$B$18)) -> #REF! | F119: =IF(B119="","",SUMIFS(INDIRECT("'["&Info!$B$5&"]"&Info!$B$6&"'!"&Info!$B$11),INDIRECT("'["&Info!$B$5&"]"&Info!$B$6&"'!"&Info!$B$9),B119,INDIRECT("'["&Info!$B$5&"]"&Info!$B$6&"'!"&Info!$B$15),">="&Info!$B$20,INDIRECT("'["&Info!$B$5&"]"&Info!$B$6&"'!"&Info!$B$15),"<="&Info!$B$21)) -> #REF! | G119: =IF(B119="","",SUMIFS(INDIRECT("'["&Info!$B$5&"]"&Info!$B$6&"'!"&Info!$B$11),INDIRECT("'["&Info!$B$5&"]"&Info!$B$6&"'!"&Info!$B$9),B119,INDIRECT("'["&Info!$B$5&"]"&Info!$B$6&"'!"&Info!$B$15),">="&Info!$B$23,INDIRECT("'["&Info!$B$5&"]"&Info!$B$6&"'!"&Info!$B$15),"<="&Info!$B$24)) -> #REF! | H119: =SUM(E119:G119) -> #REF! | I119: =IF(B119="","",IFERROR(SUMIF(INDIRECT("'["&Info!$B$5&"]"&Info!$B$6&"'!"&Info!$B$9),B119,INDIRECT("'["&Info!$B$5&"]"&Info!$B$6&"'!"&Info!$B$13))/COUNTIF(INDIRECT("'["&Info!$B$5&"]"&Info!$B$6&"'!"&Info!$B$9),B119),D119)) -> #N/A
A120: =IF(B120="","", Info!$B$2) -> DVN-FP3330-180404 | B120: 6H1982020 | C120: =IF(B120="","",IFERROR(VLOOKUP(B120,Reel!$E$3:$F$1013,2,0),VLOOKUP(B120,Ring!$E$3:$F$1000,2,0))) -> #N/A | D120: =IF(C120="","",IFERROR(VLOOKUP(C120,Reel!$F$2:$H$1013,3,0),VLOOKUP(C120,Ring!$F$3:$H$1000,3,0))) -> #N/A | E120: =IF(B120="","",SUMIFS(INDIRECT("'["&Info!$B$5&"]"&Info!$B$6&"'!"&Info!$B$11),INDIRECT("'["&Info!$B$5&"]"&Info!$B$6&"'!"&Info!$B$9),B120,INDIRECT("'["&Info!$B$5&"]"&Info!$B$6&"'!"&Info!$B$15),">="&Info!$B$17,INDIRECT("'["&Info!$B$5&"]"&Info!$B$6&"'!"&Info!$B$15),"<="&Info!$B$18)) -> #REF! | F120: =IF(B120="","",SUMIFS(INDIRECT("'["&Info!$B$5&"]"&Info!$B$6&"'!"&Info!$B$11),INDIRECT("'["&Info!$B$5&"]"&Info!$B$6&"'!"&Info!$B$9),B120,INDIRECT("'["&Info!$B$5&"]"&Info!$B$6&"'!"&Info!$B$15),">="&Info!$B$20,INDIRECT("'["&Info!$B$5&"]"&Info!$B$6&"'!"&Info!$B$15),"<="&Info!$B$21)) -> #REF! | G120: =IF(B120="","",SUMIFS(INDIRECT("'["&Info!$B$5&"]"&Info!$B$6&"'!"&Info!$B$11),INDIRECT("'["&Info!$B$5&"]"&Info!$B$6&"'!"&Info!$B$9),B120,INDIRECT("'["&Info!$B$5&"]"&Info!$B$6&"'!"&Info!$B$15),">="&Info!$B$23,INDIRECT("'["&Info!$B$5&"]"&Info!$B$6&"'!"&Info!$B$15),"<="&Info!$B$24)) -> #REF! | H120: =SUM(E120:G120) -> #REF! | I120: =IF(B120="","",IFERROR(SUMIF(INDIRECT("'["&Info!$B$5&"]"&Info!$B$6&"'!"&Info!$B$9),B120,INDIRECT("'["&Info!$B$5&"]"&Info!$B$6&"'!"&Info!$B$13))/COUNTIF(INDIRECT("'["&Info!$B$5&"]"&Info!$B$6&"'!"&Info!$B$9),B120),D120)) -> #N/A
A121: =IF(B121="","", Info!$B$2) -> DVN-FP3330-180404 | B121: 6H1079021 | C121: =IF(B121="","",IFERROR(VLOOKUP(B121,Reel!$E$3:$F$1013,2,0),VLOOKUP(B121,Ring!$E$3:$F$1000,2,0))) -> #N/A | D121: =IF(C121="","",IFERROR(VLOOKUP(C121,Reel!$F$2:$H$1013,3,0),VLOOKUP(C121,Ring!$F$3:$H$1000,3,0))) -> #N/A | E121: =IF(B121="","",SUMIFS(INDIRECT("'["&Info!$B$5&"]"&Info!$B$6&"'!"&Info!$B$11),INDIRECT("'["&Info!$B$5&"]"&Info!$B$6&"'!"&Info!$B$9),B121,INDIRECT("'["&Info!$B$5&"]"&Info!$B$6&"'!"&Info!$B$15),">="&Info!$B$17,INDIRECT("'["&Info!$B$5&"]"&Info!$B$6&"'!"&Info!$B$15),"<="&Info!$B$18)) -> #REF! | F121: =IF(B121="","",SUMIFS(INDIRECT("'["&Info!$B$5&"]"&Info!$B$6&"'!"&Info!$B$11),INDIRECT("'["&Info!$B$5&"]"&Info!$B$6&"'!"&Info!$B$9),B121,INDIRECT("'["&Info!$B$5&"]"&Info!$B$6&"'!"&Info!$B$15),">="&Info!$B$20,INDIRECT("'["&Info!$B$5&"]"&Info!$B$6&"'!"&Info!$B$15),"<="&Info!$B$21)) -> #REF! | G121: =IF(B121="","",SUMIFS(INDIRECT("'["&Info!$B$5&"]"&Info!$B$6&"'!"&Info!$B$11),INDIRECT("'["&Info!$B$5&"]"&Info!$B$6&"'!"&Info!$B$9),B121,INDIRECT("'["&Info!$B$5&"]"&Info!$B$6&"'!"&Info!$B$15),">="&Info!$B$23,INDIRECT("'["&Info!$B$5&"]"&Info!$B$6&"'!"&Info!$B$15),"<="&Info!$B$24)) -> #REF! | H121: =SUM(E121:G121) -> #REF! | I121: =IF(B121="","",IFERROR(SUMIF(INDIRECT("'["&Info!$B$5&"]"&Info!$B$6&"'!"&Info!$B$9),B121,INDIRECT("'["&Info!$B$5&"]"&Info!$B$6&"'!"&Info!$B$13))/COUNTIF(INDIRECT("'["&Info!$B$5&"]"&Info!$B$6&"'!"&Info!$B$9),B121),D121)) -> #N/A
A122: =IF(B122="","", Info!$B$2) -> DVN-FP3330-180404 | B122: 6H3577011 | C122: =IF(B122="","",IFERROR(VLOOKUP(B122,Reel!$E$3:$F$1013,2,0),VLOOKUP(B122,Ring!$E$3:$F$1000,2,0))) -> #N/A | D122: =IF(C122="","",IFERROR(VLOOKUP(C122,Reel!$F$2:$H$1013,3,0),VLOOKUP(C122,Ring!$F$3:$H$1000,3,0))) -> #N/A | E122: =IF(B122="","",SUMIFS(INDIRECT("'["&Info!$B$5&"]"&Info!$B$6&"'!"&Info!$B$11),INDIRECT("'["&Info!$B$5&"]"&Info!$B$6&"'!"&Info!$B$9),B122,INDIRECT("'["&Info!$B$5&"]"&Info!$B$6&"'!"&Info!$B$15),">="&Info!$B$17,INDIRECT("'["&Info!$B$5&"]"&Info!$B$6&"'!"&Info!$B$15),"<="&Info!$B$18)) -> #REF! | F122: =IF(B122="","",SUMIFS(INDIRECT("'["&Info!$B$5&"]"&Info!$B$6&"'!"&Info!$B$11),INDIRECT("'["&Info!$B$5&"]"&Info!$B$6&"'!"&Info!$B$9),B122,INDIRECT("'["&Info!$B$5&"]"&Info!$B$6&"'!"&Info!$B$15),">="&Info!$B$20,INDIRECT("'["&Info!$B$5&"]"&Info!$B$6&"'!"&Info!$B$15),"<="&Info!$B$21)) -> #REF! | G122: =IF(B122="","",SUMIFS(INDIRECT("'["&Info!$B$5&"]"&Info!$B$6&"'!"&Info!$B$11),INDIRECT("'["&Info!$B$5&"]"&Info!$B$6&"'!"&Info!$B$9),B122,INDIRECT("'["&Info!$B$5&"]"&Info!$B$6&"'!"&Info!$B$15),">="&Info!$B$23,INDIRECT("'["&Info!$B$5&"]"&Info!$B$6&"'!"&Info!$B$15),"<="&Info!$B$24)) -> #REF! | H122: =SUM(E122:G122) -> #REF! | I122: =IF(B122="","",IFERROR(SUMIF(INDIRECT("'["&Info!$B$5&"]"&Info!$B$6&"'!"&Info!$B$9),B122,INDIRECT("'["&Info!$B$5&"]"&Info!$B$6&"'!"&Info!$B$13))/COUNTIF(INDIRECT("'["&Info!$B$5&"]"&Info!$B$6&"'!"&Info!$B$9),B122),D122)) -> #N/A
A123: =IF(B123="","", Info!$B$2) -> DVN-FP3330-180404 | B123: 6H7263030 | C123: =IF(B123="","",IFERROR(VLOOKUP(B123,Reel!$E$3:$F$1013,2,0),VLOOKUP(B123,Ring!$E$3:$F$1000,2,0))) -> #N/A | D123: =IF(C123="","",IFERROR(VLOOKUP(C123,Reel!$F$2:$H$1013,3,0),VLOOKUP(C123,Ring!$F$3:$H$1000,3,0))) -> #N/A | E123: =IF(B123="","",SUMIFS(INDIRECT("'["&Info!$B$5&"]"&Info!$B$6&"'!"&Info!$B$11),INDIRECT("'["&Info!$B$5&"]"&Info!$B$6&"'!"&Info!$B$9),B123,INDIRECT("'["&Info!$B$5&"]"&Info!$B$6&"'!"&Info!$B$15),">="&Info!$B$17,INDIRECT("'["&Info!$B$5&"]"&Info!$B$6&"'!"&Info!$B$15),"<="&Info!$B$18)) -> #REF! | F123: =IF(B123="","",SUMIFS(INDIRECT("'["&Info!$B$5&"]"&Info!$B$6&"'!"&Info!$B$11),INDIRECT("'["&Info!$B$5&"]"&Info!$B$6&"'!"&Info!$B$9),B123,INDIRECT("'["&Info!$B$5&"]"&Info!$B$6&"'!"&Info!$B$15),">="&Info!$B$20,INDIRECT("'["&Info!$B$5&"]"&Info!$B$6&"'!"&Info!$B$15),"<="&Info!$B$21)) -> #REF! | G123: =IF(B123="","",SUMIFS(INDIRECT("'["&Info!$B$5&"]"&Info!$B$6&"'!"&Info!$B$11),INDIRECT("'["&Info!$B$5&"]"&Info!$B$6&"'!"&Info!$B$9),B123,INDIRECT("'["&Info!$B$5&"]"&Info!$B$6&"'!"&Info!$B$15),">="&Info!$B$23,INDIRECT("'["&Info!$B$5&"]"&Info!$B$6&"'!"&Info!$B$15),"<="&Info!$B$24)) -> #REF! | H123: =SUM(E123:G123) -> #REF! | I123: =IF(B123="","",IFERROR(SUMIF(INDIRECT("'["&Info!$B$5&"]"&Info!$B$6&"'!"&Info!$B$9),B123,INDIRECT("'["&Info!$B$5&"]"&Info!$B$6&"'!"&Info!$B$13))/COUNTIF(INDIRECT("'["&Info!$B$5&"]"&Info!$B$6&"'!"&Info!$B$9),B123),D123)) -> #N/A
A124: =IF(B124="","", Info!$B$2) -> DVN-FP3330-180404 | B124: 6H7263070 | C124: =IF(B124="","",IFERROR(VLOOKUP(B124,Reel!$E$3:$F$1013,2,0),VLOOKUP(B124,Ring!$E$3:$F$1000,2,0))) -> #N/A | D124: =IF(C124="","",IFERROR(VLOOKUP(C124,Reel!$F$2:$H$1013,3,0),VLOOKUP(C124,Ring!$F$3:$H$1000,3,0))) -> #N/A | E124: =IF(B124="","",SUMIFS(INDIRECT("'["&Info!$B$5&"]"&Info!$B$6&"'!"&Info!$B$11),INDIRECT("'["&Info!$B$5&"]"&Info!$B$6&"'!"&Info!$B$9),B124,INDIRECT("'["&Info!$B$5&"]"&Info!$B$6&"'!"&Info!$B$15),">="&Info!$B$17,INDIRECT("'["&Info!$B$5&"]"&Info!$B$6&"'!"&Info!$B$15),"<="&Info!$B$18)) -> #REF! | F124: =IF(B124="","",SUMIFS(INDIRECT("'["&Info!$B$5&"]"&Info!$B$6&"'!"&Info!$B$11),INDIRECT("'["&Info!$B$5&"]"&Info!$B$6&"'!"&Info!$B$9),B124,INDIRECT("'["&Info!$B$5&"]"&Info!$B$6&"'!"&Info!$B$15),">="&Info!$B$20,INDIRECT("'["&Info!$B$5&"]"&Info!$B$6&"'!"&Info!$B$15),"<="&Info!$B$21)) -> #REF! | G124: =IF(B124="","",SUMIFS(INDIRECT("'["&Info!$B$5&"]"&Info!$B$6&"'!"&Info!$B$11),INDIRECT("'["&Info!$B$5&"]"&Info!$B$6&"'!"&Info!$B$9),B124,INDIRECT("'["&Info!$B$5&"]"&Info!$B$6&"'!"&Info!$B$15),">="&Info!$B$23,INDIRECT("'["&Info!$B$5&"]"&Info!$B$6&"'!"&Info!$B$15),"<="&Info!$B$24)) -> #REF! | H124: =SUM(E124:G124) -> #REF! | I124: =IF(B124="","",IFERROR(SUMIF(INDIRECT("'["&Info!$B$5&"]"&Info!$B$6&"'!"&Info!$B$9),B124,INDIRECT("'["&Info!$B$5&"]"&Info!$B$6&"'!"&Info!$B$13))/COUNTIF(INDIRECT("'["&Info!$B$5&"]"&Info!$B$6&"'!"&Info!$B$9),B124),D124)) -> #N/A
A125: =IF(B125="","", Info!$B$2) -> DVN-FP3330-180404 | B125: 6H7264050 | C125: =IF(B125="","",IFERROR(VLOOKUP(B125,Reel!$E$3:$F$1013,2,0),VLOOKUP(B125,Ring!$E$3:$F$1000,2,0))) -> #N/A | D125: =IF(C125="","",IFERROR(VLOOKUP(C125,Reel!$F$2:$H$1013,3,0),VLOOKUP(C125,Ring!$F$3:$H$1000,3,0))) -> #N/A | E125: =IF(B125="","",SUMIFS(INDIRECT("'["&Info!$B$5&"]"&Info!$B$6&"'!"&Info!$B$11),INDIRECT("'["&Info!$B$5&"]"&Info!$B$6&"'!"&Info!$B$9),B125,INDIRECT("'["&Info!$B$5&"]"&Info!$B$6&"'!"&Info!$B$15),">="&Info!$B$17,INDIRECT("'["&Info!$B$5&"]"&Info!$B$6&"'!"&Info!$B$15),"<="&Info!$B$18)) -> #REF! | F125: =IF(B125="","",SUMIFS(INDIRECT("'["&Info!$B$5&"]"&Info!$B$6&"'!"&Info!$B$11),INDIRECT("'["&Info!$B$5&"]"&Info!$B$6&"'!"&Info!$B$9),B125,INDIRECT("'["&Info!$B$5&"]"&Info!$B$6&"'!"&Info!$B$15),">="&Info!$B$20,INDIRECT("'["&Info!$B$5&"]"&Info!$B$6&"'!"&Info!$B$15),"<="&Info!$B$21)) -> #REF! | G125: =IF(B125="","",SUMIFS(INDIRECT("'["&Info!$B$5&"]"&Info!$B$6&"'!"&Info!$B$11),INDIRECT("'["&Info!$B$5&"]"&Info!$B$6&"'!"&Info!$B$9),B125,INDIRECT("'["&Info!$B$5&"]"&Info!$B$6&"'!"&Info!$B$15),">="&Info!$B$23,INDIRECT("'["&Info!$B$5&"]"&Info!$B$6&"'!"&Info!$B$15),"<="&Info!$B$24)) -> #REF! | H125: =SUM(E125:G125) -> #REF! | I125: =IF(B125="","",IFERROR(SUMIF(INDIRECT("'["&Info!$B$5&"]"&Info!$B$6&"'!"&Info!$B$9),B125,INDIRECT("'["&Info!$B$5&"]"&Info!$B$6&"'!"&Info!$B$13))/COUNTIF(INDIRECT("'["&Info!$B$5&"]"&Info!$B$6&"'!"&Info!$B$9),B125),D125)) -> #N/A
A126: =IF(B126="","", Info!$B$2) -> DVN-FP3330-180404 | B126: 6H7264060 | C126: =IF(B126="","",IFERROR(VLOOKUP(B126,Reel!$E$3:$F$1013,2,0),VLOOKUP(B126,Ring!$E$3:$F$1000,2,0))) -> #N/A | D126: =IF(C126="","",IFERROR(VLOOKUP(C126,Reel!$F$2:$H$1013,3,0),VLOOKUP(C126,Ring!$F$3:$H$1000,3,0))) -> #N/A | E126: =IF(B126="","",SUMIFS(INDIRECT("'["&Info!$B$5&"]"&Info!$B$6&"'!"&Info!$B$11),INDIRECT("'["&Info!$B$5&"]"&Info!$B$6&"'!"&Info!$B$9),B126,INDIRECT("'["&Info!$B$5&"]"&Info!$B$6&"'!"&Info!$B$15),">="&Info!$B$17,INDIRECT("'["&Info!$B$5&"]"&Info!$B$6&"'!"&Info!$B$15),"<="&Info!$B$18)) -> #REF! | F126: =IF(B126="","",SUMIFS(INDIRECT("'["&Info!$B$5&"]"&Info!$B$6&"'!"&Info!$B$11),INDIRECT("'["&Info!$B$5&"]"&Info!$B$6&"'!"&Info!$B$9),B126,INDIRECT("'["&Info!$B$5&"]"&Info!$B$6&"'!"&Info!$B$15),">="&Info!$B$20,INDIRECT("'["&Info!$B$5&"]"&Info!$B$6&"'!"&Info!$B$15),"<="&Info!$B$21)) -> #REF! | G126: =IF(B126="","",SUMIFS(INDIRECT("'["&Info!$B$5&"]"&Info!$B$6&"'!"&Info!$B$11),INDIRECT("'["&Info!$B$5&"]"&Info!$B$6&"'!"&Info!$B$9),B126,INDIRECT("'["&Info!$B$5&"]"&Info!$B$6&"'!"&Info!$B$15),">="&Info!$B$23,INDIRECT("'["&Info!$B$5&"]"&Info!$B$6&"'!"&Info!$B$15),"<="&Info!$B$24)) -> #REF! | H126: =SUM(E126:G126) -> #REF! | I126: =IF(B126="","",IFERROR(SUMIF(INDIRECT("'["&Info!$B$5&"]"&Info!$B$6&"'!"&Info!$B$9),B126,INDIRECT("'["&Info!$B$5&"]"&Info!$B$6&"'!"&Info!$B$13))/COUNTIF(INDIRECT("'["&Info!$B$5&"]"&Info!$B$6&"'!"&Info!$B$9),B126),D126)) -> #N/A
A127: =IF(B127="","", Info!$B$2) -> DVN-FP3330-180404 | B127: 6H7264030 | C127: =IF(B127="","",IFERROR(VLOOKUP(B127,Reel!$E$3:$F$1013,2,0),VLOOKUP(B127,Ring!$E$3:$F$1000,2,0))) -> #N/A | D127: =IF(C127="","",IFERROR(VLOOKUP(C127,Reel!$F$2:$H$1013,3,0),VLOOKUP(C127,Ring!$F$3:$H$1000,3,0))) -> #N/A | E127: =IF(B127="","",SUMIFS(INDIRECT("'["&Info!$B$5&"]"&Info!$B$6&"'!"&Info!$B$11),INDIRECT("'["&Info!$B$5&"]"&Info!$B$6&"'!"&Info!$B$9),B127,INDIRECT("'["&Info!$B$5&"]"&Info!$B$6&"'!"&Info!$B$15),">="&Info!$B$17,INDIRECT("'["&Info!$B$5&"]"&Info!$B$6&"'!"&Info!$B$15),"<="&Info!$B$18)) -> #REF! | F127: =IF(B127="","",SUMIFS(INDIRECT("'["&Info!$B$5&"]"&Info!$B$6&"'!"&Info!$B$11),INDIRECT("'["&Info!$B$5&"]"&Info!$B$6&"'!"&Info!$B$9),B127,INDIRECT("'["&Info!$B$5&"]"&Info!$B$6&"'!"&Info!$B$15),">="&Info!$B$20,INDIRECT("'["&Info!$B$5&"]"&Info!$B$6&"'!"&Info!$B$15),"<="&Info!$B$21)) -> #REF! | G127: =IF(B127="","",SUMIFS(INDIRECT("'["&Info!$B$5&"]"&Info!$B$6&"'!"&Info!$B$11),INDIRECT("'["&Info!$B$5&"]"&Info!$B$6&"'!"&Info!$B$9),B127,INDIRECT("'["&Info!$B$5&"]"&Info!$B$6&"'!"&Info!$B$15),">="&Info!$B$23,INDIRECT("'["&Info!$B$5&"]"&Info!$B$6&"'!"&Info!$B$15),"<="&Info!$B$24)) -> #REF! | H127: =SUM(E127:G127) -> #REF! | I127: =IF(B127="","",IFERROR(SUMIF(INDIRECT("'["&Info!$B$5&"]"&Info!$B$6&"'!"&Info!$B$9),B127,INDIRECT("'["&Info!$B$5&"]"&Info!$B$6&"'!"&Info!$B$13))/COUNTIF(INDIRECT("'["&Info!$B$5&"]"&Info!$B$6&"'!"&Info!$B$9),B127),D127)) -> #N/A
A128: =IF(B128="","", Info!$B$2) -> DVN-FP3330-180404 | B128: 6H4952053 | C128: =IF(B128="","",IFERROR(VLOOKUP(B128,Reel!$E$3:$F$1013,2,0),VLOOKUP(B128,Ring!$E$3:$F$1000,2,0))) -> #N/A | D128: =IF(C128="","",IFERROR(VLOOKUP(C128,Reel!$F$2:$H$1013,3,0),VLOOKUP(C128,Ring!$F$3:$H$1000,3,0))) -> #N/A | E128: =IF(B128="","",SUMIFS(INDIRECT("'["&Info!$B$5&"]"&Info!$B$6&"'!"&Info!$B$11),INDIRECT("'["&Info!$B$5&"]"&Info!$B$6&"'!"&Info!$B$9),B128,INDIRECT("'["&Info!$B$5&"]"&Info!$B$6&"'!"&Info!$B$15),">="&Info!$B$17,INDIRECT("'["&Info!$B$5&"]"&Info!$B$6&"'!"&Info!$B$15),"<="&Info!$B$18)) -> #REF! | F128: =IF(B128="","",SUMIFS(INDIRECT("'["&Info!$B$5&"]"&Info!$B$6&"'!"&Info!$B$11),INDIRECT("'["&Info!$B$5&"]"&Info!$B$6&"'!"&Info!$B$9),B128,INDIRECT("'["&Info!$B$5&"]"&Info!$B$6&"'!"&Info!$B$15),">="&Info!$B$20,INDIRECT("'["&Info!$B$5&"]"&Info!$B$6&"'!"&Info!$B$15),"<="&Info!$B$21)) -> #REF! | G128: =IF(B128="","",SUMIFS(INDIRECT("'["&Info!$B$5&"]"&Info!$B$6&"'!"&Info!$B$11),INDIRECT("'["&Info!$B$5&"]"&Info!$B$6&"'!"&Info!$B$9),B128,INDIRECT("'["&Info!$B$5&"]"&Info!$B$6&"'!"&Info!$B$15),">="&Info!$B$23,INDIRECT("'["&Info!$B$5&"]"&Info!$B$6&"'!"&Info!$B$15),"<="&Info!$B$24)) -> #REF! | H128: =SUM(E128:G128) -> #REF! | I128: =IF(B128="","",IFERROR(SUMIF(INDIRECT("'["&Info!$B$5&"]"&Info!$B$6&"'!"&Info!$B$9),B128,INDIRECT("'["&Info!$B$5&"]"&Info!$B$6&"'!"&Info!$B$13))/COUNTIF(INDIRECT("'["&Info!$B$5&"]"&Info!$B$6&"'!"&Info!$B$9),B128),D128)) -> #N/A

Sheet Reel
A1: STT (SP) | B1: Khách hàng | C1: Mã Khách hàng | D1: Tên sản phẩm | E1: Mã sản phẩm | F1: Mã VF mới | G1: Giá sản phẩm | J1: Nguyên liệu | K1: Đường kính | L1: Chiều dài | M1: Giá nguyên liệu sản phẩm | T1: Giá gia công | Z1: Giá xi mạ | AC1: Tình trạng đặt hàng
G2: VND | H2: USD | M2: Chiều dài tổng | N2: Đường kính sử dụng | O2: Hệ số tương ứng với đường kính | P2: Trọng lượng sản phẩm đầu vào (gam ) | Q2: Giá nguyên liệu | R2: Giá nguyên liệu của sản phẩm | S2: Tỉ lệ nguyên liệu so với giá bán | T2: Gia công 1 | U2: năng suất | V2: Thành tiền | W2: Gia công 2 | X2: Thành tiền | Y2: Tổng giá gia công | Z2: Y/c xi mạ | AA2: giá xi mạ ( VNd/kg) | AB2: Giá xi mạ từng sản phẩm
A3: 1 | B3: D2 - DAI WA ĐÀ NẴNG | C3: D2A | D3: RING | E3: 741646600 | F3: 741646600 | H3: 0.49 | J3: C3604BD | K3: ø 5.4 | L3: 3 | M3: =(L3+(IF(K3<=4,1.5,IF(K3<=7,2,IF(K3<=11,2.5,IF(K3<=19,3,IF(K3<=25,3.5,4)))))))*1.1 -> 7.7 | N3: 5.5 | O3: 0.19 | P3: =M3*O3 -> 1.463 | R3: =Q3/1000*P3 -> 0 | S3: =IF(G3<>0,R3/G3*100,R3/(H3*21000)*100) -> 0
A4: 2 | C4: D2A | D4: RING | E4: 741646700 | F4: 741646700 | H4: 0.59 | J4: C3604BD | K4: ø 6 | L4: 6 | M4: =(L4+(IF(K4<=4,1.5,IF(K4<=7,2,IF(K4<=11,2.5,IF(K4<=19,3,IF(K4<=25,3.5,4)))))))*1.1 -> 11 | N4: 6 | O4: 0.24 | P4: =M4*O4 -> 2.64 | R4: =Q4/1000*P4 -> 0 | S4: =IF(G4<>0,R4/G4*100,R4/(H4*21000)*100) -> 0
A5: 3 | C5: D2A | D5: RING | E5: 741810300 | F5: 7418-25.3-24 | H5: 0.5 | J5: C3604BD | K5: ø 6 | L5: 7.4 | M5: =(L5+(IF(K5<=4,1.5,IF(K5<=7,2,IF(K5<=11,2.5,IF(K5<=19,3,IF(K5<=25,3.5,4)))))))*1.1 -> 12.54 | N5: 6 | O5: 0.24 | P5: =M5*O5 -> 3.0096 | R5: =Q5/1000*P5 -> 0 | S5: =IF(G5<>0,R5/G5*100,R5/(H5*21000)*100) -> 0
A6: 4 | C6: D2A | D6: RING | E6: 741879700 | F6: 7418-23.5-20.5 | H6: 0.58 | J6: C3604BD | K6: ø 7 | L6: 3.2 | M6: =(L6+(IF(K6<=4,1.5,IF(K6<=7,2,IF(K6<=11,2.5,IF(K6<=19,3,IF(K6<=25,3.5,4)))))))*1.1 -> 7.92 | N6: 7 | O6: 0.33 | P6: =M6*O6 -> 2.6136 | R6: =Q6/1000*P6 -> 0 | S6: =IF(G6<>0,R6/G6*100,R6/(H6*21000)*100) -> 0
A7: 5 | C7: D2A | D7: RING | E7: 742513200 | F7: 7425-17-14.95 | H7: 0.483 | J7: C3604BD | K7: ø 7.2 | L7: 1.1 | M7: =(L7+(IF(K7<=4,1.5,IF(K7<=7,2,IF(K7<=11,2.5,IF(K7<=19,3,IF(K7<=25,3.5,4)))))))*1.1 -> 5.61 | O7: 0.38 | P7: =M7*O7 -> 2.1318 | R7: =Q7/1000*P7 -> 0 | S7: =IF(G7<>0,R7/G7*100,R7/(H7*21000)*100) -> 0
A8: 6 | C8: D2A | D8: RING | E8: 742513300 | F8: 7425-26.8-24.8 | H8: 0.5635 | J8: C3604BD | K8: ø 12 | L8: 1 | M8: =(L8+(IF(K8<=4,1.5,IF(K8<=7,2,IF(K8<=11,2.5,IF(K8<=19,3,IF(K8<=25,3.5,4)))))))*1.1 -> 5.5 | N8: 12 | O8: =1.2*1.2*0.66 -> 0.9504 | P8: =M8*O8 -> 5.2272 | R8: =Q8/1000*P8 -> 0 | S8: =IF(G8<>0,R8/G8*100,R8/(H8*21000)*100) -> 0
A9: 7 | C9: D2A | D9: RING | E9: 742513400 | F9: 7425-26-17.1 | H9: 0.5 | J9: C3604BD | K9: ø 21.8 | L9: 3.9 | M9: =(L9+(IF(K9<=4,1.5,IF(K9<=7,2,IF(K9<=11,2.5,IF(K9<=19,3,IF(K9<=25,3.5,4)))))))*1.1 -> 8.69 | O9: =2.2*2.2*0.66 -> 3.1944 | P9: =M9*O9 -> 27.759336 | R9: =Q9/1000*P9 -> 0 | S9: =IF(G9<>0,R9/G9*100,R9/(H9*21000)*100) -> 0
A10: 8 | C10: D2A | D10: RING | E10: 742513500 | F10: 7425-17.5-14.95 | H10: 0.33 | J10: C3604BD | K10: ø 12 | L10: 2.3 | M10: =(L10+(IF(K10<=4,1.5,IF(K10<=7,2,IF(K10<=11,2.5,IF(K10<=19,3,IF(K10<=25,3.5,4)))))))*1.1 -> 6.93 | N10: 12 | O10: =1.2*1.2*0.66 -> 0.9504 | P10: =M10*O10 -> 6.586272 | R10: =Q10/1000*P10 -> 0 | S10: =IF(G10<>0,R10/G10*100,R10/(H10*21000)*100) -> 0
A11: 9 | C11: D2A | D11: RING | E11: 742514400 | F11: 7425-16.5-12 | H11: 0.45 | J11: C3604BD | K11: ø 6 | L11: 32.4 | M11: =(L11+(IF(K11<=4,1.5,IF(K11<=7,2,IF(K11<=11,2.5,IF(K11<=19,3,IF(K11<=25,3.5,4)))))))*1.1 -> 40.04 | N11: 6 | O11: 0.24 | P11: =M11*O11 -> 9.6096 | R11: =Q11/1000*P11 -> 0 | S11: =IF(G11<>0,R11/G11*100,R11/(H11*21000)*100) -> 0
A12: 10 | C12: D2A | D12: RING | E12: 742514500 | F12: 7425-22-20.6 | H12: 0.4 | J12: C3604BD | K12: ø 6 | L12: 33.8 | M12: =(L12+(IF(K12<=4,1.5,IF(K12<=7,2,IF(K12<=11,2.5,IF(K12<=19,3,IF(K12<=25,3.5,4)))))))*1.1 -> 41.58 | N12: 6 | O12: 0.24 | P12: =M12*O12 -> 9.9792 | R12: =Q12/1000*P12 -> 0 | S12: =IF(G12<>0,R12/G12*100,R12/(H12*21000)*100) -> 0
A13: 11 | C13: D2A | D13: RING | E13: 742517000 | F13: 7425-19.5-17.05 | H13: 0.49 | J13: C3604BD | K13: ø 6 | L13: 33.9 | M13: =(L13+(IF(K13<=4,1.5,IF(K13<=7,2,IF(K13<=11,2.5,IF(K13<=19,3,IF(K13<=25,3.5,4)))))))*1.1 -> 41.69 | N13: 6 | O13: 0.24 | P13: =M13*O13 -> 10.0056 | R13: =Q13/1000*P13 -> 0 | S13: =IF(G13<>0,R13/G13*100,R13/(H13*21000)*100) -> 0
A14: 12 | C14: D2A | D14: RING | E14: 742517010 | F14: 7425-19.5-16.95 | H14: 0.49 | J14: C3604BD | K14: ø 6 | L14: 34.4 | M14: =(L14+(IF(K14<=4,1.5,IF(K14<=7,2,IF(K14<=11,2.5,IF(K14<=19,3,IF(K14<=25,3.5,4)))))))*1.1 -> 42.24 | N14: 6 | O14: 0.24 | P14: =M14*O14 -> 10.1376 | R14: =Q14/1000*P14 -> 0 | S14: =IF(G14<>0,R14/G14*100,R14/(H14*21000)*100) -> 0
A15: 13 | C15: D2A | D15: RING | E15: 742517200 | F15: 7425-19.4-17.05 | H15: 0.52 | J15: C3604BD | K15: ø 6 | L15: 34.4 | M15: =(L15+(IF(K15<=4,1.5,IF(K15<=7,2,IF(K15<=11,2.5,IF(K15<=19,3,IF(K15<=25,3.5,4)))))))*1.1 -> 42.24 | N15: 6 | O15: 0.24 | P15: =M15*O15 -> 10.1376 | R15: =Q15/1000*P15 -> 0 | S15: =IF(G15<>0,R15/G15*100,R15/(H15*21000)*100) -> 0
A16: 14 | C16: D2A | D16: RING | E16: 742517300 | F16: 7425-26.5-21.95 | H16: 0.5 | J16: C3604BD | K16: ø 7.5 | L16: 44.9 | M16: =(L16+(IF(K16<=4,1.5,IF(K16<=7,2,IF(K16<=11,2.5,IF(K16<=19,3,IF(K16<=25,3.5,4)))))))*1.1 -> 53.79 | N16: 7.5 | O16: 0.38 | P16: =M16*O16 -> 20.4402 | R16: =Q16/1000*P16 -> 0 | S16: =IF(G16<>0,R16/G16*100,R16/(H16*21000)*100) -> 0
A17: 15 | C17: D2A | D17: RING | E17: 742517400 | F17: 7425-20.4-17.95 | H17: 0.49 | J17: C3604BD | K17: ø 7.5 | L17: 44.9 | M17: =(L17+(IF(K17<=4,1.5,IF(K17<=7,2,IF(K17<=11,2.5,IF(K17<=19,3,IF(K17<=25,3.5,4)))))))*1.1 -> 53.79 | N17: 7.5 | O17: 0.38 | P17: =M17*O17 -> 20.4402 | R17: =Q17/1000*P17 -> 0 | S17: =IF(G17<>0,R17/G17*100,R17/(H17*21000)*100) -> 0
A18: 16 | C18: D2A | D18: RING | E18: 742521100 | F18: 7425-19.5-15.55 | H18: 0.4 | J18: SUS303 | K18: ø 6 | L18: 34.9 | M18: =(L18+(IF(K18<=4,1.5,IF(K18<=7,2,IF(K18<=11,2.5,IF(K18<=19,3,IF(K18<=25,3.5,4)))))))*1.1 -> 42.79 | N18: 6 | O18: 0.24 | P18: =M18*O18 -> 10.2696 | Q18: 120000 | R18: =Q18/1000*P18 -> 1232.352 | S18: =IF(G18<>0,R18/G18*100,R18/(H18*21000)*100) -> 14.670857
A19: 17 | C19: D2A | D19: RING | E19: 742521200 | F19: 7425-19.5-16.55 | H19: 0.4 | J19: SUS303 | K19: ø 7 | L19: 34.9 | M19: =(L19+(IF(K19<=4,1.5,IF(K19<=7,2,IF(K19<=11,2.5,IF(K19<=19,3,IF(K19<=25,3.5,4)))))))*1.1 -> 42.79 | N19: 7 | O19: 0.33 | P19: =M19*O19 -> 14.1207 | Q19: 120000 | R19: =Q19/1000*P19 -> 1694.484 | S19: =IF(G19<>0,R19/G19*100,R19/(H19*21000)*100) -> 20.172429
A20: 18 | C20: D2A | D20: RING | E20: 752506000 | F20: 7525-23-19.7 | H20: 0.647 | J20: C3604BD | K20: ø 6 | L20: 36.9 | M20: =(L20+(IF(K20<=4,1.5,IF(K20<=7,2,IF(K20<=11,2.5,IF(K20<=19,3,IF(K20<=25,3.5,4)))))))*1.1 -> 44.99 | N20: 6 | O20: 0.24 | P20: =M20*O20 -> 10.7976 | R20: =Q20/1000*P20 -> 0 | S20: =IF(G20<>0,R20/G20*100,R20/(H20*21000)*100) -> 0
A21: 19 | C21: D2A | D21: RING | E21: 3V0047020 | F21: 3V00-15.5-8.05 | H21: 0.2871 | J21: C3604BD | K21: ø 6 | L21: 45.4 | M21: =(L21+(IF(K21<=4,1.5,IF(K21<=7,2,IF(K21<=11,2.5,IF(K21<=19,3,IF(K21<=25,3.5,4)))))))*1.1 -> 54.34 | N21: 6 | O21: 0.24 | P21: =M21*O21 -> 13.0416 | R21: =Q21/1000*P21 -> 0 | S21: =IF(G21<>0,R21/G21*100,R21/(H21*21000)*100) -> 0
A22: 20 | C22: D2A | D22: RING | E22: 3V0047030 | F22: 3V00-15.5-8.55 | H22: 0.2871 | J22: C3604BD | K22: ø 8 | L22: 46.2 | M22: =(L22+(IF(K22<=4,1.5,IF(K22<=7,2,IF(K22<=11,2.5,IF(K22<=19,3,IF(K22<=25,3.5,4)))))))*1.1 -> 55.22 | N22: 8 | O22: 0.42 | P22: =M22*O22 -> 23.1924 | R22: =Q22/1000*P22 -> 0 | S22: =IF(G22<>0,R22/G22*100,R22/(H22*21000)*100) -> 0
A23: 21 | C23: D2A | D23: RING | E23: 3V0047040 | F23: 3V00-15.5-9.55 | H23: 0.2871 | J23: C3604BD | K23: ø 7 | L23: 34.4 | M23: =(L23+(IF(K23<=4,1.5,IF(K23<=7,2,IF(K23<=11,2.5,IF(K23<=19,3,IF(K23<=25,3.5,4)))))))*1.1 -> 42.24 | N23: 7 | O23: 0.33 | P23: =M23*O23 -> 13.9392 | R23: =Q23/1000*P23 -> 0 | S23: =IF(G23<>0,R23/G23*100,R23/(H23*21000)*100) -> 0
A24: 22 | C24: D2A | D24: RING | E24: 3V0047050 | F24: 3V00-15.5-10.55 | H24: 0.2871 | J24: Aisi 12L14 | K24: ø 8 | L24: 23.5 | M24: =(L24+(IF(K24<=4,1.5,IF(K24<=7,2,IF(K24<=11,2.5,IF(K24<=19,3,IF(K24<=25,3.5,4)))))))*1.1 -> 30.25 | N24: 8 | O24: 0.42 | P24: =M24*O24 -> 12.705 | Q24: 35000 | R24: =Q24/1000*P24 -> 444.675 | S24: =IF(G24<>0,R24/G24*100,R24/(H24*21000)*100) -> 7.3754789
