Workbook

Sheet 31.01
A1: Ngày:31.01.2015 | J1: Phiếu Giao Nhận Và Sử Dụng Nguyên Liệu | DU1: (BM 01/NL)
E2: THÔNG TIN NGUYÊN LIỆU | AG2: BÁO CÁO SẢN PHẨM CA 1 | BA2: BÁO CÁO SẢN PHẨM CA 2 | BU2: BÁO CÁO TỔNG SẢN PHẨM 2 CA | CI2: NHẬP BÁO CÁO | CW2: THEO DÕI NĂNG SUẤT | DE2: Ca 1C | DH2: Ca 2A | DK2: Tổng 2 Ca
A3: STT | B3: MÁY | C3: MÃ KHÁCH HÀNG | D3: MÃ SẢN PHẨM | E3: Qui cách | T3: Tồn Đầu | U3: Cấp mới | V3: Trọng lương/pcs | W3: Kho CNC (pcs) 2 | X3: Kho SX2 ( pcs) 2 | Y3: Kho chờ nhiệt luyện (pcs) 3 | Z3: Kho Chờ rung bóng (pcs) 4 | AA3: Kho Chờ GCN (pcs) 5 | AB3: Kho QC (pcs) 7 | AC3: Kho chờ xử lý (pcs) 8 | AD3: Kho PP (pcs) 9 | AE3: Tổng sản phẩm 02 ca | AF3: Lũy kế (Từ30/06 đến 30/07 | AG3: NGUYÊN LIỆU CA1 | AN3: SẢN PHẨM CA1 | AY3: Chênh lệch định mức | BA3: NGUYÊN LIỆU CA2 | BH3: SẢN PHẨM CA2 | BS3: Chênh lệch định mức | BX3: Σ nguyên liệu sử sụng 2ca | CA3: Σ Số lượng sản phẩm 2ca | CC3: Σ Chênh lệch định mức 2ca | CE3: Σ Lũy kế Chênh lệch định mức 2ca | CG3: PHOI | CI3: Báo cáo hằng ngày | CQ3: 192.188.1.171/vfi | CW3: Loại máy | CX3: 1pcs/ giây | CY3: Năng suất | CZ3: Định mức gia công | DA3: Giá trị gia công | DB3: % Năng suất | DC3: % Hàng chỉnh máy /ca | DD3: % Hàng hao hụt /ca | DE3: Tổng Sản Phẩm Ca1 | DF3: Tổng N.L Ca1 | DG3: Tổng Mức Chênh Lệch Ca1 | DH3: Tổng Sản Phẩm Ca2 | DI3: Tổng N.L Ca2 | DJ3: Tổng Mức Chênh Lệch Ca2 | DK3: Tổng Sản Phẩm 2Ca | DL3: Tổng N.L 2Ca | DM3: Tổng Mức Chênh Lệch 2Ca | DT3: SP KPH
E4: Định mức (pcs/ cây ) | F4: Mã nhận dạng NL | G4: Mã NL VF | J4: Mã Nguyên Liệu | K4: Nhà cung cấp | L4: Đường Kính ( mm ) | N4: Hình dạng | O4: Tiêu chuẩn | P4: Dài (m) | Q4: Trọng lượng ( Kg/cây) | R4: Số lot | S4: Định Mức NL 2Ca | AG4: Tồn đầu ca ( Cây) | AH4: Sử dụng | AM4: Tồn cuối ( Cây) | AN4: Số hộp ( cái ) | AO4: Kho CNC | AP4: kho SX2 (gam) | AQ4: Kho nhiệt luyện (gam) | AR4: Kho Rung bóng (gam) | AS4: GCN (gam) | AT4: Kho QC (gam) | AU4: Kho chờ xử lý (gam) | AV4: Giao PP (gam) | AW4: Tổng SP Ca 1 | AY4: Trọng lượng (gam) | AZ4: Số lượng (pcs) | BA4: Tồn đầu ca ( Cây) | BB4: Sử dụng | BG4: Tồn cuối ( Cây) | BH4: Số hộp ( cái ) | BI4: Kho CNC | BJ4: kho SX2 (gam) | BK4: Kho nhiệt luyện (gam) | BL4: Kho Rung bóng (gam) | BM4: GCN (gam) | BN4: Kho QC (gam) | BO4: Kho chờ xử lý (gam) | BP4: Giao PP (gam) | BQ4: Tổng SP Ca 2 | BS4: Trọng lượng (gam) | BT4: Số lượng (pcs) | BU4: Tổng SP 2 Ca | BV4: Tổng NL 2 Ca sử dụng | BW4: Tổng Mức Chênh Lệch Sản Phẩm | BX4: Trọng lượng ( kg) | BY4: Số lượng (cây) | BZ4: Lũy kế | CA4: Trọng lượng ( kg) | CB4: Số lượng (pcs) | CC4: Trọng lượng (gam) | CD4: Số lượng (pcs) | CE4: Trọng lượng (gam) | CF4: Số lượng (pcs) | CG4: Ngày: | CH4: Lũy kế | CI4: Ca1A | CM4: Ca 2B | CQ4: =CI4 -> Ca1A | CT4: =CM4 -> Ca 2B | DN4: Tồn đầu ca | DO4: Cấp mới | DP4: SL sử dụng | DQ4: Tồn cuối ca | DR4: lot | DS4: Số hộp | DT4: SL | DU4: Nội dung KPH | DV4: Ghi chú
L5: OD | M5: ID | AH5: Cây đầu ca | AI5: Cây nguyên | AJ5: Cây cuối ca | AL5: ∑ | AW5: Σ Trọng lượng (gam) | AX5: Σ Số lượng (pcs) | BB5: Cây đầu ca | BC5: Cây nguyên | BD5: Cây cuối ca | BF5: ∑ | BQ5: Σ Trọng lượng (gam) | BR5: Σ Số lượng (pcs) | CI5: Trọng lượng hộp cuối | CJ5: Σ Trọng lượng (gam) | CK5: Trọng lượng chờ xử lý | CL5: Trọng lượng phế phẩm | CM5: Trọng lượng hộp cuối | CN5: Σ Trọng lượng (gam) | CO5: Trọng lượng chờ xử lý | CP5: Trọng lượng phế phẩm | CQ5: TP1 | CR5: CXL 1 | CS5: PP1 | CT5: TP2 | CU5: CXL 2 | CV5: PP2
AJ6: Tl (g) | AK6: Cây | BD6: Tl (g) | BE6: Cây | CQ6: =CQ7+CR7+CT7+CU7 -> 118666
S7: =SUMIF(S8:S106,">0") -> 2722 | T7: =SUM(T8:T106) -> 1206.86 | U7: =SUM(U8:U106) -> 948 | W7: =SUM(W8:W777) -> 455 | X7: =SUM(X8:X777) -> 39049 | Y7: =SUM(Y8:Y777) -> 5186 | Z7: =SUM(Z8:Z777) -> 10669 | AA7: =SUM(AA8:AA777) -> 1950 | AB7: =SUM(AB8:AB777) -> 60009 | AC7: =SUM(AC8:AC777) -> 1348 | AD7: =SUM(AD8:AD777) -> 2194 | AE7: =SUM(AE8:AE777) -> 118666 | AF7: =SUM(AF8:AF249) -> 118666 | AG7: =SUM(AG8:AG285) -> 1206.86 | AH7: =SUM(AH8:AH285) -> 2.86 | AI7: =SUM(AI8:AI285) -> 374 | AJ7: =SUM(AJ8:AJ285) -> 3227 | AK7: =SUM(AK8:AK285) -> 93.91587 | AL7: =SUM(AL8:AL285) -> 371.82 | AM7: =SUM(AM8:AM285) -> 1783.04 | AN7: =SUM(AN8:AN285) -> 0 | ... CP7: =SUM(CP8:CP285) -> 2260 | CQ7: =SUM(CQ8:CQ777) -> 62925 | CR7: =SUM(CR8:CR777) -> 1348 | CS7: =SUM(CS8:CS777) -> 669 | CT7: =SUM(CT8:CT777) -> 54393 | CU7: =SUM(CU8:CU777) -> 0 | CV7: =SUM(CV8:CV777) -> 1525 | CW7: =SUM(CW8:CW106) -> 0 | CX7: =SUM(CX8:CX106) -> 3534.72 | CY7: =SUM(CY8:CY106) -> #DIV/0! | CZ7: =SUM(CZ8:CZ106) -> 25021.102 | DA7: =SUM(DA8:DA106) -> 0 | DB7: =SUM(DB8:DB106) -> 0 | DC7: =SUM(DC8:DC106) -> 0 | DD7: =SUM(DD8:DD106) -> 0 | DE7: =SUM(DE8:DE108) -> 64273 | DF7: =SUM(DF8:DF108) -> 371.82 | DG7: =SUM(DG8:DG108) -> -421.35366 | DH7: =SUM(DH8:DH108) -> 54393 | DI7: =SUM(DI8:DI108) -> 300.56 | DJ7: =SUM(DJ8:DJ108) -> -893.83129 | DK7: =SUM(DK8:DK108) -> 118666 | DL7: =SUM(DL8:DL108) -> 672.38 | DM7: =SUM(DM8:DM108) -> -1315.1849
A8: 1 | B8: C01 | D8: SM04 | E8: 70 | F8: D | G8: =CONCATENATE(K8,J8,"-",IF(N8="D",L8,IF(N8="H",CONCATENATE(N8,L8),CONCATENATE(N8,L8,"x",M8))),"x",P8,"-",O8,R8) -> GWA6063-T5-17x3-H9B15 | H8: =CONCATENATE(J8,,K8,L8,M8,N8,O8) -> A6063-T5GW170DH9 | I8: =CONCATENATE(J8,K8,L8,M8,N8,O8,P8,R8) -> A6063-T5GW170DH93B15 | J8: A6063-T5 | K8: GW | L8: 17 | M8: 0 | N8: D | O8: H9 | P8: 3 | Q8: 1.832 | R8: B15 | S8: =ROUND(CY8/E8,0)*2 -> 16 | T8: 17 | U8: 10 | V8: 10.1 | W8: =IF(V8="","",INT((AO8+BI8)/$V8)) -> 0 | X8: =IF(V8="","",INT((AP8+BJ8)/$V8)) -> 148 | Y8: =IF(V8="","",INT((AQ8+BK8)/$V8)) -> 0 | Z8: =IF(V8="","",INT((AR8+BL8)/$V8)) -> 0 | AA8: =IF(V8="","",INT((AS8+BM8)/$V8)) -> 0 | AB8: =IF(V8="","",INT((AT8+BN8)/$V8)) -> 0 | AC8: =IF(V8="","",INT((AU8+BO8)/$V8)) -> 0 | AD8: =IF(V8="","",INT((AV8+BP8)/$V8)) -> 47 | AE8: =IF(V8="","",SUM(W8:AC8)) -> 148 | AF8: =AE8 -> 148 | AG8: =T8 -> 17 | AH8: =IFERROR(VALUE("0"&RIGHT(AG8,(LEN(AG8)-LEN(TRUNC(AG8))))),"") -> 0 | AI8: 2 | AJ8: =$CI8 -> 0 | AK8: =IF(V8="","",IF(AJ8=0,1,AJ8/$V8/$E8)) -> 1 | AL8: =IF(V8="","",MAX(ROUNDUP((IF(AI8+AJ8=0,0,AH8)+AI8+AK8-1),2),0)) -> 2 | AM8: =IF(V8="","",AG8+U8-AL8) -> 25 | AP8: =$CJ8 -> 1500 | AU8: =CK8 -> 0 | AV8: =CL8 -> 475 | AW8: =SUM(AO8:AV8) -> 1975 | AX8: =IF(V8="","",INT(AW8/$V8)) -> 195 | AY8: =IF(V8="","",AW8-AL8*$E8*$V8) -> 561 | AZ8: =IF($V8="","",AY8/$V8) -> 55.544554 | BA8: =AM8 -> 25 | BB8: =VALUE("0"&RIGHT(BA8,(LEN(BA8)-LEN(TRUNC(BA8))))) -> 0 | BD8: =$CM8 -> 0 | BE8: =IF(AA8="","",IF(BD8=0,1,BD8/$V8/$E8)) -> 1 | BF8: =IF(V8="","",MAX(ROUNDUP((IF(BC8+BD8=0,0,BB8)+BC8+BE8-1),2),0)) -> 0 | BG8: =IF(AA8="","",BA8-BF8) -> 25 | BJ8: =$CN8 -> 0 | BO8: =CO8 -> 0 | BP8: =CP8 -> 0 | BQ8: =SUM(BI8:BP8) -> 0 | BR8: =IF(AA8="","",INT(BQ8/$V8)) -> 0 | BS8: =IF(AA8="","",-BF8*$E8*$V8+BQ8) -> 0 | BT8: =IF($V8="","",BS8/$V8) -> 0 | BU8: =IFERROR(AE8,"") -> 148 | BV8: =IFERROR(BF8+AL8,"") -> 2 | BW8: =IFERROR(BT8+AZ8,"") -> 55.544554 | BX8: =IF($Q8="","",(BF8+AL8)*$Q8) -> 3.664 | BY8: =IFERROR(BF8+AL8,0) -> 2 | BZ8: =BY8 -> 2 | CA8: =IFERROR((BQ8+AW8)/1000,"") -> 1.975 | CB8: =IFERROR(BR8+AX8,"") -> 195 | CC8: =IFERROR(BS8+AY8,"") -> 561 | CD8: =IFERROR(BT8+AZ8,"") -> 55.544554 | CG8: =IF(BX8="",0,(BX8-CA8)+((AV8+BP8)/1000)) -> 2.164 | CH8: =CG8 -> 2.164 | CJ8: 1500 | CL8: 475 | CQ8: =INT(IFERROR( CJ8/$V8,0)) -> 148 | CR8: =INT(IFERROR( CK8/$V8,0)) -> 0 | CS8: =INT(IFERROR( CL8/$V8,0)) -> 47 | CT8: =INT(IFERROR( AE8-CQ8-CU8-CR8,0)) -> 0 | CU8: =INT(IFERROR( AC8-CR8,0)) -> 0 | CV8: =INT(IFERROR( AD8-CS8,0)) -> 0 | CX8: 72 | CY8: =INT(60/CX8*60*(12-(CEILING((60/CX8*60*12)/E8,1)*IF(CW8="T",0.45,IF(CW8="",5,3))/60))) -> 562 | CZ8: =IF(CX8="",0,(IF(CW8="",360,180)/(60/CX8))*1.35) -> 583.2 | DE8: =IFERROR(CQ8+CR8,"") -> 148 | DF8: =IFERROR(AL8,"") -> 2 | DG8: =IFERROR(AZ8,"") -> 55.544554 | DH8: =IFERROR(CT8+CU8,"") -> 0 | DI8: =IFERROR(BF8,"") -> 0 | DJ8: =IFERROR(BT8,"") -> 0 | DK8: =IFERROR(DE8+DH8,"") -> 148 | DL8: =IFERROR(DF8+DI8,"") -> 2 | DM8: =IFERROR(DG8+DJ8,"") -> 55.544554 | DN8: =T8 -> 17 | DO8: =U8 -> 10 | DR8: B15C010515 | DW8: =IFERROR(AL8+BC8,"") -> 2 | DX8: =IFERROR(DK8+DL8+DM8,"") -> 205.54455 | DY8: =CQ8+CR8+CS8+CT8+CU8+CV8 -> 195 | DZ8: =IFERROR((AD8*V8/1000),0) -> 0.4747 | EA8: =IFERROR((AE8*V8/1000),0) -> 1.4948 | EB8: =BX8-EA8 -> 2.1692 | EC8: =(BX8-CA8)+((AV8+BP8)/1000) -> 2.164 | EF8: =DG8+DJ8 -> 55.544554
A9: 2 | B9: C02 | D9: Y5 1851 | E9: 8 | F9: B | G9: =CONCATENATE(K9,J9,"-",IF(N9="D",L9,IF(N9="H",CONCATENATE(N9,L9),CONCATENATE(N9,L9,"x",M9))),"x",P9,"-",O9,R9) -> TV12L14-10x2.5-H9A14 | H9: =CONCATENATE(J9,,K9,L9,M9,N9,O9) -> 12L14TV100DH9 | I9: =CONCATENATE(J9,K9,L9,M9,N9,O9,P9,R9) -> 12L14TV100DH92.5A14 | J9: 12L14 | K9: TV | L9: 10 | M9: 0 | N9: D | O9: H9 | P9: 2.5 | Q9: 1.533 | R9: A14 | S9: =ROUND(CY9/E9,0)*2 -> 70 | T9: 0 | V9: 159.7 | W9: =IF(V9="","",INT((AO9+BI9)/$V9)) -> 0 | X9: =IF(V9="","",INT((AP9+BJ9)/$V9)) -> 0 | Y9: =IF(V9="","",INT((AQ9+BK9)/$V9)) -> 0 | Z9: =IF(V9="","",INT((AR9+BL9)/$V9)) -> 0 | AA9: =IF(V9="","",INT((AS9+BM9)/$V9)) -> 0 | AB9: =IF(V9="","",INT((AT9+BN9)/$V9)) -> 0 | AC9: =IF(V9="","",INT((AU9+BO9)/$V9)) -> 0 | AD9: =IF(V9="","",INT((AV9+BP9)/$V9)) -> 0 | AE9: =IF(V9="","",SUM(W9:AC9)) -> 0 | AF9: =AE9 -> 0 | AG9: =T9 -> 0 | AH9: =IFERROR(VALUE("0"&RIGHT(AG9,(LEN(AG9)-LEN(TRUNC(AG9))))),"") -> 0 | AJ9: =$CI9 -> 0 | AK9: =IF(V9="","",IF(AJ9=0,1,AJ9/$V9/$E9)) -> 1 | AL9: =IF(V9="","",MAX(ROUNDUP((IF(AI9+AJ9=0,0,AH9)+AI9+AK9-1),2),0)) -> 0 | AM9: =IF(V9="","",AG9+U9-AL9) -> 0 | AP9: =$CJ9 -> 0 | AU9: =CK9 -> 0 | AV9: =CL9 -> 0 | AW9: =SUM(AO9:AV9) -> 0 | AX9: =IF(V9="","",INT(AW9/$V9)) -> 0 | AY9: =IF(V9="","",AW9-AL9*$E9*$V9) -> 0 | AZ9: =IF($V9="","",AY9/$V9) -> 0 | BA9: =AM9 -> 0 | BB9: =VALUE("0"&RIGHT(BA9,(LEN(BA9)-LEN(TRUNC(BA9))))) -> 0 | BD9: =$CM9 -> 0 | BE9: =IF(AA9="","",IF(BD9=0,1,BD9/$V9/$E9)) -> 1 | BF9: =IF(V9="","",MAX(ROUNDUP((IF(BC9+BD9=0,0,BB9)+BC9+BE9-1),2),0)) -> 0 | BG9: =IF(AA9="","",BA9-BF9) -> 0 | BJ9: =$CN9 -> 0 | BO9: =CO9 -> 0 | BP9: =CP9 -> 0 | BQ9: =SUM(BI9:BP9) -> 0 | BR9: =IF(AA9="","",INT(BQ9/$V9)) -> 0 | BS9: =IF(AA9="","",-BF9*$E9*$V9+BQ9) -> 0 | BT9: =IF($V9="","",BS9/$V9) -> 0 | BU9: =IFERROR(AE9,"") -> 0 | BV9: =IFERROR(BF9+AL9,"") -> 0 | BW9: =IFERROR(BT9+AZ9,"") -> 0 | BX9: =IF($Q9="","",(BF9+AL9)*$Q9) -> 0 | BY9: =IFERROR(BF9+AL9,0) -> 0 | BZ9: =BY9 -> 0 | CA9: =IFERROR((BQ9+AW9)/1000,"") -> 0 | CB9: =IFERROR(BR9+AX9,"") -> 0 | CC9: =IFERROR(BS9+AY9,"") -> 0 | CD9: =IFERROR(BT9+AZ9,"") -> 0 | CG9: =IF(BX9="",0,(BX9-CA9)+((AV9+BP9)/1000)) -> 0 | CH9: =CG9 -> 0 | CQ9: =INT(IFERROR( CJ9/$V9,0)) -> 0 | CR9: =INT(IFERROR( CK9/$V9,0)) -> 0 | CS9: =INT(IFERROR( CL9/$V9,0)) -> 0 | CT9: =INT(IFERROR( AE9-CQ9-CU9-CR9,0)) -> 0 | CU9: =INT(IFERROR( AC9-CR9,0)) -> 0 | CV9: =INT(IFERROR( AD9-CS9,0)) -> 0 | CX9: 67 | CY9: =INT(60/CX9*60*(12-(CEILING((60/CX9*60*12)/E9,1)*IF(CW9="T",0.45,IF(CW9="",5,3))/60))) -> 282 | CZ9: =IF(CX9="",0,(IF(CW9="",360,180)/(60/CX9))*1.35) -> 542.7 | DE9: =IFERROR(CQ9+CR9,"") -> 0 | DF9: =IFERROR(AL9,"") -> 0 | DG9: =IFERROR(AZ9,"") -> 0 | DH9: =IFERROR(CT9+CU9,"") -> 0 | DI9: =IFERROR(BF9,"") -> 0 | DJ9: =IFERROR(BT9,"") -> 0 | DK9: =IFERROR(DE9+DH9,"") -> 0 | DL9: =IFERROR(DF9+DI9,"") -> 0 | DM9: =IFERROR(DG9+DJ9,"") -> 0 | DN9: =T9 -> 0 | DO9: =U9 -> 0 | DW9: =IFERROR(BU9+BV9,"") -> 0 | DX9: =IFERROR(DK9+DL9+DM9,"") -> 0 | DY9: =CQ9+CR9+CS9+CT9+CU9+CV9 -> 0 | DZ9: =IFERROR((AD9*V9/1000),0) -> 0 | EA9: =IFERROR((AE9*V9/1000),0) -> 0 | EB9: =BX9-EA9 -> 0 | EC9: =(BX9-CA9)+((AV9+BP9)/1000) -> 0
A10: 3 | B10: C03 | D10: SM04 | E10: 70 | F10: D | G10: =CONCATENATE(K10,J10,"-",IF(N10="D",L10,IF(N10="H",CONCATENATE(N10,L10),CONCATENATE(N10,L10,"x",M10))),"x",P10,"-",O10,R10) -> GWA6063-T5-17x3-H9B15 | H10: =CONCATENATE(J10,,K10,L10,M10,N10,O10) -> A6063-T5GW170DH9 | I10: =CONCATENATE(J10,K10,L10,M10,N10,O10,P10,R10) -> A6063-T5GW170DH93B15 | J10: A6063-T5 | K10: GW | L10: 17 | M10: 0 | N10: D | O10: H9 | P10: 3 | Q10: 1.832 | R10: B15 | S10: =ROUND(CY10/E10,0)*2 -> 22 | T10: 6 | U10: 20 | V10: 10.1 | W10: =IF(V10="","",INT((AO10+BI10)/$V10)) -> 0 | X10: =IF(V10="","",INT((AP10+BJ10)/$V10)) -> 1445 | Y10: =IF(V10="","",INT((AQ10+BK10)/$V10)) -> 0 | Z10: =IF(V10="","",INT((AR10+BL10)/$V10)) -> 0 | AA10: =IF(V10="","",INT((AS10+BM10)/$V10)) -> 0 | AB10: =IF(V10="","",INT((AT10+BN10)/$V10)) -> 0 | AC10: =IF(V10="","",INT((AU10+BO10)/$V10)) -> 0 | AD10: =IF(V10="","",INT((AV10+BP10)/$V10)) -> 14 | AE10: =IF(V10="","",SUM(W10:AC10)) -> 1445 | AF10: =AE10 -> 1445 | AG10: =T10 -> 6 | AH10: =IFERROR(VALUE("0"&RIGHT(AG10,(LEN(AG10)-LEN(TRUNC(AG10))))),"") -> 0 | AI10: 9 | AJ10: =$CI10 -> 0 | AK10: =IF(V10="","",IF(AJ10=0,1,AJ10/$V10/$E10)) -> 1 | AL10: =IF(V10="","",MAX(ROUNDUP((IF(AI10+AJ10=0,0,AH10)+AI10+AK10-1),2),0)) -> 9 | AM10: =IF(V10="","",AG10+U10-AL10) -> 17 | AP10: =$CJ10 -> 5900 | AU10: =CK10 -> 0 | AV10: =CL10 -> 0 | AW10: =SUM(AO10:AV10) -> 5900 | AX10: =IF(V10="","",INT(AW10/$V10)) -> 584 | AY10: =IF(V10="","",AW10-AL10*$E10*$V10) -> -463 | AZ10: =IF($V10="","",AY10/$V10) -> -45.841584 | BA10: =AM10 -> 17 | BB10: =VALUE("0"&RIGHT(BA10,(LEN(BA10)-LEN(TRUNC(BA10))))) -> 0 | BC10: 13 | BD10: =$CM10 -> 0 | BE10: =IF(AA10="","",IF(BD10=0,1,BD10/$V10/$E10)) -> 1 | BF10: =IF(V10="","",MAX(ROUNDUP((IF(BC10+BD10=0,0,BB10)+BC10+BE10-1),2),0)) -> 13 | BG10: =IF(AA10="","",BA10-BF10) -> 4 | BJ10: =$CN10 -> 8700 | BO10: =CO10 -> 0 | BP10: =CP10 -> 145 | BQ10: =SUM(BI10:BP10) -> 8845 | BR10: =IF(AA10="","",INT(BQ10/$V10)) -> 875 | BS10: =IF(AA10="","",-BF10*$E10*$V10+BQ10) -> -346 | BT10: =IF($V10="","",BS10/$V10) -> -34.257426 | BU10: =IFERROR(AE10,"") -> 1445 | BV10: =IFERROR(BF10+AL10,"") -> 22 | BW10: =IFERROR(BT10+AZ10,"") -> -80.09901 | BX10: =IF($Q10="","",(BF10+AL10)*$Q10) -> 40.304 | BY10: =IFERROR(BF10+AL10,0) -> 22 | BZ10: =BY10 -> 22 | CA10: =IFERROR((BQ10+AW10)/1000,"") -> 14.745 | CB10: =IFERROR(BR10+AX10,"") -> 1459 | CC10: =IFERROR(BS10+AY10,"") -> -809 | CD10: =IFERROR(BT10+AZ10,"") -> -80.09901 | CG10: =IF(BX10="",0,(BX10-CA10)+((AV10+BP10)/1000)) -> 25.704 | CH10: =CG10 -> 25.704 | CJ10: 5900 | CN10: 8700 | CP10: 145 | CQ10: =INT(IFERROR( CJ10/$V10,0)) -> 584 | CR10: =INT(IFERROR( CK10/$V10,0)) -> 0 | CS10: =INT(IFERROR( CL10/$V10,0)) -> 0 | CT10: =INT(IFERROR( AE10-CQ10-CU10-CR10,0)) -> 861 | CU10: =INT(IFERROR( AC10-CR10,0)) -> 0 | CV10: =INT(IFERROR( AD10-CS10,0)) -> 14 | CX10: 51 | CY10: =INT(60/CX10*60*(12-(CEILING((60/CX10*60*12)/E10,1)*IF(CW10="T",0.45,IF(CW10="",5,3))/60))) -> 770 | CZ10: =IF(CX10="",0,(IF(CW10="",360,180)/(60/CX10))*1.35) -> 413.1 | DE10: =IFERROR(CQ10+CR10,"") -> 584 | DF10: =IFERROR(AL10,"") -> 9 | DG10: =IFERROR(AZ10,"") -> -45.841584 | DH10: =IFERROR(CT10+CU10,"") -> 861 | DI10: =IFERROR(BF10,"") -> 13 | DJ10: =IFERROR(BT10,"") -> -34.257426 | DK10: =IFERROR(DE10+DH10,"") -> 1445 | DL10: =IFERROR(DF10+DI10,"") -> 22 | DM10: =IFERROR(DG10+DJ10,"") -> -80.09901 | DN10: =T10 -> 6 | DO10: =U10 -> 20 | DR10: B15C030515 | DW10: =IFERROR(AL10+BF10,"") -> 22 | DX10: =IFERROR(DK10+DL10+DM10,"") -> 1386.901 | DY10: =CQ10+CR10+CS10+CT10+CU10+CV10 -> 1459 | DZ10: =IFERROR((AD10*V10/1000),0) -> 0.1414 | EA10: =IFERROR((AE10*V10/1000),0) -> 14.5945 | EB10: =BX10-EA10 -> 25.7095 | EC10: =(BX10-CA10)+((AV10+BP10)/1000) -> 25.704 | EF10: =DG10+DJ10 -> -80.09901
A11: 4 | B11: C04 | D11: 020 | E11: 283 | F11: B | G11: =CONCATENATE(K11,J11,"-",IF(N11="D",L11,IF(N11="H",CONCATENATE(N11,L11),CONCATENATE(N11,L11,"x",M11))),"x",P11,"-",O11,R11) -> TV12L14-11x2.5-H9C14 | H11: =CONCATENATE(J11,,K11,L11,M11,N11,O11) -> 12L14TV110DH9 | I11: =CONCATENATE(J11,K11,L11,M11,N11,O11,P11,R11) -> 12L14TV110DH92.5C14 | J11: 12L14 | K11: TV | L11: 11 | M11: 0 | N11: D | O11: H9 | P11: 2.5 | R11: C14 | S11: =ROUND(CY11/E11,0)*2 -> 12 | T11: 0.71 | U11: 20 | V11: 2 | W11: =IF(V11="","",INT((AO11+BI11)/$V11)) -> 0 | X11: =IF(V11="","",INT((AP11+BJ11)/$V11)) -> 1673 | Y11: =IF(V11="","",INT((AQ11+BK11)/$V11)) -> 0 | Z11: =IF(V11="","",INT((AR11+BL11)/$V11)) -> 0 | AA11: =IF(V11="","",INT((AS11+BM11)/$V11)) -> 0 | AB11: =IF(V11="","",INT((AT11+BN11)/$V11)) -> 0 | AC11: =IF(V11="","",INT((AU11+BO11)/$V11)) -> 0 | AD11: =IF(V11="","",INT((AV11+BP11)/$V11)) -> 0 | AE11: =IF(V11="","",SUM(W11:AC11)) -> 1673 | AF11: =AE11 -> 1673 | AG11: =T11 -> 0.71 | AH11: =IFERROR(VALUE("0"&RIGHT(AG11,(LEN(AG11)-LEN(TRUNC(AG11))))),"") -> 0.71 | AI11: 6 | AJ11: =$CI11 -> 0 | AK11: =IF(V11="","",IF(AJ11=0,1,AJ11/$V11/$E11)) -> 1 | AL11: =IF(V11="","",MAX(ROUNDUP((IF(AI11+AJ11=0,0,AH11)+AI11+AK11-1),2),0)) -> 6.71 | AM11: =IF(V11="","",AG11+U11-AL11) -> 14 | AP11: =$CJ11 -> 3347 | AU11: =CK11 -> 0 | AV11: =CL11 -> 0 | AW11: =SUM(AO11:AV11) -> 3347 | AX11: =IF(V11="","",INT(AW11/$V11)) -> 1673 | AY11: =IF(V11="","",AW11-AL11*$E11*$V11) -> -450.86 | AZ11: =IF($V11="","",AY11/$V11) -> -225.43 | BA11: =AM11 -> 14 | BB11: =VALUE("0"&RIGHT(BA11,(LEN(BA11)-LEN(TRUNC(BA11))))) -> 0 | BD11: =$CM11 -> 0 | BE11: =IF(AA11="","",IF(BD11=0,1,BD11/$V11/$E11)) -> 1 | BF11: =IF(V11="","",MAX(ROUNDUP((IF(BC11+BD11=0,0,BB11)+BC11+BE11-1),2),0)) -> 0 | BG11: =IF(AA11="","",BA11-BF11) -> 14 | BJ11: =$CN11 -> 0 | BO11: =CO11 -> 0 | BP11: =CP11 -> 0 | BQ11: =SUM(BI11:BP11) -> 0 | BR11: =IF(AA11="","",INT(BQ11/$V11)) -> 0 | BS11: =IF(AA11="","",-BF11*$E11*$V11+BQ11) -> 0 | BT11: =IF($V11="","",BS11/$V11) -> 0 | BU11: =IFERROR(AE11,"") -> 1673 | BV11: =IFERROR(BF11+AL11,"") -> 6.71 | BW11: =IFERROR(BT11+AZ11,"") -> -225.43 | BX11: =IF($Q11="","",(BF11+AL11)*$Q11) | BY11: =IFERROR(BF11+AL11,0) -> 6.71 | BZ11: =BY11 -> 6.71 | CA11: =IFERROR((BQ11+AW11)/1000,"") -> 3.347 | CB11: =IFERROR(BR11+AX11,"") -> 1673 | CC11: =IFERROR(BS11+AY11,"") -> -450.86 | CD11: =IFERROR(BT11+AZ11,"") -> -225.43 | CG11: =IF(BX11="",0,(BX11-CA11)+((AV11+BP11)/1000)) -> 0 | CH11: =CG11 -> 0 | CJ11: 3347 | CQ11: =INT(IFERROR( CJ11/$V11,0)) -> 1673 | CR11: =INT(IFERROR( CK11/$V11,0)) -> 0 | CS11: =INT(IFERROR( CL11/$V11,0)) -> 0 | CT11: =INT(IFERROR( AE11-CQ11-CU11-CR11,0)) -> 0 | CU11: =INT(IFERROR( AC11-CR11,0)) -> 0 | CV11: =INT(IFERROR( AD11-CS11,0)) -> 0 | CX11: 25 | CY11: =INT(60/CX11*60*(12-(CEILING((60/CX11*60*12)/E11,1)*IF(CW11="T",0.45,IF(CW11="",5,3))/60))) -> 1644 | CZ11: =IF(CX11="",0,(IF(CW11="",360,180)/(60/CX11))*1.35) -> 202.5 | DE11: =IFERROR(CQ11+CR11,"") -> 1673 | DF11: =IFERROR(AL11,"") -> 6.71 | DG11: =IFERROR(AZ11,"") -> -225.43 | DH11: =IFERROR(CT11+CU11,"") -> 0 | DI11: =IFERROR(BF11,"") -> 0 | DJ11: =IFERROR(BT11,"") -> 0 | DK11: =IFERROR(DE11+DH11,"") -> 1673 | DL11: =IFERROR(DF11+DI11,"") -> 6.71 | DM11: =IFERROR(DG11+DJ11,"") -> -225.43 | DN11: 0 | DO11: =U11 -> 20 | DR11: C14C120515 | DW11: =IFERROR(BU11+BV11,"") -> 1679.71 | DX11: =IFERROR(DK11+DL11+DM11,"") -> 1454.28 | DY11: =CQ11+CR11+CS11+CT11+CU11+CV11 -> 1673 | DZ11: =IFERROR((AD11*V11/1000),0) -> 0 | EA11: =IFERROR((AE11*V11/1000),0) -> 3.346 | EB11: =BX11-EA11 -> #VALUE! | EC11: =(BX11-CA11)+((AV11+BP11)/1000) -> #VALUE! | EF11: =DG11+DJ11 -> -225.43
A12: 5 | B12: C05 | D12: 10620 | E12: 127 | F12: A | G12: =CONCATENATE(K12,J12,"-",IF(N12="D",L12,IF(N12="H",CONCATENATE(N12,L12),CONCATENATE(N12,L12,"x",M12))),"x",P12,"-",O12,R12) -> DCC3604-10x3-H9B12 | H12: =CONCATENATE(J12,,K12,L12,M12,N12,O12) -> C3604DC100DH9 | I12: =CONCATENATE(J12,K12,L12,M12,N12,O12,P12,R12) -> C3604DC100DH93B12 | J12: C3604 | K12: DC | L12: 10 | M12: 0 | N12: D | O12: H9 | P12: 3 | Q12: 2 | R12: B12 | S12: =ROUND(CY12/E12,0)*2 -> 26 | T12: 0 | V12: 7.46 | W12: =IF(V12="","",INT((AO12+BI12)/$V12)) -> 0 | X12: =IF(V12="","",INT((AP12+BJ12)/$V12)) -> 0 | Y12: =IF(V12="","",INT((AQ12+BK12)/$V12)) -> 0 | Z12: =IF(V12="","",INT((AR12+BL12)/$V12)) -> 0 | AA12: =IF(V12="","",INT((AS12+BM12)/$V12)) -> 0 | AB12: =IF(V12="","",INT((AT12+BN12)/$V12)) -> 0 | AC12: =IF(V12="","",INT((AU12+BO12)/$V12)) -> 0 | AD12: =IF(V12="","",INT((AV12+BP12)/$V12)) -> 0 | AE12: =IF(V12="","",SUM(W12:AC12)) -> 0 | AF12: =AE12 -> 0 | AG12: =T12 -> 0 | AH12: =IFERROR(VALUE("0"&RIGHT(AG12,(LEN(AG12)-LEN(TRUNC(AG12))))),"") -> 0 | AJ12: =$CI12 -> 0 | AK12: =IF(V12="","",IF(AJ12=0,1,AJ12/$V12/$E12)) -> 1 | AL12: =IF(V12="","",MAX(ROUNDUP((IF(AI12+AJ12=0,0,AH12)+AI12+AK12-1),2),0)) -> 0 | AM12: =IF(V12="","",AG12+U12-AL12) -> 0 | AP12: =$CJ12 -> 0 | AU12: =CK12 -> 0 | AV12: =CL12 -> 0 | AW12: =SUM(AO12:AV12) -> 0 | AX12: =IF(V12="","",INT(AW12/$V12)) -> 0 | AY12: =IF(V12="","",AW12-AL12*$E12*$V12) -> 0 | AZ12: =IF($V12="","",AY12/$V12) -> 0 | BA12: =AM12 -> 0 | BB12: =VALUE("0"&RIGHT(BA12,(LEN(BA12)-LEN(TRUNC(BA12))))) -> 0 | BD12: =$CM12 -> 0 | BE12: =IF(AA12="","",IF(BD12=0,1,BD12/$V12/$E12)) -> 1 | BF12: =IF(V12="","",MAX(ROUNDUP((IF(BC12+BD12=0,0,BB12)+BC12+BE12-1),2),0)) -> 0 | BG12: =IF(AA12="","",BA12-BF12) -> 0 | BJ12: =$CN12 -> 0 | BO12: =CO12 -> 0 | BP12: =CP12 -> 0 | BQ12: =SUM(BI12:BP12) -> 0 | BR12: =IF(AA12="","",INT(BQ12/$V12)) -> 0 | BS12: =IF(AA12="","",-BF12*$E12*$V12+BQ12) -> 0 | BT12: =IF($V12="","",BS12/$V12) -> 0 | BU12: =IFERROR(AE12,"") -> 0 | BV12: =IFERROR(BF12+AL12,"") -> 0 | BW12: =IFERROR(BT12+AZ12,"") -> 0 | BX12: =IF($Q12="","",(BF12+AL12)*$Q12) -> 0 | BY12: =IFERROR(BF12+AL12,0) -> 0 | BZ12: =BY12 -> 0 | CA12: =IFERROR((BQ12+AW12)/1000,"") -> 0 | CB12: =IFERROR(BR12+AX12,"") -> 0 | CC12: =IFERROR(BS12+AY12,"") -> 0 | CD12: =IFERROR(BT12+AZ12,"") -> 0 | CG12: =IF(BX12="",0,(BX12-CA12)+((AV12+BP12)/1000)) -> 0 | CH12: =CG12 -> 0 | CQ12: =INT(IFERROR( CJ12/$V12,0)) -> 0 | CR12: =INT(IFERROR( CK12/$V12,0)) -> 0 | CS12: =INT(IFERROR( CL12/$V12,0)) -> 0 | CT12: =INT(IFERROR( AE12-CQ12-CU12-CR12,0)) -> 0 | CU12: =INT(IFERROR( AC12-CR12,0)) -> 0 | CV12: =INT(IFERROR( AD12-CS12,0)) -> 0 | CX12: 24 | CY12: =INT(60/CX12*60*(12-(CEILING((60/CX12*60*12)/E12,1)*IF(CW12="T",0.45,IF(CW12="",5,3))/60))) -> 1612 | CZ12: =IF(CX12="",0,(IF(CW12="",360,180)/(60/CX12))*1.35) -> 194.4 | DE12: =IFERROR(CQ12+CR12,"") -> 0 | DF12: =IFERROR(AL12,"") -> 0 | DG12: =IFERROR(AZ12,"") -> 0 | DH12: =IFERROR(CT12+CU12,"") -> 0 | DI12: =IFERROR(BF12,"") -> 0 | DJ12: =IFERROR(BT12,"") -> 0 | DK12: =IFERROR(DE12+DH12,"") -> 0 | DL12: =IFERROR(DF12+DI12,"") -> 0 | DM12: =IFERROR(DG12+DJ12,"") -> 0 | DN12: =T12 -> 0 | DO12: =U12 -> 0 | DW12: =IFERROR(BU12+BV12,"") -> 0 | DX12: =IFERROR(DK12+DL12+DM12,"") -> 0 | DY12: =CQ12+CR12+CS12+CT12+CU12+CV12 -> 0 | DZ12: =IFERROR((AD12*V12/1000),0) -> 0 | EA12: =IFERROR((AE12*V12/1000),0) -> 0 | EB12: =BX12-EA12 -> 0 | EC12: =(BX12-CA12)+((AV12+BP12)/1000) -> 0
A13: 6 | B13: C06 | D13: 10620 | E13: 127 | F13: D | G13: =CONCATENATE(K13,J13,"-",IF(N13="D",L13,IF(N13="H",CONCATENATE(N13,L13),CONCATENATE(N13,L13,"x",M13))),"x",P13,"-",O13,R13) -> DCC3604-10x3-H9B12 | H13: =CONCATENATE(J13,,K13,L13,M13,N13,O13) -> C3604DC100DH9 | I13: =CONCATENATE(J13,K13,L13,M13,N13,O13,P13,R13) -> C3604DC100DH93B12 | J13: C3604 | K13: DC | L13: 10 | M13: 0 | N13: D | O13: H9 | P13: 3 | Q13: 2 | R13: B12 | S13: =ROUND(CY13/E13,0)*2 -> 40 | T13: 0 | U13: 15 | V13: 7.64 | W13: =IF(V13="","",INT((AO13+BI13)/$V13)) -> 0 | X13: =IF(V13="","",INT((AP13+BJ13)/$V13)) -> 1093 | Y13: =IF(V13="","",INT((AQ13+BK13)/$V13)) -> 0 | Z13: =IF(V13="","",INT((AR13+BL13)/$V13)) -> 0 | AA13: =IF(V13="","",INT((AS13+BM13)/$V13)) -> 0 | AB13: =IF(V13="","",INT((AT13+BN13)/$V13)) -> 0 | AC13: =IF(V13="","",INT((AU13+BO13)/$V13)) -> 0 | AD13: =IF(V13="","",INT((AV13+BP13)/$V13)) -> 89 | AE13: =IF(V13="","",SUM(W13:AC13)) -> 1093 | AF13: =AE13 -> 1093 | AG13: =T13 -> 0 | AH13: =IFERROR(VALUE("0"&RIGHT(AG13,(LEN(AG13)-LEN(TRUNC(AG13))))),"") -> 0 | AI13: 4 | AJ13: =$CI13 -> 0 | AK13: =IF(V13="","",IF(AJ13=0,1,AJ13/$V13/$E13)) -> 1 | AL13: =IF(V13="","",MAX(ROUNDUP((IF(AI13+AJ13=0,0,AH13)+AI13+AK13-1),2),0)) -> 4 | AM13: =IF(V13="","",AG13+U13-AL13) -> 11 | AP13: =$CJ13 -> 3962 | AU13: =CK13 -> 0 | AV13: =CL13 -> 298 | AW13: =SUM(AO13:AV13) -> 4260 | AX13: =IF(V13="","",INT(AW13/$V13)) -> 557 | AY13: =IF(V13="","",AW13-AL13*$E13*$V13) -> 378.88 | AZ13: =IF($V13="","",AY13/$V13) -> 49.591623 | BA13: =AM13 -> 11 | BB13: =VALUE("0"&RIGHT(BA13,(LEN(BA13)-LEN(TRUNC(BA13))))) -> 0 | BC13: 5 | BD13: =$CM13 -> 0 | BE13: =IF(AA13="","",IF(BD13=0,1,BD13/$V13/$E13)) -> 1 | BF13: =IF(V13="","",MAX(ROUNDUP((IF(BC13+BD13=0,0,BB13)+BC13+BE13-1),2),0)) -> 5 | BG13: =IF(AA13="","",BA13-BF13) -> 6 | BJ13: =$CN13 -> 4389 | BO13: =CO13 -> 0 | BP13: =CP13 -> 384 | BQ13: =SUM(BI13:BP13) -> 4773 | BR13: =IF(AA13="","",INT(BQ13/$V13)) -> 624 | BS13: =IF(AA13="","",-BF13*$E13*$V13+BQ13) -> -78.4 | BT13: =IF($V13="","",BS13/$V13) -> -10.26178 | BU13: =IFERROR(AE13,"") -> 1093 | BV13: =IFERROR(BF13+AL13,"") -> 9 | BW13: =IFERROR(BT13+AZ13,"") -> 39.329843 | BX13: =IF($Q13="","",(BF13+AL13)*$Q13) -> 18 | BY13: =IFERROR(BF13+AL13,0) -> 9 | BZ13: =BY13 -> 9 | CA13: =IFERROR((BQ13+AW13)/1000,"") -> 9.033 | CB13: =IFERROR(BR13+AX13,"") -> 1181 | CC13: =IFERROR(BS13+AY13,"") -> 300.48 | CD13: =IFERROR(BT13+AZ13,"") -> 39.329843 | CG13: =IF(BX13="",0,(BX13-CA13)+((AV13+BP13)/1000)) -> 9.649 | CH13: =CG13 -> 9.649 | CJ13: 3962 | CL13: 298 | CN13: 4389 | CP13: 384 | CQ13: =INT(IFERROR( CJ13/$V13,0)) -> 518 | CR13: =INT(IFERROR( CK13/$V13,0)) -> 0 | CS13: =INT(IFERROR( CL13/$V13,0)) -> 39 | CT13: =INT(IFERROR( AE13-CQ13-CU13-CR13,0)) -> 575 | CU13: =INT(IFERROR( AC13-CR13,0)) -> 0 | CV13: =INT(IFERROR( AD13-CS13,0)) -> 50 | CX13: 14 | CY13: =INT(60/CX13*60*(12-(CEILING((60/CX13*60*12)/E13,1)*IF(CW13="T",0.45,IF(CW13="",5,3))/60))) -> 2550 | CZ13: =IF(CX13="",0,(IF(CW13="",360,180)/(60/CX13))*1.35) -> 113.4 | DE13: =IFERROR(CQ13+CR13,"") -> 518 | DF13: =IFERROR(AL13,"") -> 4 | DG13: =IFERROR(AZ13,"") -> 49.591623 | DH13: =IFERROR(CT13+CU13,"") -> 575 | DI13: =IFERROR(BF13,"") -> 5 | DJ13: =IFERROR(BT13,"") -> -10.26178 | DK13: =IFERROR(DE13+DH13,"") -> 1093 | DL13: =IFERROR(DF13+DI13,"") -> 9 | DM13: =IFERROR(DG13+DJ13,"") -> 39.329843 | DN13: =T13 -> 0 | DO13: =U13 -> 15 | DR13: B15C060515 | DW13: =IFERROR(BU13+BV13,"") -> 1102 | DX13: =IFERROR(DK13+DL13+DM13,"") -> 1141.3298 | DY13: =CQ13+CR13+CS13+CT13+CU13+CV13 -> 1182 | DZ13: =IFERROR((AD13*V13/1000),0) -> 0.67996 | EA13: =IFERROR((AE13*V13/1000),0) -> 8.35052 | EB13: =BX13-EA13 -> 9.64948 | EC13: =(BX13-CA13)+((AV13+BP13)/1000) -> 9.649
A14: 7 | B14: C07 | D14: H7 | E14: 60 | F14: A | G14: =CONCATENATE(K14,J14,"-",IF(N14="D",L14,IF(N14="H",CONCATENATE(N14,L14),CONCATENATE(N14,L14,"x",M14))),"x",P14,"-",O14,R14) -> IBC3602-7.5x3-H9A14 | H14: =CONCATENATE(J14,,K14,L14,M14,N14,O14) -> C3602IB7.50DH9 | I14: =CONCATENATE(J14,K14,L14,M14,N14,O14,P14,R14) -> C3602IB7.50DH93A14 | J14: C3602 | K14: IB | L14: 7.5 | M14: 0 | N14: D | O14: H9 | P14: 3 | Q14: 1.122 | R14: A14 | S14: =ROUND(CY14/E14,0)*2 -> 100 | T14: 0 | V14: 10.8 | W14: =IF(V14="","",INT((AO14+BI14)/$V14)) -> 0 | X14: =IF(V14="","",INT((AP14+BJ14)/$V14)) -> 0 | Y14: =IF(V14="","",INT((AQ14+BK14)/$V14)) -> 0 | Z14: =IF(V14="","",INT((AR14+BL14)/$V14)) -> 0 | AA14: =IF(V14="","",INT((AS14+BM14)/$V14)) -> 0 | AB14: =IF(V14="","",INT((AT14+BN14)/$V14)) -> 0 | AC14: =IF(V14="","",INT((AU14+BO14)/$V14)) -> 0 | AD14: =IF(V14="","",INT((AV14+BP14)/$V14)) -> 0 | AE14: =IF(V14="","",SUM(W14:AC14)) -> 0 | AF14: =AE14 -> 0 | AG14: =T14 -> 0 | AH14: =IFERROR(VALUE("0"&RIGHT(AG14,(LEN(AG14)-LEN(TRUNC(AG14))))),"") -> 0 | AJ14: =$CI14 -> 0 | AK14: =IF(V14="","",IF(AJ14=0,1,AJ14/$V14/$E14)) -> 1 | AL14: =IF(V14="","",MAX(ROUNDUP((IF(AI14+AJ14=0,0,AH14)+AI14+AK14-1),2),0)) -> 0 | AM14: =IF(V14="","",AG14+U14-AL14) -> 0 | AT14: =$CJ14 -> 0 | AU14: =CK14 -> 0 | AV14: =CL14 -> 0 | AW14: =SUM(AO14:AV14) -> 0 | AX14: =IF(V14="","",INT(AW14/$V14)) -> 0 | AY14: =IF(V14="","",AW14-AL14*$E14*$V14) -> 0 | AZ14: =IF($V14="","",AY14/$V14) -> 0 | BA14: =AM14 -> 0 | BB14: =VALUE("0"&RIGHT(BA14,(LEN(BA14)-LEN(TRUNC(BA14))))) -> 0 | BD14: =$CM14 -> 0 | BE14: =IF(AA14="","",IF(BD14=0,1,BD14/$V14/$E14)) -> 1 | BF14: =IF(V14="","",MAX(ROUNDUP((IF(BC14+BD14=0,0,BB14)+BC14+BE14-1),2),0)) -> 0 | BG14: =IF(AA14="","",BA14-BF14) -> 0 | BN14: =$CN14 -> 0 | BO14: =CO14 -> 0 | BP14: =CP14 -> 0 | BQ14: =SUM(BI14:BP14) -> 0 | BR14: =IF(AA14="","",INT(BQ14/$V14)) -> 0 | BS14: =IF(AA14="","",-BF14*$E14*$V14+BQ14) -> 0 | BT14: =IF($V14="","",BS14/$V14) -> 0 | BU14: =IFERROR(AE14,"") -> 0 | BV14: =IFERROR(BF14+AL14,"") -> 0 | BW14: =IFERROR(BT14+AZ14,"") -> 0 | BX14: =IF($Q14="","",(BF14+AL14)*$Q14) -> 0 | BY14: =IFERROR(BF14+AL14,0) -> 0 | BZ14: =BY14 -> 0 | CA14: =IFERROR((BQ14+AW14)/1000,"") -> 0 | CB14: =IFERROR(BR14+AX14,"") -> 0 | CC14: =IFERROR(BS14+AY14,"") -> 0 | CD14: =IFERROR(BT14+AZ14,"") -> 0 | CG14: =IF(BX14="",0,(BX14-CA14)+((AV14+BP14)/1000)) -> 0 | CH14: =CG14 -> 0 | CQ14: =INT(IFERROR( CJ14/$V14,0)) -> 0 | CR14: =INT(IFERROR( CK14/$V14,0)) -> 0 | CS14: =INT(IFERROR( CL14/$V14,0)) -> 0 | CT14: =INT(IFERROR( AE14-CQ14-CU14-CR14,0)) -> 0 | CU14: =INT(IFERROR( AC14-CR14,0)) -> 0 | CV14: =INT(IFERROR( AD14-CS14,0)) -> 0 | CW14: T | CX14: 14 | CY14: =INT(60/CX14*60*(12-(CEILING((60/CX14*60*12)/E14,1)*IF(CW14="T",0.45,IF(CW14="",5,3))/60))) -> 2985 | CZ14: =IF(CX14="",0,(IF(CW14="",360,180)/(60/CX14))*1.35) -> 56.7 | DE14: =IFERROR(CQ14+CR14,"") -> 0 | DF14: =IFERROR(AL14,"") -> 0 | DG14: =IFERROR(AZ14,"") -> 0 | DH14: =IFERROR(CT14+CU14,"") -> 0 | DI14: =IFERROR(BF14,"") -> 0 | DJ14: =IFERROR(BT14,"") -> 0 | DK14: =IFERROR(DE14+DH14,"") -> 0 | DL14: =IFERROR(DF14+DI14,"") -> 0 | DM14: =IFERROR(DG14+DJ14,"") -> 0 | DN14: =T14 -> 0 | DO14: =U14 -> 0 | DW14: =IFERROR(BU14+BV14,"") -> 0 | DX14: =IFERROR(DK14+DL14+DM14,"") -> 0 | DY14: =CQ14+CR14+CS14+CT14+CU14+CV14 -> 0 | DZ14: =IFERROR((AD14*V14/1000),0) -> 0 | EA14: =IFERROR((AE14*V14/1000),0) -> 0 | EB14: =BX14-EA14 -> 0 | EC14: =(BX14-CA14)+((AV14+BP14)/1000) -> 0
A15: 8 | B15: C08 | D15: S5 | E15: 30 | F15: B | G15: =CONCATENATE(K15,J15,"-",IF(N15="D",L15,IF(N15="H",CONCATENATE(N15,L15),CONCATENATE(N15,L15,"x",M15))),"x",P15,"-",O15,R15) -> TV12L14-H6x2.5-H11A14 | H15: =CONCATENATE(J15,,K15,L15,M15,N15,O15) -> 12L14TV60HH11 | I15: =CONCATENATE(J15,K15,L15,M15,N15,O15,P15,R15) -> 12L14TV60HH112.5A14 | J15: 12L14 | K15: TV | L15: 6 | M15: 0 | N15: H | O15: H11 | P15: 2.5 | Q15: 0.606 | R15: A14 | S15: =ROUND(CY15/E15,0)*2 -> 50 | T15: 0 | V15: 16.15 | W15: =IF(V15="","",INT((AO15+BI15)/$V15)) -> 0 | X15: =IF(V15="","",INT((AP15+BJ15)/$V15)) -> 0 | Y15: =IF(V15="","",INT((AQ15+BK15)/$V15)) -> 0 | Z15: =IF(V15="","",INT((AR15+BL15)/$V15)) -> 0 | AA15: =IF(V15="","",INT((AS15+BM15)/$V15)) -> 0 | AB15: =IF(V15="","",INT((AT15+BN15)/$V15)) -> 0 | AC15: =IF(V15="","",INT((AU15+BO15)/$V15)) -> 0 | AD15: =IF(V15="","",INT((AV15+BP15)/$V15)) -> 0 | AE15: =IF(V15="","",SUM(W15:AC15)) -> 0 | AF15: =AE15 -> 0 | AG15: =T15 -> 0 | AH15: =IFERROR(VALUE("0"&RIGHT(AG15,(LEN(AG15)-LEN(TRUNC(AG15))))),"") -> 0 | AJ15: =$CI15 -> 0 | AK15: =IF(V15="","",IF(AJ15=0,1,AJ15/$V15/$E15)) -> 1 | AL15: =IF(V15="","",MAX(ROUNDUP((IF(AI15+AJ15=0,0,AH15)+AI15+AK15-1),2),0)) -> 0 | AM15: =IF(V15="","",AG15+U15-AL15) -> 0 | AO15: =$CJ15 -> 0 | AU15: =CK15 -> 0 | AV15: =CL15 -> 0 | AW15: =SUM(AO15:AV15) -> 0 | AX15: =IF(V15="","",INT(AW15/$V15)) -> 0 | AY15: =IF(V15="","",AW15-AL15*$E15*$V15) -> 0 | AZ15: =IF($V15="","",AY15/$V15) -> 0 | BA15: =AM15 -> 0 | BB15: =VALUE("0"&RIGHT(BA15,(LEN(BA15)-LEN(TRUNC(BA15))))) -> 0 | BD15: =$CM15 -> 0 | BE15: =IF(AA15="","",IF(BD15=0,1,BD15/$V15/$E15)) -> 1 | BF15: =IF(V15="","",MAX(ROUNDUP((IF(BC15+BD15=0,0,BB15)+BC15+BE15-1),2),0)) -> 0 | BG15: =IF(AA15="","",BA15-BF15) -> 0 | BI15: =$CN15 -> 0 | BO15: =CO15 -> 0 | BP15: =CP15 -> 0 | BQ15: =SUM(BI15:BP15) -> 0 | BR15: =IF(AA15="","",INT(BQ15/$V15)) -> 0 | BS15: =IF(AA15="","",-BF15*$E15*$V15+BQ15) -> 0 | BT15: =IF($V15="","",BS15/$V15) -> 0 | BU15: =IFERROR(AE15,"") -> 0 | BV15: =IFERROR(BF15+AL15,"") -> 0 | BW15: =IFERROR(BT15+AZ15,"") -> 0 | BX15: =IF($Q15="","",(BF15+AL15)*$Q15) -> 0 | BY15: =IFERROR(BF15+AL15,0) -> 0 | BZ15: =BY15 -> 0 | CA15: =IFERROR((BQ15+AW15)/1000,"") -> 0 | CB15: =IFERROR(BR15+AX15,"") -> 0 | CC15: =IFERROR(BS15+AY15,"") -> 0 | CD15: =IFERROR(BT15+AZ15,"") -> 0 | CG15: =IF(BX15="",0,(BX15-CA15)+((AV15+BP15)/1000)) -> 0 | CH15: =CG15 -> 0 | CQ15: =INT(IFERROR( CJ15/$V15,0)) -> 0 | CR15: =INT(IFERROR( CK15/$V15,0)) -> 0 | CS15: =INT(IFERROR( CL15/$V15,0)) -> 0 | CT15: =INT(IFERROR( AE15-CQ15-CU15-CR15,0)) -> 0 | CU15: =INT(IFERROR( AC15-CR15,0)) -> 0 | CV15: =INT(IFERROR( AD15-CS15,0)) -> 0 | CX15: 45 | CY15: =INT(60/CX15*60*(12-(CEILING((60/CX15*60*12)/E15,1)*IF(CW15="T",0.45,IF(CW15="",5,3))/60))) -> 746 | CZ15: =IF(CX15="",0,(IF(CW15="",360,180)/(60/CX15))*1.35) -> 364.5 | DE15: =IFERROR(CQ15+CR15,"") -> 0 | DF15: =IFERROR(AL15,"") -> 0 | DG15: =IFERROR(AZ15,"") -> 0 | DH15: =IFERROR(CT15+CU15,"") -> 0 | DI15: =IFERROR(BF15,"") -> 0 | DJ15: =IFERROR(BT15,"") -> 0 | DK15: =IFERROR(DE15+DH15,"") -> 0 | DL15: =IFERROR(DF15+DI15,"") -> 0 | DM15: =IFERROR(DG15+DJ15,"") -> 0 | DN15: =T15 -> 0 | DO15: =U15 -> 0 | DW15: =IFERROR(BU15+BV15,"") -> 0 | DX15: =IFERROR(DK15+DL15+DM15,"") -> 0 | DY15: =CQ15+CR15+CS15+CT15+CU15+CV15 -> 0 | DZ15: =IFERROR((AD15*V15/1000),0) -> 0 | EA15: =IFERROR((AE15*V15/1000),0) -> 0 | EB15: =BX15-EA15 -> 0 | EC15: =EB15+DZ15 -> 0 | EF15: =DG15+DJ15 -> 0
A16: 9 | B16: C09 | D16: 131100 | E16: 68 | F16: D | G16: =CONCATENATE(K16,J16,"-",IF(N16="D",L16,IF(N16="H",CONCATENATE(N16,L16),CONCATENATE(N16,L16,"x",M16))),"x",P16,"-",O16,R16) -> GWA6063-T5-T18.15x8.6x3-H9A15 | H16: =CONCATENATE(J16,,K16,L16,M16,N16,O16) -> A6063-T5GW18.158.6TH9 | I16: =CONCATENATE(J16,K16,L16,M16,N16,O16,P16,R16) -> A6063-T5GW18.158.6TH93A15 | J16: A6063-T5 | K16: GW | L16: 18.15 | M16: 8.6 | N16: T | O16: H9 | P16: 3 | Q16: 1.641 | R16: A15 | S16: =ROUND(CY16/E16,0)*2 -> 14 | T16: 0 | V16: 9.9 | W16: =IF(V16="","",INT((AO16+BI16)/$V16)) -> 0 | X16: =IF(V16="","",INT((AP16+BJ16)/$V16)) -> 0 | Y16: =IF(V16="","",INT((AQ16+BK16)/$V16)) -> 0 | Z16: =IF(V16="","",INT((AR16+BL16)/$V16)) -> 0 | AA16: =IF(V16="","",INT((AS16+BM16)/$V16)) -> 0 | AB16: =IF(V16="","",INT((AT16+BN16)/$V16)) -> 0 | AC16: =IF(V16="","",INT((AU16+BO16)/$V16)) -> 0 | AD16: =IF(V16="","",INT((AV16+BP16)/$V16)) -> 0 | AE16: =IF(V16="","",SUM(W16:AC16)) -> 0 | AF16: =AE16 -> 0 | AG16: =T16 -> 0 | AH16: =IFERROR(VALUE("0"&RIGHT(AG16,(LEN(AG16)-LEN(TRUNC(AG16))))),"") -> 0 | AJ16: =$CI16 -> 0 | AK16: =IF(V16="","",IF(AJ16=0,1,AJ16/$V16/$E16)) -> 1 | AL16: =IF(V16="","",MAX(ROUNDUP((IF(AI16+AJ16=0,0,AH16)+AI16+AK16-1),2),0)) -> 0 | AM16: =IF(V16="","",AG16+U16-AL16) -> 0 | AP16: =$CJ16 -> 0 | AU16: =CK16 -> 0 | AV16: =CL16 -> 0 | AW16: =SUM(AO16:AV16) -> 0 | AX16: =IF(V16="","",INT(AW16/$V16)) -> 0 | AY16: =IF(V16="","",AW16-AL16*$E16*$V16) -> 0 | AZ16: =IF($V16="","",AY16/$V16) -> 0 | BA16: =AM16 -> 0 | BB16: =VALUE("0"&RIGHT(BA16,(LEN(BA16)-LEN(TRUNC(BA16))))) -> 0 | BD16: =$CM16 -> 0 | BE16: =IF(AA16="","",IF(BD16=0,1,BD16/$V16/$E16)) -> 1 | BF16: =IF(V16="","",MAX(ROUNDUP((IF(BC16+BD16=0,0,BB16)+BC16+BE16-1),2),0)) -> 0 | BG16: =IF(AA16="","",BA16-BF16) -> 0 | BJ16: =$CN16 -> 0 | BO16: =CO16 -> 0 | BP16: =CP16 -> 0 | BQ16: =SUM(BI16:BP16) -> 0 | BR16: =IF(AA16="","",INT(BQ16/$V16)) -> 0 | BS16: =IF(AA16="","",-BF16*$E16*$V16+BQ16) -> 0 | BT16: =IF($V16="","",BS16/$V16) -> 0 | BU16: =IFERROR(AE16,"") -> 0 | BV16: =IFERROR(BF16+AL16,"") -> 0 | BW16: =IFERROR(BT16+AZ16,"") -> 0 | BX16: =IF($Q16="","",(BF16+AL16)*$Q16) -> 0 | BY16: =IFERROR(BF16+AL16,0) -> 0 | BZ16: =BY16 -> 0 | CA16: =IFERROR((BQ16+AW16)/1000,"") -> 0 | CB16: =IFERROR(BR16+AX16,"") -> 0 | CC16: =IFERROR(BS16+AY16,"") -> 0 | CD16: =IFERROR(BT16+AZ16,"") -> 0 | CG16: =IF(BX16="",0,(BX16-CA16)+((AV16+BP16)/1000)) -> 0 | CH16: =CG16 -> 0 | CQ16: =INT(IFERROR( CJ16/$V16,0)) -> 0 | CR16: =INT(IFERROR( CK16/$V16,0)) -> 0 | CS16: =INT(IFERROR( CL16/$V16,0)) -> 0 | CT16: =INT(IFERROR( AE16-CQ16-CU16-CR16,0)) -> 0 | CU16: =INT(IFERROR( AC16-CR16,0)) -> 0 | CV16: =INT(IFERROR( AD16-CS16,0)) -> 0 | CX16: 83.56 | CY16: =INT(60/CX16*60*(12-(CEILING((60/CX16*60*12)/E16,1)*IF(CW16="T",0.45,IF(CW16="",5,3))/60))) -> 488 | CZ16: =IF(CX16="",0,(IF(CW16="",360,180)/(60/CX16))*1.35) -> 676.836 | DE16: =IFERROR(CQ16+CR16,"") -> 0 | DF16: =IFERROR(AL16,"") -> 0 | DG16: =IFERROR(AZ16,"") -> 0 | DH16: =IFERROR(CT16+CU16,"") -> 0 | DI16: =IFERROR(BF16,"") -> 0 | DJ16: =IFERROR(BT16,"") -> 0 | DK16: =IFERROR(DE16+DH16,"") -> 0 | DL16: =IFERROR(DF16+DI16,"") -> 0 | DM16: =IFERROR(DG16+DJ16,"") -> 0 | DN16: =T16 -> 0 | DO16: =U16 -> 0 | DW16: =IFERROR(AL16+BF16,"") -> 0 | DX16: =IFERROR(DK16+DL16+DM16,"") -> 0 | DY16: =CQ16+CR16+CS16+CT16+CU16+CV16 -> 0 | DZ16: =IFERROR((AD16*V16/1000),0) -> 0 | EA16: =IFERROR((AE16*V16/1000),0) -> 0 | EB16: =BX16-EA16 -> 0 | EC16: =EB16+DZ16 -> 0 | EF16: =DG16+DJ16 -> 0
A17: 10 | B17: C10 | D17: 31100 | E17: 91 | F17: D | G17: =CONCATENATE(K17,J17,"-",IF(N17="D",L17,IF(N17="H",CONCATENATE(N17,L17),CONCATENATE(N17,L17,"x",M17))),"x",P17,"-",O17,R17) -> GWA6063-T5-T18.15x8.6x3-H9A15 | H17: =CONCATENATE(J17,,K17,L17,M17,N17,O17) -> A6063-T5GW18.158.6TH9 | I17: =CONCATENATE(J17,K17,L17,M17,N17,O17,P17,R17) -> A6063-T5GW18.158.6TH93A15 | J17: A6063-T5 | K17: GW | L17: 18.15 | M17: 8.6 | N17: T | O17: H9 | P17: 3 | Q17: 1.641 | R17: A15 | S17: =ROUND(CY17/E17,0)*2 -> 14 | T17: 8 | U17: 10 | V17: 7.7 | W17: =IF(V17="","",INT((AO17+BI17)/$V17)) -> 0 | X17: =IF(V17="","",INT((AP17+BJ17)/$V17)) -> 1101 | Y17: =IF(V17="","",INT((AQ17+BK17)/$V17)) -> 0 | Z17: =IF(V17="","",INT((AR17+BL17)/$V17)) -> 0 | AA17: =IF(V17="","",INT((AS17+BM17)/$V17)) -> 0 | AB17: =IF(V17="","",INT((AT17+BN17)/$V17)) -> 0 | AC17: =IF(V17="","",INT((AU17+BO17)/$V17)) -> 0 | AD17: =IF(V17="","",INT((AV17+BP17)/$V17)) -> 0 | AE17: =IF(V17="","",SUM(W17:AC17)) -> 1101 | AF17: =AE17 -> 1101 | AG17: =T17 -> 8 | AH17: =IFERROR(VALUE("0"&RIGHT(AG17,(LEN(AG17)-LEN(TRUNC(AG17))))),"") -> 0 | AI17: 6 | AJ17: =$CI17 -> 0 | AK17: =IF(V17="","",IF(AJ17=0,1,AJ17/$V17/$E17)) -> 1 | AL17: =IF(V17="","",MAX(ROUNDUP((IF(AI17+AJ17=0,0,AH17)+AI17+AK17-1),2),0)) -> 6 | AM17: =IF(V17="","",AG17+U17-AL17) -> 12 | AP17: =$CJ17 -> 4404.4 | AU17: =CK17 -> 0 | AV17: =CL17 -> 0 | AW17: =SUM(AO17:AV17) -> 4404.4 | AX17: =IF(V17="","",INT(AW17/$V17)) -> 572 | AY17: =IF(V17="","",AW17-AL17*$E17*$V17) -> 200.2 | AZ17: =IF($V17="","",AY17/$V17) -> 26 | BA17: =AM17 -> 12 | BB17: =VALUE("0"&RIGHT(BA17,(LEN(BA17)-LEN(TRUNC(BA17))))) -> 0 | BC17: 6 | BD17: =$CM17 -> 0 | BE17: =IF(AA17="","",IF(BD17=0,1,BD17/$V17/$E17)) -> 1 | BF17: =IF(V17="","",MAX(ROUNDUP((IF(BC17+BD17=0,0,BB17)+BC17+BE17-1),2),0)) -> 6 | BG17: =IF(AA17="","",BA17-BF17) -> 6 | BJ17: =$CN17 -> 4078.8 | BO17: =CO17 -> 0 | BP17: =CP17 -> 0 | BQ17: =SUM(BI17:BP17) -> 4078.8 | BR17: =IF(AA17="","",INT(BQ17/$V17)) -> 529 | BS17: =IF(AA17="","",-BF17*$E17*$V17+BQ17) -> -125.4 | BT17: =IF($V17="","",BS17/$V17) -> -16.285714 | BU17: =IFERROR(AE17,"") -> 1101 | BV17: =IFERROR(BF17+AL17,"") -> 12 | BW17: =IFERROR(BT17+AZ17,"") -> 9.7142857 | BX17: =IF($Q17="","",(BF17+AL17)*$Q17) -> 19.692 | BY17: =IFERROR(BF17+AL17,0) -> 12 | BZ17: =BY17 -> 12 | CA17: =IFERROR((BQ17+AW17)/1000,"") -> 8.4832 | CB17: =IFERROR(BR17+AX17,"") -> 1101 | CC17: =IFERROR(BS17+AY17,"") -> 74.8 | CD17: =IFERROR(BT17+AZ17,"") -> 9.7142857 | CG17: =IF(BX17="",0,(BX17-CA17)+((AV17+BP17)/1000)) -> 11.2088 | CH17: =CG17 -> 11.2088 | CJ17: =572*7.7 -> 4404.4 | CN17: =412*9.9 -> 4078.8 | CQ17: =INT(IFERROR( CJ17/$V17,0)) -> 572 | CR17: =INT(IFERROR( CK17/$V17,0)) -> 0 | CS17: =INT(IFERROR( CL17/$V17,0)) -> 0 | CT17: =INT(IFERROR( AE17-CQ17-CU17-CR17,0)) -> 529 | CU17: =INT(IFERROR( AC17-CR17,0)) -> 0 | CV17: =INT(IFERROR( AD17-CS17,0)) -> 0 | CX17: 60 | CY17: =INT(60/CX17*60*(12-(CEILING((60/CX17*60*12)/E17,1)*IF(CW17="T",0.45,IF(CW17="",5,3))/60))) -> 680 | CZ17: =IF(CX17="",0,(IF(CW17="",360,180)/(60/CX17))*1.35) -> 486 | DE17: =IFERROR(CQ17+CR17,"") -> 572 | DF17: =IFERROR(AL17,"") -> 6 | DG17: =IFERROR(AZ17,"") -> 26 | DH17: =IFERROR(CT17+CU17,"") -> 529 | DI17: =IFERROR(BF17,"") -> 6 | DJ17: =IFERROR(BT17,"") -> -16.285714 | DK17: =IFERROR(DE17+DH17,"") -> 1101 | DL17: =IFERROR(DF17+DI17,"") -> 12 | DM17: =IFERROR(DG17+DJ17,"") -> 9.7142857 | DN17: =T17 -> 8 | DO17: =U17 -> 10 | DR17: A15C100515 | DW17: =IFERROR(AL17+BF17,"") -> 12 | DX17: =IFERROR(DK17+DL17+DM17,"") -> 1122.7143 | DY17: =CQ17+CR17+CS17+CT17+CU17+CV17 -> 1101 | DZ17: =IFERROR((AD17*V17/1000),0) -> 0 | EA17: =IFERROR((AE17*V17/1000),0) -> 8.4777 | EB17: =BX17-EA17 -> 11.2143 | EC17: =EB17+DZ17 -> 11.2143 | EF17: =DG17+DJ17 -> 9.7142857
A18: 11 | B18: C11 | D18: 131100 | E18: 68 | F18: D | G18: =CONCATENATE(K18,J18,"-",IF(N18="D",L18,IF(N18="H",CONCATENATE(N18,L18),CONCATENATE(N18,L18,"x",M18))),"x",P18,"-",O18,R18) -> GWA6063-T5-T18.15x8.6x3-H9A15 | H18: =CONCATENATE(J18,,K18,L18,M18,N18,O18) -> A6063-T5GW18.158.6TH9 | I18: =CONCATENATE(J18,K18,L18,M18,N18,O18,P18,R18) -> A6063-T5GW18.158.6TH93A15 | J18: A6063-T5 | K18: GW | L18: 18.15 | M18: 8.6 | N18: T | O18: H9 | P18: 3 | Q18: 1.641 | R18: A15 | S18: =ROUND(CY18/E18,0)*2 -> 16 | T18: 6 | U18: 10 | V18: 9.9 | W18: =IF(V18="","",INT((AO18+BI18)/$V18)) -> 0 | X18: =IF(V18="","",INT((AP18+BJ18)/$V18)) -> 440 | Y18: =IF(V18="","",INT((AQ18+BK18)/$V18)) -> 0 | Z18: =IF(V18="","",INT((AR18+BL18)/$V18)) -> 0 | AA18: =IF(V18="","",INT((AS18+BM18)/$V18)) -> 0 | AB18: =IF(V18="","",INT((AT18+BN18)/$V18)) -> 0 | AC18: =IF(V18="","",INT((AU18+BO18)/$V18)) -> 0 | AD18: =IF(V18="","",INT((AV18+BP18)/$V18)) -> 0 | AE18: =IF(V18="","",SUM(W18:AC18)) -> 440 | AF18: =AE18 -> 440 | AG18: =T18 -> 6 | AH18: =IFERROR(VALUE("0"&RIGHT(AG18,(LEN(AG18)-LEN(TRUNC(AG18))))),"") -> 0 | AI18: 7 | AJ18: =$CI18 -> 0 | AK18: =IF(V18="","",IF(AJ18=0,1,AJ18/$V18/$E18)) -> 1 | AL18: =IF(V18="","",MAX(ROUNDUP((IF(AI18+AJ18=0,0,AH18)+AI18+AK18-1),2),0)) -> 7 | AM18: =IF(V18="","",AG18+U18-AL18) -> 9 | AP18: =$CJ18 -> 4356 | AU18: =CK18 -> 0 | AV18: =CL18 -> 0 | AW18: =SUM(AO18:AV18) -> 4356 | AX18: =IF(V18="","",INT(AW18/$V18)) -> 440 | AY18: =IF(V18="","",AW18-AL18*$E18*$V18) -> -356.4 | AZ18: =IF($V18="","",AY18/$V18) -> -36 | BA18: =AM18 -> 9 | BB18: =VALUE("0"&RIGHT(BA18,(LEN(BA18)-LEN(TRUNC(BA18))))) -> 0 | BD18: =$CM18 -> 0 | BE18: =IF(AA18="","",IF(BD18=0,1,BD18/$V18/$E18)) -> 1 | BF18: =IF(V18="","",MAX(ROUNDUP((IF(BC18+BD18=0,0,BB18)+BC18+BE18-1),2),0)) -> 0 | BG18: =IF(AA18="","",BA18-BF18) -> 9 | BJ18: =$CN18 -> 0 | BO18: =CO18 -> 0 | BP18: =CP18 -> 0 | BQ18: =SUM(BI18:BP18) -> 0 | BR18: =IF(AA18="","",INT(BQ18/$V18)) -> 0 | BS18: =IF(AA18="","",-BF18*$E18*$V18+BQ18) -> 0 | BT18: =IF($V18="","",BS18/$V18) -> 0 | BU18: =IFERROR(AE18,"") -> 440 | BV18: =IFERROR(BF18+AL18,"") -> 7 | BW18: =IFERROR(BT18+AZ18,"") -> -36 | BX18: =IF($Q18="","",(BF18+AL18)*$Q18) -> 11.487 | BY18: =IFERROR(BF18+AL18,0) -> 7 | BZ18: =BY18 -> 7 | CA18: =IFERROR((BQ18+AW18)/1000,"") -> 4.356 | CB18: =IFERROR(BR18+AX18,"") -> 440 | CC18: =IFERROR(BS18+AY18,"") -> -356.4 | CD18: =IFERROR(BT18+AZ18,"") -> -36 | CG18: =IF(BX18="",0,(BX18-CA18)+((AV18+BP18)/1000)) -> 7.131 | CH18: =CG18 -> 7.131 | CJ18: =440*9.9 -> 4356 | CQ18: =INT(IFERROR( CJ18/$V18,0)) -> 440 | CR18: =INT(IFERROR( CK18/$V18,0)) -> 0 | CS18: =INT(IFERROR( CL18/$V18,0)) -> 0 | CT18: =INT(IFERROR( AE18-CQ18-CU18-CR18,0)) -> 0 | CU18: =INT(IFERROR( AC18-CR18,0)) -> 0 | CV18: =INT(IFERROR( AD18-CS18,0)) -> 0 | CX18: 79.33 | CY18: =INT(60/CX18*60*(12-(CEILING((60/CX18*60*12)/E18,1)*IF(CW18="T",0.45,IF(CW18="",5,3))/60))) -> 510 | CZ18: =IF(CX18="",0,(IF(CW18="",360,180)/(60/CX18))*1.35) -> 642.573 | DE18: =IFERROR(CQ18+CR18,"") -> 440 | DF18: =IFERROR(AL18,"") -> 7 | DG18: =IFERROR(AZ18,"") -> -36 | DH18: =IFERROR(CT18+CU18,"") -> 0 | DI18: =IFERROR(BF18,"") -> 0 | DJ18: =IFERROR(BT18,"") -> 0 | DK18: =IFERROR(DE18+DH18,"") -> 440 | DL18: =IFERROR(DF18+DI18,"") -> 7 | DM18: =IFERROR(DG18+DJ18,"") -> -36 | DN18: =T18 -> 6 | DO18: =U18 -> 10 | DR18: A15C110515 | DW18: =IFERROR(AL18+BF18,"") -> 7 | DX18: =IFERROR(DK18+DL18+DM18,"") -> 411 | DY18: =CQ18+CR18+CS18+CT18+CU18+CV18 -> 440 | DZ18: =IFERROR((AD18*V18/1000),0) -> 0 | EA18: =IFERROR((AE18*V18/1000),0) -> 4.356 | EB18: =BX18-EA18 -> 7.131 | EC18: =EB18+DZ18 -> 7.131 | EF18: =DG18+DJ18 -> -36
A19: 12 | B19: C12 | D19: S90001 | E19: 104 | F19: B | G19: =CONCATENATE(K19,J19,"-",IF(N19="D",L19,IF(N19="H",CONCATENATE(N19,L19),CONCATENATE(N19,L19,"x",M19))),"x",P19,"-",O19,R19) -> TV12L14-12x3-H9B14 | H19: =CONCATENATE(J19,,K19,L19,M19,N19,O19) -> 12L14TV120DH9 | I19: =CONCATENATE(J19,K19,L19,M19,N19,O19,P19,R19) -> 12L14TV120DH93B14 | J19: 12L14 | K19: TV | L19: 12 | M19: 0 | N19: D | O19: H9 | P19: 3 | Q19: 2.652 | R19: B14 | S19: =ROUND(CY19/E19,0)*2 -> 20 | T19: 0 | V19: 10.6 | W19: =IF(V19="","",INT((AO19+BI19)/$V19)) -> 0 | X19: =IF(V19="","",INT((AP19+BJ19)/$V19)) -> 0 | Y19: =IF(V19="","",INT((AQ19+BK19)/$V19)) -> 0 | Z19: =IF(V19="","",INT((AR19+BL19)/$V19)) -> 0 | AA19: =IF(V19="","",INT((AS19+BM19)/$V19)) -> 0 | AB19: =IF(V19="","",INT((AT19+BN19)/$V19)) -> 0 | AC19: =IF(V19="","",INT((AU19+BO19)/$V19)) -> 0 | AD19: =IF(V19="","",INT((AV19+BP19)/$V19)) -> 0 | AE19: =IF(V19="","",SUM(W19:AC19)) -> 0 | AF19: =AE19 -> 0 | AG19: =T19 -> 0 | AH19: =IFERROR(VALUE("0"&RIGHT(AG19,(LEN(AG19)-LEN(TRUNC(AG19))))),"") -> 0 | AJ19: =$CI19 -> 0 | AK19: =IF(V19="","",IF(AJ19=0,1,AJ19/$V19/$E19)) -> 1 | AL19: =IF(V19="","",MAX(ROUNDUP((IF(AI19+AJ19=0,0,AH19)+AI19+AK19-1),2),0)) -> 0 | AM19: =IF(V19="","",AG19+U19-AL19) -> 0 | AP19: =$CJ19 -> 0 | AU19: =CK19 -> 0 | AV19: =CL19 -> 0 | AW19: =SUM(AO19:AV19) -> 0 | AX19: =IF(V19="","",INT(AW19/$V19)) -> 0 | AY19: =IF(V19="","",AW19-AL19*$E19*$V19) -> 0 | AZ19: =IF($V19="","",AY19/$V19) -> 0 | BA19: =AM19 -> 0 | BB19: =VALUE("0"&RIGHT(BA19,(LEN(BA19)-LEN(TRUNC(BA19))))) -> 0 | BD19: =$CM19 -> 0 | BE19: =IF(AA19="","",IF(BD19=0,1,BD19/$V19/$E19)) -> 1 | BF19: =IF(V19="","",MAX(ROUNDUP((IF(BC19+BD19=0,0,BB19)+BC19+BE19-1),2),0)) -> 0 | BG19: =IF(AA19="","",BA19-BF19) -> 0 | BJ19: =$CN19 -> 0 | BO19: =CO19 -> 0 | BP19: =CP19 -> 0 | BQ19: =SUM(BI19:BP19) -> 0 | BR19: =IF(AA19="","",INT(BQ19/$V19)) -> 0 | BS19: =IF(AA19="","",-BF19*$E19*$V19+BQ19) -> 0 | BT19: =IF($V19="","",BS19/$V19) -> 0 | BU19: =IFERROR(AE19,"") -> 0 | BV19: =IFERROR(BF19+AL19,"") -> 0 | BW19: =IFERROR(BT19+AZ19,"") -> 0 | BX19: =IF($Q19="","",(BF19+AL19)*$Q19) -> 0 | BY19: =IFERROR(BF19+AL19,0) -> 0 | BZ19: =BY19 -> 0 | CA19: =IFERROR((BQ19+AW19)/1000,"") -> 0 | CB19: =IFERROR(BR19+AX19,"") -> 0 | CC19: =IFERROR(BS19+AY19,"") -> 0 | CD19: =IFERROR(BT19+AZ19,"") -> 0 | CG19: =IF(BX19="",0,(BX19-CA19)+((AV19+BP19)/1000)) -> 0 | CH19: =CG19 -> 0 | CQ19: =INT(IFERROR( CJ19/$V19,0)) -> 0 | CR19: =INT(IFERROR( CK19/$V19,0)) -> 0 | CS19: =INT(IFERROR( CL19/$V19,0)) -> 0 | CT19: =INT(IFERROR( AE19-CQ19-CU19-CR19,0)) -> 0 | CU19: =INT(IFERROR( AC19-CR19,0)) -> 0 | CV19: =INT(IFERROR( AD19-CS19,0)) -> 0 | CX19: 37.89 | CY19: =INT(60/CX19*60*(12-(CEILING((60/CX19*60*12)/E19,1)*IF(CW19="T",0.45,IF(CW19="",5,3))/60))) -> 1053 | CZ19: =IF(CX19="",0,(IF(CW19="",360,180)/(60/CX19))*1.35) -> 306.909 | DE19: =IFERROR(CQ19+CR19,"") -> 0 | DF19: =IFERROR(AL19,"") -> 0 | DG19: =IFERROR(AZ19,"") -> 0 | DH19: =IFERROR(CT19+CU19,"") -> 0 | DI19: =IFERROR(BF19,"") -> 0 | DJ19: =IFERROR(BT19,"") -> 0 | DK19: =IFERROR(DE19+DH19,"") -> 0 | DL19: =IFERROR(DF19+DI19,"") -> 0 | DM19: =IFERROR(DG19+DJ19,"") -> 0 | DN19: =T19 -> 0 | DO19: =U19 -> 0 | DW19: =IFERROR(AL19+BF19,"") -> 0 | DX19: =IFERROR(DK19+DL19+DM19,"") -> 0 | DY19: =CQ19+CR19+CS19+CT19+CU19+CV19 -> 0 | DZ19: =IFERROR((AD19*V19/1000),0) -> 0 | EA19: =IFERROR((AE19*V19/1000),0) -> 0 | EB19: =BX19-EA19 -> 0 | EC19: =EB19+DZ19 -> 0
A20: 13 | B20: C12B | D20: Y1 8800 | E20: 298 | F20: D | G20: =CONCATENATE(K20,J20,"-",IF(N20="D",L20,IF(N20="H",CONCATENATE(N20,L20),CONCATENATE(N20,L20,"x",M20))),"x",P20,"-",O20,R20) -> GWA6063-T5-8.3x3-H9B14 | H20: =CONCATENATE(J20,,K20,L20,M20,N20,O20) -> A6063-T5GW8.30DH9 | I20: =CONCATENATE(J20,K20,L20,M20,N20,O20,P20,R20) -> A6063-T5GW8.30DH93B14 | J20: A6063-T5 | K20: GW | L20: 8.3 | M20: 0 | N20: D | O20: H9 | P20: 3 | Q20: 0.435 | R20: B14 | S20: =ROUND(CY20/E20,0)*2 -> 18 | T20: 41 | U20: 3 | V20: 1.05 | W20: =IF(V20="","",INT((AO20+BI20)/$V20)) -> 0 | X20: =IF(V20="","",INT((AP20+BJ20)/$V20)) -> 0 | Y20: =IF(V20="","",INT((AQ20+BK20)/$V20)) -> 0 | Z20: =IF(V20="","",INT((AR20+BL20)/$V20)) -> 0 | AA20: =IF(V20="","",INT((AS20+BM20)/$V20)) -> 0 | AB20: =IF(V20="","",INT((AT20+BN20)/$V20)) -> 848 | AC20: =IF(V20="","",INT((AU20+BO20)/$V20)) -> 0 | AD20: =IF(V20="","",INT((AV20+BP20)/$V20)) -> 0 | AE20: =IF(V20="","",SUM(W20:AC20)) -> 848 | AF20: =AE20 -> 848 | AG20: =T20 -> 41 | AH20: =IFERROR(VALUE("0"&RIGHT(AG20,(LEN(AG20)-LEN(TRUNC(AG20))))),"") -> 0 | AI20: 3 | AJ20: =$CI20 -> 0 | AK20: =IF(V20="","",IF(AJ20=0,1,AJ20/$V20/$E20)) -> 1 | AL20: =IF(V20="","",MAX(ROUNDUP((IF(AI20+AJ20=0,0,AH20)+AI20+AK20-1),2),0)) -> 3 | AM20: =IF(V20="","",AG20+U20-AL20) -> 41 | AT20: =$CJ20 -> 891 | AU20: =CK20 -> 0 | AV20: =CL20 -> 0 | AW20: =SUM(AO20:AV20) -> 891 | AX20: =IF(V20="","",INT(AW20/$V20)) -> 848 | AY20: =IF(V20="","",AW20-AL20*$E20*$V20) -> -47.7 | AZ20: =IF($V20="","",AY20/$V20) -> -45.428571 | BA20: =AM20 -> 41 | BB20: =VALUE("0"&RIGHT(BA20,(LEN(BA20)-LEN(TRUNC(BA20))))) -> 0 | BD20: =$CM20 -> 0 | BE20: =IF(AA20="","",IF(BD20=0,1,BD20/$V20/$E20)) -> 1 | BF20: =IF(V20="","",MAX(ROUNDUP((IF(BC20+BD20=0,0,BB20)+BC20+BE20-1),2),0)) -> 0 | BG20: =IF(AA20="","",BA20-BF20) -> 41 | BN20: =$CN20 -> 0 | BO20: =CO20 -> 0 | BP20: =CP20 -> 0 | BQ20: =SUM(BI20:BP20) -> 0 | BR20: =IF(AA20="","",INT(BQ20/$V20)) -> 0 | BS20: =IF(AA20="","",-BF20*$E20*$V20+BQ20) -> 0 | BT20: =IF($V20="","",BS20/$V20) -> 0 | BU20: =IFERROR(AE20,"") -> 848 | BV20: =IFERROR(BF20+AL20,"") -> 3 | BW20: =IFERROR(BT20+AZ20,"") -> -45.428571 | BX20: =IF($Q20="","",(BF20+AL20)*$Q20) -> 1.305 | BY20: =IFERROR(BF20+AL20,0) -> 3 | BZ20: =BY20 -> 3 | CA20: =IFERROR((BQ20+AW20)/1000,"") -> 0.891 | CB20: =IFERROR(BR20+AX20,"") -> 848 | CC20: =IFERROR(BS20+AY20,"") -> -47.7 | CD20: =IFERROR(BT20+AZ20,"") -> -45.428571 | CG20: =IF(BX20="",0,(BX20-CA20)+((AV20+BP20)/1000)) -> 0.414 | CH20: =CG20 -> 0.414 | CJ20: 891 | CQ20: =INT(IFERROR( CJ20/$V20,0)) -> 848 | CR20: =INT(IFERROR( CK20/$V20,0)) -> 0 | CS20: =INT(IFERROR( CL20/$V20,0)) -> 0 | CT20: =INT(IFERROR( AE20-CQ20-CU20-CR20,0)) -> 0 | CU20: =INT(IFERROR( AC20-CR20,0)) -> 0 | CV20: =INT(IFERROR( AD20-CS20,0)) -> 0 | CX20: 15 | CY20: =INT(60/CX20*60*(12-(CEILING((60/CX20*60*12)/E20,1)*IF(CW20="T",0.45,IF(CW20="",5,3))/60))) -> 2680 | CZ20: =IF(CX20="",0,(IF(CW20="",360,180)/(60/CX20))*1.35) -> 121.5 | DE20: =IFERROR(CQ20+CR20,"") -> 848 | DF20: =IFERROR(AL20,"") -> 3 | DG20: =IFERROR(AZ20,"") -> -45.428571 | DH20: =IFERROR(CT20+CU20,"") -> 0 | DI20: =IFERROR(BF20,"") -> 0 | DJ20: =IFERROR(BT20,"") -> 0 | DK20: =IFERROR(DE20+DH20,"") -> 848 | DL20: =IFERROR(DF20+DI20,"") -> 3 | DM20: =IFERROR(DG20+DJ20,"") -> -45.428571 | DN20: =T20 -> 41 | DO20: =U20 -> 3 | DR20: B14C12B0515 | DW20: =IFERROR(BU20+BV20,"") -> 851 | DX20: =IFERROR(DK20+DL20+DM20,"") -> 805.57143 | DY20: =CQ20+CR20+CS20+CT20+CU20+CV20 -> 848 | DZ20: =IFERROR((AD20*V20/1000),0) -> 0 | EA20: =IFERROR((AE20*V20/1000),0) -> 0.8904 | EB20: =BX20-EA20 -> 0.4146 | EC20: =EB20+DZ20 -> 0.4146 | EF20: =DG20+DJ20 -> -45.428571
A21: 14 | B21: C14 | D21: 020 | E21: 283 | G21: =CONCATENATE(K21,J21,"-",IF(N21="D",L21,IF(N21="H",CONCATENATE(N21,L21),CONCATENATE(N21,L21,"x",M21))),"x",P21,"-",O21,R21) -> TV12L14-11x2.5-H9C14 | H21: =CONCATENATE(J21,,K21,L21,M21,N21,O21) -> 12L14TV110DH9 | I21: =CONCATENATE(J21,K21,L21,M21,N21,O21,P21,R21) -> 12L14TV110DH92.5C14 | J21: 12L14 | K21: TV | L21: 11 | M21: 0 | N21: D | O21: H9 | P21: 2.5 | R21: C14 | S21: =ROUND(CY21/E21,0)*2 -> 10 | T21: 2 | U21: 13 | V21: 2 | W21: =IF(V21="","",INT((AO21+BI21)/$V21)) -> 0 | X21: =IF(V21="","",INT((AP21+BJ21)/$V21)) -> 3247 | Y21: =IF(V21="","",INT((AQ21+BK21)/$V21)) -> 0 | Z21: =IF(V21="","",INT((AR21+BL21)/$V21)) -> 0 | AA21: =IF(V21="","",INT((AS21+BM21)/$V21)) -> 0 | AB21: =IF(V21="","",INT((AT21+BN21)/$V21)) -> 0 | AC21: =IF(V21="","",INT((AU21+BO21)/$V21)) -> 0 | AD21: =IF(V21="","",INT((AV21+BP21)/$V21)) -> 0 | AE21: =IF(V21="","",SUM(W21:AC21)) -> 3247 | AF21: =AE21 -> 3247 | AG21: =T21 -> 2 | AH21: =IFERROR(VALUE("0"&RIGHT(AG21,(LEN(AG21)-LEN(TRUNC(AG21))))),"") -> 0 | AI21: 6 | AJ21: =$CI21 -> 0 | AK21: =IF(V21="","",IF(AJ21=0,1,AJ21/$V21/$E21)) -> 1 | AL21: =IF(V21="","",MAX(ROUNDUP((IF(AI21+AJ21=0,0,AH21)+AI21+AK21-1),2),0)) -> 6 | AM21: =IF(V21="","",AG21+U21-AL21) -> 9 | AP21: =$CJ21 -> 3533 | AU21: =CK21 -> 0 | AV21: =CL21 -> 0 | AW21: =SUM(AO21:AV21) -> 3533 | AX21: =IF(V21="","",INT(AW21/$V21)) -> 1766 | AY21: =IF(V21="","",AW21-AL21*$E21*$V21) -> 137 | AZ21: =IF($V21="","",AY21/$V21) -> 68.5 | BA21: =AM21 -> 9 | BB21: =VALUE("0"&RIGHT(BA21,(LEN(BA21)-LEN(TRUNC(BA21))))) -> 0 | BC21: 6 | BD21: =$CM21 -> 120 | BE21: =IF(AA21="","",IF(BD21=0,1,BD21/$V21/$E21)) -> 0.21201413 | BF21: =IF(V21="","",MAX(ROUNDUP((IF(BC21+BD21=0,0,BB21)+BC21+BE21-1),2),0)) -> 5.22 | BG21: =IF(AA21="","",BA21-BF21) -> 3.78 | BJ21: =$CN21 -> 2961 | BO21: =CO21 -> 0 | BP21: =CP21 -> 0 | BQ21: =SUM(BI21:BP21) -> 2961 | BR21: =IF(AA21="","",INT(BQ21/$V21)) -> 1480 | BS21: =IF(AA21="","",-BF21*$E21*$V21+BQ21) -> 6.48 | BT21: =IF($V21="","",BS21/$V21) -> 3.24 | BU21: =IFERROR(AE21,"") -> 3247 | BV21: =IFERROR(BF21+AL21,"") -> 11.22 | BW21: =IFERROR(BT21+AZ21,"") -> 71.74 | BX21: =IF($Q21="","",(BF21+AL21)*$Q21) | BY21: =IFERROR(BF21+AL21,0) -> 11.22 | BZ21: =BY21 -> 11.22 | CA21: =IFERROR((BQ21+AW21)/1000,"") -> 6.494 | CB21: =IFERROR(BR21+AX21,"") -> 3246 | CC21: =IFERROR(BS21+AY21,"") -> 143.48 | CD21: =IFERROR(BT21+AZ21,"") -> 71.74 | CG21: =IF(BX21="",0,(BX21-CA21)+((AV21+BP21)/1000)) -> 0 | CH21: =CG21 -> 0 | CJ21: 3533 | CM21: 120 | CN21: 2961 | CQ21: =INT(IFERROR( CJ21/$V21,0)) -> 1766 | CR21: =INT(IFERROR( CK21/$V21,0)) -> 0 | CS21: =INT(IFERROR( CL21/$V21,0)) -> 0 | CT21: =INT(IFERROR( AE21-CQ21-CU21-CR21,0)) -> 1481 | CU21: =INT(IFERROR( AC21-CR21,0)) -> 0 | CV21: =INT(IFERROR( AD21-CS21,0)) -> 0 | CX21: 30 | CY21: =INT(60/CX21*60*(12-(CEILING((60/CX21*60*12)/E21,1)*IF(CW21="T",0.45,IF(CW21="",5,3))/60))) -> 1380 | CZ21: =IF(CX21="",0,(IF(CW21="",360,180)/(60/CX21))*1.35) -> 243 | DE21: =IFERROR(CQ21+CR21,"") -> 1766 | DF21: =IFERROR(AL21,"") -> 6 | DG21: =IFERROR(AZ21,"") -> 68.5 | DH21: =IFERROR(CT21+CU21,"") -> 1481 | DI21: =IFERROR(BF21,"") -> 5.22 | DJ21: =IFERROR(BT21,"") -> 3.24 | DK21: =IFERROR(DE21+DH21,"") -> 3247 | DL21: =IFERROR(DF21+DI21,"") -> 11.22 | DM21: =IFERROR(DG21+DJ21,"") -> 71.74 | DN21: 2 | DO21: =U21 -> 13 | DR21: C14C140515 | DW21: =IFERROR(BU21+BV21,"") -> 3258.22 | DX21: =IFERROR(DK21+DL21+DM21,"") -> 3329.96 | DY21: =CQ21+CR21+CS21+CT21+CU21+CV21 -> 3247 | DZ21: =IFERROR((AD21*V21/1000),0) -> 0 | EA21: =IFERROR((AE21*V21/1000),0) -> 6.494 | EB21: =BX21-EA21 -> #VALUE! | EC21: =EB21+DZ21 -> #VALUE! | EF21: =DG21+DJ21 -> 71.74
A22: 15 | B22: C15 | D22: SC5 | E22: 40 | G22: =CONCATENATE(K22,J22,"-",IF(N22="D",L22,IF(N22="H",CONCATENATE(N22,L22),CONCATENATE(N22,L22,"x",M22))),"x",P22,"-",O22,R22) -> TV12L14-5.97x2.5-H9B14 | H22: =CONCATENATE(J22,,K22,L22,M22,N22,O22) -> 12L14TV5.970DH9 | I22: =CONCATENATE(J22,K22,L22,M22,N22,O22,P22,R22) -> 12L14TV5.970DH92.5B14 | J22: 12L14 | K22: TV | L22: 5.97 | M22: 0 | N22: D | O22: H9 | P22: 2.5 | Q22: 0.547 | R22: B14 | S22: =ROUND(CY22/E22,0)*2 -> 48 | T22: 39 | U22: 61 | V22: 4.45 | W22: =IF(V22="","",INT((AO22+BI22)/$V22)) -> 0 | X22: =IF(V22="","",INT((AP22+BJ22)/$V22)) -> 1325 | Y22: =IF(V22="","",INT((AQ22+BK22)/$V22)) -> 0 | Z22: =IF(V22="","",INT((AR22+BL22)/$V22)) -> 0 | AA22: =IF(V22="","",INT((AS22+BM22)/$V22)) -> 0 | AB22: =IF(V22="","",INT((AT22+BN22)/$V22)) -> 0 | AC22: =IF(V22="","",INT((AU22+BO22)/$V22)) -> 0 | AD22: =IF(V22="","",INT((AV22+BP22)/$V22)) -> 2 | AE22: =IF(V22="","",SUM(W22:AC22)) -> 1325 | AF22: =AE22 -> 1325 | AG22: =T22 -> 39 | AH22: =IFERROR(VALUE("0"&RIGHT(AG22,(LEN(AG22)-LEN(TRUNC(AG22))))),"") -> 0 | AI22: 33 | AJ22: =$CI22 -> 0 | AK22: =IF(V22="","",IF(AJ22=0,1,AJ22/$V22/$E22)) -> 1 | AL22: =IF(V22="","",MAX(ROUNDUP((IF(AI22+AJ22=0,0,AH22)+AI22+AK22-1),2),0)) -> 33 | AM22: =IF(V22="","",AG22+U22-AL22) -> 67 | AP22: =$CJ22 -> 5900 | AU22: =CK22 -> 0 | AV22: =CL22 -> 10 | AW22: =SUM(AO22:AV22) -> 5910 | AX22: =IF(V22="","",INT(AW22/$V22)) -> 1328 | AY22: =IF(V22="","",AW22-AL22*$E22*$V22) -> 36 | AZ22: =IF($V22="","",AY22/$V22) -> 8.0898876 | BA22: =AM22 -> 67 | BB22: =VALUE("0"&RIGHT(BA22,(LEN(BA22)-LEN(TRUNC(BA22))))) -> 0 | BD22: =$CM22 -> 0 | BE22: =IF(AA22="","",IF(BD22=0,1,BD22/$V22/$E22)) -> 1 | BF22: =IF(V22="","",MAX(ROUNDUP((IF(BC22+BD22=0,0,BB22)+BC22+BE22-1),2),0)) -> 0 | BG22: =IF(AA22="","",BA22-BF22) -> 67 | BJ22: =$CN22 -> 0 | BO22: =CO22 -> 0 | BP22: =CP22 -> 0 | BQ22: =SUM(BI22:BP22) -> 0 | BR22: =IF(AA22="","",INT(BQ22/$V22)) -> 0 | BS22: =IF(AA22="","",-BF22*$E22*$V22+BQ22) -> 0 | BT22: =IF($V22="","",BS22/$V22) -> 0 | BU22: =IFERROR(AE22,"") -> 1325 | BV22: =IFERROR(BF22+AL22,"") -> 33 | BW22: =IFERROR(BT22+AZ22,"") -> 8.0898876 | BX22: =IF($Q22="","",(BF22+AL22)*$Q22) -> 18.051 | BY22: =IFERROR(BF22+AL22,0) -> 33 | BZ22: =BY22 -> 33 | CA22: =IFERROR((BQ22+AW22)/1000,"") -> 5.91 | CB22: =IFERROR(BR22+AX22,"") -> 1328 | CC22: =IFERROR(BS22+AY22,"") -> 36 | CD22: =IFERROR(BT22+AZ22,"") -> 8.0898876 | CG22: =IF(BX22="",0,(BX22-CA22)+((AV22+BP22)/1000)) -> 12.151 | CH22: =CG22 -> 12.151 | CJ22: 5900 | CL22: 10 | CQ22: =INT(IFERROR( CJ22/$V22,0)) -> 1325 | CR22: =INT(IFERROR( CK22/$V22,0)) -> 0 | CS22: =INT(IFERROR( CL22/$V22,0)) -> 2 | CT22: =INT(IFERROR( AE22-CQ22-CU22-CR22,0)) -> 0 | CU22: =INT(IFERROR( AC22-CR22,0)) -> 0 | CV22: =INT(IFERROR( AD22-CS22,0)) -> 0 | CX22: 36.09 | CY22: =INT(60/CX22*60*(12-(CEILING((60/CX22*60*12)/E22,1)*IF(CW22="T",0.45,IF(CW22="",5,3))/60))) -> 947 | CZ22: =IF(CX22="",0,(IF(CW22="",360,180)/(60/CX22))*1.35) -> 292.329 | DE22: =IFERROR(CQ22+CR22,"") -> 1325 | DF22: =IFERROR(AL22,"") -> 33 | DG22: =IFERROR(AZ22,"") -> 8.0898876 | DH22: =IFERROR(CT22+CU22,"") -> 0 | DI22: =IFERROR(BF22,"") -> 0 | DJ22: =IFERROR(BT22,"") -> 0 | DK22: =IFERROR(DE22+DH22,"") -> 1325 | DL22: =IFERROR(DF22+DI22,"") -> 33 | DM22: =IFERROR(DG22+DJ22,"") -> 8.0898876 | DN22: =T22 -> 39 | DO22: =U22 -> 61 | DR22: B14C150515 | DW22: =IFERROR(BU22+BV22,"") -> 1358 | DX22: =IFERROR(DK22+DL22+DM22,"") -> 1366.0899 | DY22: =CQ22+CR22+CS22+CT22+CU22+CV22 -> 1327 | DZ22: =IFERROR((AD22*V22/1000),0) -> 0.0089 | EA22: =IFERROR((AE22*V22/1000),0) -> 5.89625 | EB22: =BX22-EA22 -> 12.15475 | EC22: =EB22+DZ22 -> 12.16365 | EF22: =DG22+DJ22 -> 8.0898876
