Workbook

Sheet Code
A1: =CONCATENATE("BẢNG DỮ LIỆU KIỂM TRA TRƯỚC KHI UPLOAD PHẦN MỀM"," (NGÀY:" & Info!B5&")") -> BẢNG DỮ LIỆU KIỂM TRA TRƯỚC KHI UPLOAD PHẦN MỀM (NGÀY:21.07)
A2: STT | B2: Máy | C2: SP | D2: NL | O2: Ca 1 | S2: Ca 2 | W2: Tổng 2 ca
D3: Tên | E3: NCC | F3: OD | G3: ID | H3: Hình dạng | I3: Tiêu chuẩn | J3: Dài | K3: Lot | L3: TL | M3: Định mức | N3: Kho (CT) | O3: NL SD | P3: Oke | Q3: CXL | R3: PP | S3: NL SD | T3: Oke | U3: CXL | V3: PP | W3: NL SD | X3: Oke | Y3: CXL | Z3: PP
N4: =COUNT(N5:N1000)- COUNTIFS(N5:N1000,0) -> 72 | O4: =IFERROR(SUM(O5:O1000),0) -> 532.5 | P4: =IFERROR(SUM(P5:P1000),0) -> 82866 | Q4: =IFERROR(SUM(Q5:Q1000),0) -> 5155 | R4: =IFERROR(SUM(R5:R1000),0) -> 2264 | S4: =IFERROR(SUM(S5:S1000),0) -> 454.5 | T4: =IFERROR(SUM(T5:T1000),0) -> 69947 | U4: =IFERROR(SUM(U5:U1000),0) -> 7457 | V4: =IFERROR(SUM(V5:V1000),0) -> 645 | ... Z4: =IFERROR(SUM(Z5:Z1000),0) -> 2909
A5: 1 | B5: =IFERROR( IF(A5="","", VLOOKUP(A5,INDIRECT("'[" &Info!$B$4&"]"&Info!$B$5&"'!$A$6:$B$1000"),2,0)),"") -> C01 | C5: =IFERROR( IF(A5="","", VLOOKUP(A5,INDIRECT("'[" &Info!$B$4&"]"&Info!$B$5&"'!$A$6:$D$1000"),3,0)),"") -> SM04 | D5: =IF(C5="","", VLOOKUP(A5,INDIRECT("'[" &Info!$B$4&"]"&Info!$B$5&"'!$A$6:$T$1000"),20,0)) -> A6061-T6 | E5: =IF(D5="","", VLOOKUP(A5,INDIRECT("'[" &Info!$B$4&"]"&Info!$B$5&"'!$A$6:$U$1000"),21,0)) -> GW | F5: =IF(D5="","", VLOOKUP(A5,INDIRECT("'[" &Info!$B$4&"]"&Info!$B$5&"'!$A$6:$V$1000"),22,0)) -> 17 | G5: =IF(D5="","", VLOOKUP(A5,INDIRECT("'[" &Info!$B$4&"]"&Info!$B$5&"'!$A$6:$W$1000"),23,0)) -> 0 | H5: =IF(D5="","", VLOOKUP(A5,INDIRECT("'[" &Info!$B$4&"]"&Info!$B$5&"'!$A$6:$X$1000"),24,0)) -> D | I5: =LOWER( IF(D5="","", VLOOKUP(A5,INDIRECT("'[" &Info!$B$4&"]"&Info!$B$5&"'!$A$6:$y$1000"),25,0))) -> h9 | J5: =IF(D5="","", VLOOKUP(A5,INDIRECT("'[" &Info!$B$4&"]"&Info!$B$5&"'!$A$6:$Z$1000"),26,0)) -> 3 | K5: =IF(D5="","", VLOOKUP(A5,INDIRECT("'[" &Info!$B$4&"]"&Info!$B$5&"'!$A$6:$AA$1000"),27,0)) -> D17 | L5: =IF(D5="","", VLOOKUP(A5,INDIRECT("'[" &Info!$B$4&"]"&Info!$B$5&"'!$A$6:$H$1000"),8,0)) -> 10.1 | M5: =IF(D5="","", VLOOKUP(A5,INDIRECT("'[" &Info!$B$4&"]"&Info!$B$5&"'!$A$6:$F$1000"),6,0)) -> 70 | N5: =IF(C5="","", VLOOKUP(A5,INDIRECT("'[" &Info!$B$4&"]"&Info!$B$5&"'!$A$6:$Au$1000"),47,0)) -> 12 | O5: =IF(N5="","",IF(N5=0,0,VLOOKUP(A5,INDIRECT("'[" &Info!$B$4&"]"&Info!$B$5&"'!$A$6:$AH$1000"),34,0))) -> 13 | P5: =IF(N5="","",IF(N5=0,0,VLOOKUP(A5,INDIRECT("'[" &Info!$B$4&"]"&Info!$B$5&"'!$A$6:$AW$1000"),49,0))) -> 910 | Q5: =IF(N5="","",IF(N5=0,0, VLOOKUP(A5,INDIRECT("'[" &Info!$B$4&"]"&Info!$B$5&"'!$A$6:$AX$1000"),50,0))) -> 0 | R5: =IF(N5="","",IF(N5=0,0, VLOOKUP(A5,INDIRECT("'[" &Info!$B$4&"]"&Info!$B$5&"'!$A$6:$AY$1000"),51,0))) -> 0 | S5: =IF(N5="","",IF(N5=0,0,VLOOKUP(A5,INDIRECT("'[" &Info!$B$4&"]"&Info!$B$5&"'!$A$6:$Ai$1000"),35,0))) -> 10 | T5: =IF(N5="","",IF(N5=0,0, VLOOKUP(A5,INDIRECT("'[" &Info!$B$4&"]"&Info!$B$5&"'!$A$6:$Az$1000"),52,0))) -> 683 | U5: =IF(N5="","",IF(N5=0,0, VLOOKUP(A5,INDIRECT("'[" &Info!$B$4&"]"&Info!$B$5&"'!$A$6:$BA$1000"),53,0))) -> 0 | V5: =IF(N5="","",IF(N5=0,0, VLOOKUP(A5,INDIRECT("'[" &Info!$B$4&"]"&Info!$B$5&"'!$A$6:$BB$1000"),54,0))) -> 0 | W5: =IF(N6="","",O5+S5) -> 23 | X5: =IF(N6="","",P5+T5) -> 1593 | Y5: =IF(N6="","",Q5+U5) -> 0 | Z5: =IF(N6="","",R5+V5) -> 0
A6: =IFERROR( VLOOKUP(A5+1,INDIRECT("'[" &Info!$B$4&"]"&Info!$B$5&"'!$A$6:$A$1000"),1,0),"") -> 2 | B6: =IFERROR( IF(A6="","", VLOOKUP(A6,INDIRECT("'[" &Info!$B$4&"]"&Info!$B$5&"'!$A$6:$B$1000"),2,0)),"") -> C02 | C6: =IFERROR( IF(A6="","", VLOOKUP(A6,INDIRECT("'[" &Info!$B$4&"]"&Info!$B$5&"'!$A$6:$D$1000"),3,0)),"") -> 3201 | D6: =IF(C6="","", VLOOKUP(A6,INDIRECT("'[" &Info!$B$4&"]"&Info!$B$5&"'!$A$6:$T$1000"),20,0)) -> C2700 | E6: =IF(D6="","", VLOOKUP(A6,INDIRECT("'[" &Info!$B$4&"]"&Info!$B$5&"'!$A$6:$U$1000"),21,0)) -> YH | F6: =IF(D6="","", VLOOKUP(A6,INDIRECT("'[" &Info!$B$4&"]"&Info!$B$5&"'!$A$6:$U$1000"),21,0)) -> YH | G6: =IF(D6="","", VLOOKUP(A6,INDIRECT("'[" &Info!$B$4&"]"&Info!$B$5&"'!$A$6:$V$1000"),22,0)) -> 5.5 | H6: =IF(D6="","", VLOOKUP(A6,INDIRECT("'[" &Info!$B$4&"]"&Info!$B$5&"'!$A$6:$W$1000"),23,0)) -> 0 | I6: =LOWER( IF(D6="","", VLOOKUP(A6,INDIRECT("'[" &Info!$B$4&"]"&Info!$B$5&"'!$A$6:$y$1000"),25,0))) -> h9 | J6: =IF(D6="","", VLOOKUP(A6,INDIRECT("'[" &Info!$B$4&"]"&Info!$B$5&"'!$A$6:$Z$1000"),26,0)) -> 3 | K6: =IF(D6="","", VLOOKUP(A6,INDIRECT("'[" &Info!$B$4&"]"&Info!$B$5&"'!$A$6:$AA$1000"),27,0)) -> A17 | L6: =IF(D6="","", VLOOKUP(A6,INDIRECT("'[" &Info!$B$4&"]"&Info!$B$5&"'!$A$6:$H$1000"),8,0)) -> 1.076 | M6: =IF(D6="","", VLOOKUP(A6,INDIRECT("'[" &Info!$B$4&"]"&Info!$B$5&"'!$A$6:$F$1000"),6,0)) -> 167 | N6: =IF(C6="","", VLOOKUP(A6,INDIRECT("'[" &Info!$B$4&"]"&Info!$B$5&"'!$A$6:$Au$1000"),47,0)) -> 12 | O6: =IF(N6="","",IF(N6=0,0,VLOOKUP(A6,INDIRECT("'[" &Info!$B$4&"]"&Info!$B$5&"'!$A$6:$AH$1000"),34,0))) -> 5 | P6: =IF(N6="","",IF(N6=0,0,VLOOKUP(A6,INDIRECT("'[" &Info!$B$4&"]"&Info!$B$5&"'!$A$6:$AW$1000"),49,0))) -> 747 | Q6: =IF(N6="","",IF(N6=0,0, VLOOKUP(A6,INDIRECT("'[" &Info!$B$4&"]"&Info!$B$5&"'!$A$6:$AX$1000"),50,0))) -> 0 | R6: =IF(N6="","",IF(N6=0,0, VLOOKUP(A6,INDIRECT("'[" &Info!$B$4&"]"&Info!$B$5&"'!$A$6:$AY$1000"),51,0))) -> 0 | S6: =IF(N6="","",IF(N6=0,0,VLOOKUP(A6,INDIRECT("'[" &Info!$B$4&"]"&Info!$B$5&"'!$A$6:$Ai$1000"),35,0))) -> 5 | T6: =IF(N6="","",IF(N6=0,0, VLOOKUP(A6,INDIRECT("'[" &Info!$B$4&"]"&Info!$B$5&"'!$A$6:$Az$1000"),52,0))) -> 284 | U6: =IF(N6="","",IF(N6=0,0, VLOOKUP(A6,INDIRECT("'[" &Info!$B$4&"]"&Info!$B$5&"'!$A$6:$BA$1000"),53,0))) -> 0 | V6: =IF(N6="","",IF(N6=0,0, VLOOKUP(A6,INDIRECT("'[" &Info!$B$4&"]"&Info!$B$5&"'!$A$6:$BB$1000"),54,0))) -> 0 | W6: =IF(N7="","",O6+S6) -> 10 | X6: =IF(N7="","",P6+T6) -> 1031 | Y6: =IF(N7="","",Q6+U6) -> 0 | Z6: =IF(N7="","",R6+V6) -> 0
A7: =IFERROR( VLOOKUP(A6+1,INDIRECT("'[" &Info!$B$4&"]"&Info!$B$5&"'!$A$6:$A$1000"),1,0),"") -> 3 | B7: =IFERROR( IF(A7="","", VLOOKUP(A7,INDIRECT("'[" &Info!$B$4&"]"&Info!$B$5&"'!$A$6:$B$1000"),2,0)),"") -> C03 | C7: =IFERROR( IF(A7="","", VLOOKUP(A7,INDIRECT("'[" &Info!$B$4&"]"&Info!$B$5&"'!$A$6:$D$1000"),3,0)),"") -> SM04 | D7: =IF(C7="","", VLOOKUP(A7,INDIRECT("'[" &Info!$B$4&"]"&Info!$B$5&"'!$A$6:$T$1000"),20,0)) -> A6061-T6 | E7: =IF(D7="","", VLOOKUP(A7,INDIRECT("'[" &Info!$B$4&"]"&Info!$B$5&"'!$A$6:$U$1000"),21,0)) -> GW | F7: =IF(D7="","", VLOOKUP(A7,INDIRECT("'[" &Info!$B$4&"]"&Info!$B$5&"'!$A$6:$U$1000"),21,0)) -> GW | G7: =IF(D7="","", VLOOKUP(A7,INDIRECT("'[" &Info!$B$4&"]"&Info!$B$5&"'!$A$6:$V$1000"),22,0)) -> 17 | H7: =IF(D7="","", VLOOKUP(A7,INDIRECT("'[" &Info!$B$4&"]"&Info!$B$5&"'!$A$6:$W$1000"),23,0)) -> 0 | I7: =LOWER( IF(D7="","", VLOOKUP(A7,INDIRECT("'[" &Info!$B$4&"]"&Info!$B$5&"'!$A$6:$y$1000"),25,0))) -> h9 | J7: =IF(D7="","", VLOOKUP(A7,INDIRECT("'[" &Info!$B$4&"]"&Info!$B$5&"'!$A$6:$Z$1000"),26,0)) -> 3 | K7: =IF(D7="","", VLOOKUP(A7,INDIRECT("'[" &Info!$B$4&"]"&Info!$B$5&"'!$A$6:$AA$1000"),27,0)) -> D17 | L7: =IF(D7="","", VLOOKUP(A7,INDIRECT("'[" &Info!$B$4&"]"&Info!$B$5&"'!$A$6:$H$1000"),8,0)) -> 10.1 | M7: =IF(D7="","", VLOOKUP(A7,INDIRECT("'[" &Info!$B$4&"]"&Info!$B$5&"'!$A$6:$F$1000"),6,0)) -> 70 | N7: =IF(C7="","", VLOOKUP(A7,INDIRECT("'[" &Info!$B$4&"]"&Info!$B$5&"'!$A$6:$Au$1000"),47,0)) -> 12 | O7: =IF(N7="","",IF(N7=0,0,VLOOKUP(A7,INDIRECT("'[" &Info!$B$4&"]"&Info!$B$5&"'!$A$6:$AH$1000"),34,0))) -> 14 | P7: =IF(N7="","",IF(N7=0,0,VLOOKUP(A7,INDIRECT("'[" &Info!$B$4&"]"&Info!$B$5&"'!$A$6:$AW$1000"),49,0))) -> 831 | Q7: =IF(N7="","",IF(N7=0,0, VLOOKUP(A7,INDIRECT("'[" &Info!$B$4&"]"&Info!$B$5&"'!$A$6:$AX$1000"),50,0))) -> 0 | R7: =IF(N7="","",IF(N7=0,0, VLOOKUP(A7,INDIRECT("'[" &Info!$B$4&"]"&Info!$B$5&"'!$A$6:$AY$1000"),51,0))) -> 0 | S7: =IF(N7="","",IF(N7=0,0,VLOOKUP(A7,INDIRECT("'[" &Info!$B$4&"]"&Info!$B$5&"'!$A$6:$Ai$1000"),35,0))) -> 0 | T7: =IF(N7="","",IF(N7=0,0, VLOOKUP(A7,INDIRECT("'[" &Info!$B$4&"]"&Info!$B$5&"'!$A$6:$Az$1000"),52,0))) -> 0 | U7: =IF(N7="","",IF(N7=0,0, VLOOKUP(A7,INDIRECT("'[" &Info!$B$4&"]"&Info!$B$5&"'!$A$6:$BA$1000"),53,0))) -> 0 | V7: =IF(N7="","",IF(N7=0,0, VLOOKUP(A7,INDIRECT("'[" &Info!$B$4&"]"&Info!$B$5&"'!$A$6:$BB$1000"),54,0))) -> 0 | W7: =IF(N8="","",O7+S7) -> 14 | X7: =IF(N8="","",P7+T7) -> 831 | Y7: =IF(N8="","",Q7+U7) -> 0 | Z7: =IF(N8="","",R7+V7) -> 0
A8: =IFERROR( VLOOKUP(A7+1,INDIRECT("'[" &Info!$B$4&"]"&Info!$B$5&"'!$A$6:$A$1000"),1,0),"") -> 4 | B8: =IFERROR( IF(A8="","", VLOOKUP(A8,INDIRECT("'[" &Info!$B$4&"]"&Info!$B$5&"'!$A$6:$B$1000"),2,0)),"") -> C04 | C8: =IFERROR( IF(A8="","", VLOOKUP(A8,INDIRECT("'[" &Info!$B$4&"]"&Info!$B$5&"'!$A$6:$D$1000"),3,0)),"") -> 1501 | D8: =IF(C8="","", VLOOKUP(A8,INDIRECT("'[" &Info!$B$4&"]"&Info!$B$5&"'!$A$6:$T$1000"),20,0)) -> 12L14 | E8: =IF(D8="","", VLOOKUP(A8,INDIRECT("'[" &Info!$B$4&"]"&Info!$B$5&"'!$A$6:$U$1000"),21,0)) -> LT | F8: =IF(D8="","", VLOOKUP(A8,INDIRECT("'[" &Info!$B$4&"]"&Info!$B$5&"'!$A$6:$U$1000"),21,0)) -> LT | G8: =IF(D8="","", VLOOKUP(A8,INDIRECT("'[" &Info!$B$4&"]"&Info!$B$5&"'!$A$6:$V$1000"),22,0)) -> 11 | H8: =IF(D8="","", VLOOKUP(A8,INDIRECT("'[" &Info!$B$4&"]"&Info!$B$5&"'!$A$6:$W$1000"),23,0)) -> 0 | I8: =LOWER( IF(D8="","", VLOOKUP(A8,INDIRECT("'[" &Info!$B$4&"]"&Info!$B$5&"'!$A$6:$y$1000"),25,0))) -> h9 | J8: =IF(D8="","", VLOOKUP(A8,INDIRECT("'[" &Info!$B$4&"]"&Info!$B$5&"'!$A$6:$Z$1000"),26,0)) -> 3 | K8: =IF(D8="","", VLOOKUP(A8,INDIRECT("'[" &Info!$B$4&"]"&Info!$B$5&"'!$A$6:$AA$1000"),27,0)) -> A17 | L8: =IF(D8="","", VLOOKUP(A8,INDIRECT("'[" &Info!$B$4&"]"&Info!$B$5&"'!$A$6:$H$1000"),8,0)) -> 2.02 | M8: =IF(D8="","", VLOOKUP(A8,INDIRECT("'[" &Info!$B$4&"]"&Info!$B$5&"'!$A$6:$F$1000"),6,0)) -> 0 | N8: =IF(C8="","", VLOOKUP(A8,INDIRECT("'[" &Info!$B$4&"]"&Info!$B$5&"'!$A$6:$Au$1000"),47,0)) -> 0 | O8: =IF(N8="","",IF(N8=0,0,VLOOKUP(A8,INDIRECT("'[" &Info!$B$4&"]"&Info!$B$5&"'!$A$6:$AH$1000"),34,0))) -> 0 | P8: =IF(N8="","",IF(N8=0,0,VLOOKUP(A8,INDIRECT("'[" &Info!$B$4&"]"&Info!$B$5&"'!$A$6:$AW$1000"),49,0))) -> 0 | Q8: =IF(N8="","",IF(N8=0,0, VLOOKUP(A8,INDIRECT("'[" &Info!$B$4&"]"&Info!$B$5&"'!$A$6:$AX$1000"),50,0))) -> 0 | R8: =IF(N8="","",IF(N8=0,0, VLOOKUP(A8,INDIRECT("'[" &Info!$B$4&"]"&Info!$B$5&"'!$A$6:$AY$1000"),51,0))) -> 0 | S8: =IF(N8="","",IF(N8=0,0,VLOOKUP(A8,INDIRECT("'[" &Info!$B$4&"]"&Info!$B$5&"'!$A$6:$Ai$1000"),35,0))) -> 0 | T8: =IF(N8="","",IF(N8=0,0, VLOOKUP(A8,INDIRECT("'[" &Info!$B$4&"]"&Info!$B$5&"'!$A$6:$Az$1000"),52,0))) -> 0 | U8: =IF(N8="","",IF(N8=0,0, VLOOKUP(A8,INDIRECT("'[" &Info!$B$4&"]"&Info!$B$5&"'!$A$6:$BA$1000"),53,0))) -> 0 | V8: =IF(N8="","",IF(N8=0,0, VLOOKUP(A8,INDIRECT("'[" &Info!$B$4&"]"&Info!$B$5&"'!$A$6:$BB$1000"),54,0))) -> 0 | W8: =IF(N9="","",O8+S8) -> 0 | X8: =IF(N9="","",P8+T8) -> 0 | Y8: =IF(N9="","",Q8+U8) -> 0 | Z8: =IF(N9="","",R8+V8) -> 0
A9: =IFERROR( VLOOKUP(A8+1,INDIRECT("'[" &Info!$B$4&"]"&Info!$B$5&"'!$A$6:$A$1000"),1,0),"") -> 5 | B9: =IFERROR( IF(A9="","", VLOOKUP(A9,INDIRECT("'[" &Info!$B$4&"]"&Info!$B$5&"'!$A$6:$B$1000"),2,0)),"") -> C05 | C9: =IFERROR( IF(A9="","", VLOOKUP(A9,INDIRECT("'[" &Info!$B$4&"]"&Info!$B$5&"'!$A$6:$D$1000"),3,0)),"") -> SC6 | D9: =IF(C9="","", VLOOKUP(A9,INDIRECT("'[" &Info!$B$4&"]"&Info!$B$5&"'!$A$6:$T$1000"),20,0)) -> 12L14 | E9: =IF(D9="","", VLOOKUP(A9,INDIRECT("'[" &Info!$B$4&"]"&Info!$B$5&"'!$A$6:$U$1000"),21,0)) -> TV | F9: =IF(D9="","", VLOOKUP(A9,INDIRECT("'[" &Info!$B$4&"]"&Info!$B$5&"'!$A$6:$U$1000"),21,0)) -> TV | G9: =IF(D9="","", VLOOKUP(A9,INDIRECT("'[" &Info!$B$4&"]"&Info!$B$5&"'!$A$6:$V$1000"),22,0)) -> 5.97 | H9: =IF(D9="","", VLOOKUP(A9,INDIRECT("'[" &Info!$B$4&"]"&Info!$B$5&"'!$A$6:$W$1000"),23,0)) -> 0 | I9: =LOWER( IF(D9="","", VLOOKUP(A9,INDIRECT("'[" &Info!$B$4&"]"&Info!$B$5&"'!$A$6:$y$1000"),25,0))) -> h9 | J9: =IF(D9="","", VLOOKUP(A9,INDIRECT("'[" &Info!$B$4&"]"&Info!$B$5&"'!$A$6:$Z$1000"),26,0)) -> 3 | K9: =IF(D9="","", VLOOKUP(A9,INDIRECT("'[" &Info!$B$4&"]"&Info!$B$5&"'!$A$6:$AA$1000"),27,0)) -> A17 | L9: =IF(D9="","", VLOOKUP(A9,INDIRECT("'[" &Info!$B$4&"]"&Info!$B$5&"'!$A$6:$H$1000"),8,0)) -> 4.65 | M9: =IF(D9="","", VLOOKUP(A9,INDIRECT("'[" &Info!$B$4&"]"&Info!$B$5&"'!$A$6:$F$1000"),6,0)) -> 38 | N9: =IF(C9="","", VLOOKUP(A9,INDIRECT("'[" &Info!$B$4&"]"&Info!$B$5&"'!$A$6:$Au$1000"),47,0)) -> 12 | O9: =IF(N9="","",IF(N9=0,0,VLOOKUP(A9,INDIRECT("'[" &Info!$B$4&"]"&Info!$B$5&"'!$A$6:$AH$1000"),34,0))) -> 1 | P9: =IF(N9="","",IF(N9=0,0,VLOOKUP(A9,INDIRECT("'[" &Info!$B$4&"]"&Info!$B$5&"'!$A$6:$AW$1000"),49,0))) -> 0 | Q9: =IF(N9="","",IF(N9=0,0, VLOOKUP(A9,INDIRECT("'[" &Info!$B$4&"]"&Info!$B$5&"'!$A$6:$AX$1000"),50,0))) -> 0 | R9: =IF(N9="","",IF(N9=0,0, VLOOKUP(A9,INDIRECT("'[" &Info!$B$4&"]"&Info!$B$5&"'!$A$6:$AY$1000"),51,0))) -> 204 | S9: =IF(N9="","",IF(N9=0,0,VLOOKUP(A9,INDIRECT("'[" &Info!$B$4&"]"&Info!$B$5&"'!$A$6:$Ai$1000"),35,0))) -> 0 | T9: =IF(N9="","",IF(N9=0,0, VLOOKUP(A9,INDIRECT("'[" &Info!$B$4&"]"&Info!$B$5&"'!$A$6:$Az$1000"),52,0))) -> 0 | U9: =IF(N9="","",IF(N9=0,0, VLOOKUP(A9,INDIRECT("'[" &Info!$B$4&"]"&Info!$B$5&"'!$A$6:$BA$1000"),53,0))) -> 0 | V9: =IF(N9="","",IF(N9=0,0, VLOOKUP(A9,INDIRECT("'[" &Info!$B$4&"]"&Info!$B$5&"'!$A$6:$BB$1000"),54,0))) -> 0 | W9: =IF(N10="","",O9+S9) -> 1 | X9: =IF(N10="","",P9+T9) -> 0 | Y9: =IF(N10="","",Q9+U9) -> 0 | Z9: =IF(N10="","",R9+V9) -> 204
A10: =IFERROR( VLOOKUP(A9+1,INDIRECT("'[" &Info!$B$4&"]"&Info!$B$5&"'!$A$6:$A$1000"),1,0),"") -> 6 | B10: =IFERROR( IF(A10="","", VLOOKUP(A10,INDIRECT("'[" &Info!$B$4&"]"&Info!$B$5&"'!$A$6:$B$1000"),2,0)),"") -> C06 | C10: =IFERROR( IF(A10="","", VLOOKUP(A10,INDIRECT("'[" &Info!$B$4&"]"&Info!$B$5&"'!$A$6:$D$1000"),3,0)),"") -> 10620 | D10: =IF(C10="","", VLOOKUP(A10,INDIRECT("'[" &Info!$B$4&"]"&Info!$B$5&"'!$A$6:$T$1000"),20,0)) -> C3604 | E10: =IF(D10="","", VLOOKUP(A10,INDIRECT("'[" &Info!$B$4&"]"&Info!$B$5&"'!$A$6:$U$1000"),21,0)) -> GH | F10: =IF(D10="","", VLOOKUP(A10,INDIRECT("'[" &Info!$B$4&"]"&Info!$B$5&"'!$A$6:$U$1000"),21,0)) -> GH | G10: =IF(D10="","", VLOOKUP(A10,INDIRECT("'[" &Info!$B$4&"]"&Info!$B$5&"'!$A$6:$V$1000"),22,0)) -> 10 | H10: =IF(D10="","", VLOOKUP(A10,INDIRECT("'[" &Info!$B$4&"]"&Info!$B$5&"'!$A$6:$W$1000"),23,0)) -> 0 | I10: =LOWER( IF(D10="","", VLOOKUP(A10,INDIRECT("'[" &Info!$B$4&"]"&Info!$B$5&"'!$A$6:$y$1000"),25,0))) -> h9 | J10: =IF(D10="","", VLOOKUP(A10,INDIRECT("'[" &Info!$B$4&"]"&Info!$B$5&"'!$A$6:$Z$1000"),26,0)) -> 2.5 | K10: =IF(D10="","", VLOOKUP(A10,INDIRECT("'[" &Info!$B$4&"]"&Info!$B$5&"'!$A$6:$AA$1000"),27,0)) -> B17 | L10: =IF(D10="","", VLOOKUP(A10,INDIRECT("'[" &Info!$B$4&"]"&Info!$B$5&"'!$A$6:$H$1000"),8,0)) -> 7.4 | M10: =IF(D10="","", VLOOKUP(A10,INDIRECT("'[" &Info!$B$4&"]"&Info!$B$5&"'!$A$6:$F$1000"),6,0)) -> 104 | N10: =IF(C10="","", VLOOKUP(A10,INDIRECT("'[" &Info!$B$4&"]"&Info!$B$5&"'!$A$6:$Au$1000"),47,0)) -> 0 | O10: =IF(N10="","",IF(N10=0,0,VLOOKUP(A10,INDIRECT("'[" &Info!$B$4&"]"&Info!$B$5&"'!$A$6:$AH$1000"),34,0))) -> 0 | P10: =IF(N10="","",IF(N10=0,0,VLOOKUP(A10,INDIRECT("'[" &Info!$B$4&"]"&Info!$B$5&"'!$A$6:$AW$1000"),49,0))) -> 0 | Q10: =IF(N10="","",IF(N10=0,0, VLOOKUP(A10,INDIRECT("'[" &Info!$B$4&"]"&Info!$B$5&"'!$A$6:$AX$1000"),50,0))) -> 0 | R10: =IF(N10="","",IF(N10=0,0, VLOOKUP(A10,INDIRECT("'[" &Info!$B$4&"]"&Info!$B$5&"'!$A$6:$AY$1000"),51,0))) -> 0 | S10: =IF(N10="","",IF(N10=0,0,VLOOKUP(A10,INDIRECT("'[" &Info!$B$4&"]"&Info!$B$5&"'!$A$6:$Ai$1000"),35,0))) -> 0 | T10: =IF(N10="","",IF(N10=0,0, VLOOKUP(A10,INDIRECT("'[" &Info!$B$4&"]"&Info!$B$5&"'!$A$6:$Az$1000"),52,0))) -> 0 | U10: =IF(N10="","",IF(N10=0,0, VLOOKUP(A10,INDIRECT("'[" &Info!$B$4&"]"&Info!$B$5&"'!$A$6:$BA$1000"),53,0))) -> 0 | V10: =IF(N10="","",IF(N10=0,0, VLOOKUP(A10,INDIRECT("'[" &Info!$B$4&"]"&Info!$B$5&"'!$A$6:$BB$1000"),54,0))) -> 0 | W10: =IF(N11="","",O10+S10) -> 0 | X10: =IF(N11="","",P10+T10) -> 0 | Y10: =IF(N11="","",Q10+U10) -> 0 | Z10: =IF(N11="","",R10+V10) -> 0
A11: =IFERROR( VLOOKUP(A10+1,INDIRECT("'[" &Info!$B$4&"]"&Info!$B$5&"'!$A$6:$A$1000"),1,0),"") -> 7 | B11: =IFERROR( IF(A11="","", VLOOKUP(A11,INDIRECT("'[" &Info!$B$4&"]"&Info!$B$5&"'!$A$6:$B$1000"),2,0)),"") -> C07 | C11: =IFERROR( IF(A11="","", VLOOKUP(A11,INDIRECT("'[" &Info!$B$4&"]"&Info!$B$5&"'!$A$6:$D$1000"),3,0)),"") -> SC5 | D11: =IF(C11="","", VLOOKUP(A11,INDIRECT("'[" &Info!$B$4&"]"&Info!$B$5&"'!$A$6:$T$1000"),20,0)) -> 12L14 | E11: =IF(D11="","", VLOOKUP(A11,INDIRECT("'[" &Info!$B$4&"]"&Info!$B$5&"'!$A$6:$U$1000"),21,0)) -> LT | F11: =IF(D11="","", VLOOKUP(A11,INDIRECT("'[" &Info!$B$4&"]"&Info!$B$5&"'!$A$6:$U$1000"),21,0)) -> LT | G11: =IF(D11="","", VLOOKUP(A11,INDIRECT("'[" &Info!$B$4&"]"&Info!$B$5&"'!$A$6:$V$1000"),22,0)) -> 6 | H11: =IF(D11="","", VLOOKUP(A11,INDIRECT("'[" &Info!$B$4&"]"&Info!$B$5&"'!$A$6:$W$1000"),23,0)) -> 0 | I11: =LOWER( IF(D11="","", VLOOKUP(A11,INDIRECT("'[" &Info!$B$4&"]"&Info!$B$5&"'!$A$6:$y$1000"),25,0))) -> h9 | J11: =IF(D11="","", VLOOKUP(A11,INDIRECT("'[" &Info!$B$4&"]"&Info!$B$5&"'!$A$6:$Z$1000"),26,0)) -> 3 | K11: =IF(D11="","", VLOOKUP(A11,INDIRECT("'[" &Info!$B$4&"]"&Info!$B$5&"'!$A$6:$AA$1000"),27,0)) -> A17 | L11: =IF(D11="","", VLOOKUP(A11,INDIRECT("'[" &Info!$B$4&"]"&Info!$B$5&"'!$A$6:$H$1000"),8,0)) -> 4.55 | M11: =IF(D11="","", VLOOKUP(A11,INDIRECT("'[" &Info!$B$4&"]"&Info!$B$5&"'!$A$6:$F$1000"),6,0)) -> 48 | N11: =IF(C11="","", VLOOKUP(A11,INDIRECT("'[" &Info!$B$4&"]"&Info!$B$5&"'!$A$6:$Au$1000"),47,0)) -> 0 | O11: =IF(N11="","",IF(N11=0,0,VLOOKUP(A11,INDIRECT("'[" &Info!$B$4&"]"&Info!$B$5&"'!$A$6:$AH$1000"),34,0))) -> 0 | P11: =IF(N11="","",IF(N11=0,0,VLOOKUP(A11,INDIRECT("'[" &Info!$B$4&"]"&Info!$B$5&"'!$A$6:$AW$1000"),49,0))) -> 0 | Q11: =IF(N11="","",IF(N11=0,0, VLOOKUP(A11,INDIRECT("'[" &Info!$B$4&"]"&Info!$B$5&"'!$A$6:$AX$1000"),50,0))) -> 0 | R11: =IF(N11="","",IF(N11=0,0, VLOOKUP(A11,INDIRECT("'[" &Info!$B$4&"]"&Info!$B$5&"'!$A$6:$AY$1000"),51,0))) -> 0 | S11: =IF(N11="","",IF(N11=0,0,VLOOKUP(A11,INDIRECT("'[" &Info!$B$4&"]"&Info!$B$5&"'!$A$6:$Ai$1000"),35,0))) -> 0 | T11: =IF(N11="","",IF(N11=0,0, VLOOKUP(A11,INDIRECT("'[" &Info!$B$4&"]"&Info!$B$5&"'!$A$6:$Az$1000"),52,0))) -> 0 | U11: =IF(N11="","",IF(N11=0,0, VLOOKUP(A11,INDIRECT("'[" &Info!$B$4&"]"&Info!$B$5&"'!$A$6:$BA$1000"),53,0))) -> 0 | V11: =IF(N11="","",IF(N11=0,0, VLOOKUP(A11,INDIRECT("'[" &Info!$B$4&"]"&Info!$B$5&"'!$A$6:$BB$1000"),54,0))) -> 0 | W11: =IF(N12="","",O11+S11) -> 0 | X11: =IF(N12="","",P11+T11) -> 0 | Y11: =IF(N12="","",Q11+U11) -> 0 | Z11: =IF(N12="","",R11+V11) -> 0
A12: =IFERROR( VLOOKUP(A11+1,INDIRECT("'[" &Info!$B$4&"]"&Info!$B$5&"'!$A$6:$A$1000"),1,0),"") -> 8 | B12: =IFERROR( IF(A12="","", VLOOKUP(A12,INDIRECT("'[" &Info!$B$4&"]"&Info!$B$5&"'!$A$6:$B$1000"),2,0)),"") -> C08 | C12: =IFERROR( IF(A12="","", VLOOKUP(A12,INDIRECT("'[" &Info!$B$4&"]"&Info!$B$5&"'!$A$6:$D$1000"),3,0)),"") -> 15106 | D12: =IF(C12="","", VLOOKUP(A12,INDIRECT("'[" &Info!$B$4&"]"&Info!$B$5&"'!$A$6:$T$1000"),20,0)) -> C3604 | E12: =IF(D12="","", VLOOKUP(A12,INDIRECT("'[" &Info!$B$4&"]"&Info!$B$5&"'!$A$6:$U$1000"),21,0)) -> YH | F12: =IF(D12="","", VLOOKUP(A12,INDIRECT("'[" &Info!$B$4&"]"&Info!$B$5&"'!$A$6:$U$1000"),21,0)) -> YH | G12: =IF(D12="","", VLOOKUP(A12,INDIRECT("'[" &Info!$B$4&"]"&Info!$B$5&"'!$A$6:$V$1000"),22,0)) -> 14 | H12: =IF(D12="","", VLOOKUP(A12,INDIRECT("'[" &Info!$B$4&"]"&Info!$B$5&"'!$A$6:$W$1000"),23,0)) -> 0 | I12: =LOWER( IF(D12="","", VLOOKUP(A12,INDIRECT("'[" &Info!$B$4&"]"&Info!$B$5&"'!$A$6:$y$1000"),25,0))) -> h9 | J12: =IF(D12="","", VLOOKUP(A12,INDIRECT("'[" &Info!$B$4&"]"&Info!$B$5&"'!$A$6:$Z$1000"),26,0)) -> 3 | K12: =IF(D12="","", VLOOKUP(A12,INDIRECT("'[" &Info!$B$4&"]"&Info!$B$5&"'!$A$6:$AA$1000"),27,0)) -> E16 | L12: =IF(D12="","", VLOOKUP(A12,INDIRECT("'[" &Info!$B$4&"]"&Info!$B$5&"'!$A$6:$H$1000"),8,0)) -> 2.84 | M12: =IF(D12="","", VLOOKUP(A12,INDIRECT("'[" &Info!$B$4&"]"&Info!$B$5&"'!$A$6:$F$1000"),6,0)) -> 491 | N12: =IF(C12="","", VLOOKUP(A12,INDIRECT("'[" &Info!$B$4&"]"&Info!$B$5&"'!$A$6:$Au$1000"),47,0)) -> 7 | O12: =IF(N12="","",IF(N12=0,0,VLOOKUP(A12,INDIRECT("'[" &Info!$B$4&"]"&Info!$B$5&"'!$A$6:$AH$1000"),34,0))) -> 3 | P12: =IF(N12="","",IF(N12=0,0,VLOOKUP(A12,INDIRECT("'[" &Info!$B$4&"]"&Info!$B$5&"'!$A$6:$AW$1000"),49,0))) -> 1098 | Q12: =IF(N12="","",IF(N12=0,0, VLOOKUP(A12,INDIRECT("'[" &Info!$B$4&"]"&Info!$B$5&"'!$A$6:$AX$1000"),50,0))) -> 200 | R12: =IF(N12="","",IF(N12=0,0, VLOOKUP(A12,INDIRECT("'[" &Info!$B$4&"]"&Info!$B$5&"'!$A$6:$AY$1000"),51,0))) -> 0 | S12: =IF(N12="","",IF(N12=0,0,VLOOKUP(A12,INDIRECT("'[" &Info!$B$4&"]"&Info!$B$5&"'!$A$6:$Ai$1000"),35,0))) -> 3 | T12: =IF(N12="","",IF(N12=0,0, VLOOKUP(A12,INDIRECT("'[" &Info!$B$4&"]"&Info!$B$5&"'!$A$6:$Az$1000"),52,0))) -> 1241 | U12: =IF(N12="","",IF(N12=0,0, VLOOKUP(A12,INDIRECT("'[" &Info!$B$4&"]"&Info!$B$5&"'!$A$6:$BA$1000"),53,0))) -> 68 | V12: =IF(N12="","",IF(N12=0,0, VLOOKUP(A12,INDIRECT("'[" &Info!$B$4&"]"&Info!$B$5&"'!$A$6:$BB$1000"),54,0))) -> 425 | W12: =IF(N13="","",O12+S12) -> 6 | X12: =IF(N13="","",P12+T12) -> 2339 | Y12: =IF(N13="","",Q12+U12) -> 268 | Z12: =IF(N13="","",R12+V12) -> 425
A13: =IFERROR( VLOOKUP(A12+1,INDIRECT("'[" &Info!$B$4&"]"&Info!$B$5&"'!$A$6:$A$1000"),1,0),"") -> 9 | B13: =IFERROR( IF(A13="","", VLOOKUP(A13,INDIRECT("'[" &Info!$B$4&"]"&Info!$B$5&"'!$A$6:$B$1000"),2,0)),"") -> C09 | C13: =IFERROR( IF(A13="","", VLOOKUP(A13,INDIRECT("'[" &Info!$B$4&"]"&Info!$B$5&"'!$A$6:$D$1000"),3,0)),"") -> 131100 | D13: =IF(C13="","", VLOOKUP(A13,INDIRECT("'[" &Info!$B$4&"]"&Info!$B$5&"'!$A$6:$T$1000"),20,0)) -> A6063-T5 | E13: =IF(D13="","", VLOOKUP(A13,INDIRECT("'[" &Info!$B$4&"]"&Info!$B$5&"'!$A$6:$U$1000"),21,0)) -> GW | F13: =IF(D13="","", VLOOKUP(A13,INDIRECT("'[" &Info!$B$4&"]"&Info!$B$5&"'!$A$6:$U$1000"),21,0)) -> GW | G13: =IF(D13="","", VLOOKUP(A13,INDIRECT("'[" &Info!$B$4&"]"&Info!$B$5&"'!$A$6:$V$1000"),22,0)) -> 18.15 | H13: =IF(D13="","", VLOOKUP(A13,INDIRECT("'[" &Info!$B$4&"]"&Info!$B$5&"'!$A$6:$W$1000"),23,0)) -> 8.6 | I13: =LOWER( IF(D13="","", VLOOKUP(A13,INDIRECT("'[" &Info!$B$4&"]"&Info!$B$5&"'!$A$6:$y$1000"),25,0))) -> h9 | J13: =IF(D13="","", VLOOKUP(A13,INDIRECT("'[" &Info!$B$4&"]"&Info!$B$5&"'!$A$6:$Z$1000"),26,0)) -> 3 | K13: =IF(D13="","", VLOOKUP(A13,INDIRECT("'[" &Info!$B$4&"]"&Info!$B$5&"'!$A$6:$AA$1000"),27,0)) -> J17 | L13: =IF(D13="","", VLOOKUP(A13,INDIRECT("'[" &Info!$B$4&"]"&Info!$B$5&"'!$A$6:$H$1000"),8,0)) -> 9.9 | M13: =IF(D13="","", VLOOKUP(A13,INDIRECT("'[" &Info!$B$4&"]"&Info!$B$5&"'!$A$6:$F$1000"),6,0)) -> 70 | N13: =IF(C13="","", VLOOKUP(A13,INDIRECT("'[" &Info!$B$4&"]"&Info!$B$5&"'!$A$6:$Au$1000"),47,0)) -> 12 | O13: =IF(N13="","",IF(N13=0,0,VLOOKUP(A13,INDIRECT("'[" &Info!$B$4&"]"&Info!$B$5&"'!$A$6:$AH$1000"),34,0))) -> 2 | P13: =IF(N13="","",IF(N13=0,0,VLOOKUP(A13,INDIRECT("'[" &Info!$B$4&"]"&Info!$B$5&"'!$A$6:$AW$1000"),49,0))) -> 323 | Q13: =IF(N13="","",IF(N13=0,0, VLOOKUP(A13,INDIRECT("'[" &Info!$B$4&"]"&Info!$B$5&"'!$A$6:$AX$1000"),50,0))) -> 92 | R13: =IF(N13="","",IF(N13=0,0, VLOOKUP(A13,INDIRECT("'[" &Info!$B$4&"]"&Info!$B$5&"'!$A$6:$AY$1000"),51,0))) -> 0 | S13: =IF(N13="","",IF(N13=0,0,VLOOKUP(A13,INDIRECT("'[" &Info!$B$4&"]"&Info!$B$5&"'!$A$6:$Ai$1000"),35,0))) -> 0 | T13: =IF(N13="","",IF(N13=0,0, VLOOKUP(A13,INDIRECT("'[" &Info!$B$4&"]"&Info!$B$5&"'!$A$6:$Az$1000"),52,0))) -> 0 | U13: =IF(N13="","",IF(N13=0,0, VLOOKUP(A13,INDIRECT("'[" &Info!$B$4&"]"&Info!$B$5&"'!$A$6:$BA$1000"),53,0))) -> 0 | V13: =IF(N13="","",IF(N13=0,0, VLOOKUP(A13,INDIRECT("'[" &Info!$B$4&"]"&Info!$B$5&"'!$A$6:$BB$1000"),54,0))) -> 0 | W13: =IF(N14="","",O13+S13) -> 2 | X13: =IF(N14="","",P13+T13) -> 323 | Y13: =IF(N14="","",Q13+U13) -> 92 | Z13: =IF(N14="","",R13+V13) -> 0
A14: =IFERROR( VLOOKUP(A13+1,INDIRECT("'[" &Info!$B$4&"]"&Info!$B$5&"'!$A$6:$A$1000"),1,0),"") -> 10 | B14: =IFERROR( IF(A14="","", VLOOKUP(A14,INDIRECT("'[" &Info!$B$4&"]"&Info!$B$5&"'!$A$6:$B$1000"),2,0)),"") -> C10 | C14: =IFERROR( IF(A14="","", VLOOKUP(A14,INDIRECT("'[" &Info!$B$4&"]"&Info!$B$5&"'!$A$6:$D$1000"),3,0)),"") -> 131100 | D14: =IF(C14="","", VLOOKUP(A14,INDIRECT("'[" &Info!$B$4&"]"&Info!$B$5&"'!$A$6:$T$1000"),20,0)) -> A6063-T5 | E14: =IF(D14="","", VLOOKUP(A14,INDIRECT("'[" &Info!$B$4&"]"&Info!$B$5&"'!$A$6:$U$1000"),21,0)) -> GW | F14: =IF(D14="","", VLOOKUP(A14,INDIRECT("'[" &Info!$B$4&"]"&Info!$B$5&"'!$A$6:$U$1000"),21,0)) -> GW | G14: =IF(D14="","", VLOOKUP(A14,INDIRECT("'[" &Info!$B$4&"]"&Info!$B$5&"'!$A$6:$V$1000"),22,0)) -> 18.15 | H14: =IF(D14="","", VLOOKUP(A14,INDIRECT("'[" &Info!$B$4&"]"&Info!$B$5&"'!$A$6:$W$1000"),23,0)) -> 8.6 | I14: =LOWER( IF(D14="","", VLOOKUP(A14,INDIRECT("'[" &Info!$B$4&"]"&Info!$B$5&"'!$A$6:$y$1000"),25,0))) -> h9 | J14: =IF(D14="","", VLOOKUP(A14,INDIRECT("'[" &Info!$B$4&"]"&Info!$B$5&"'!$A$6:$Z$1000"),26,0)) -> 3 | K14: =IF(D14="","", VLOOKUP(A14,INDIRECT("'[" &Info!$B$4&"]"&Info!$B$5&"'!$A$6:$AA$1000"),27,0)) -> J17 | L14: =IF(D14="","", VLOOKUP(A14,INDIRECT("'[" &Info!$B$4&"]"&Info!$B$5&"'!$A$6:$H$1000"),8,0)) -> 9.9 | M14: =IF(D14="","", VLOOKUP(A14,INDIRECT("'[" &Info!$B$4&"]"&Info!$B$5&"'!$A$6:$F$1000"),6,0)) -> 70 | N14: =IF(C14="","", VLOOKUP(A14,INDIRECT("'[" &Info!$B$4&"]"&Info!$B$5&"'!$A$6:$Au$1000"),47,0)) -> 12 | O14: =IF(N14="","",IF(N14=0,0,VLOOKUP(A14,INDIRECT("'[" &Info!$B$4&"]"&Info!$B$5&"'!$A$6:$AH$1000"),34,0))) -> 8 | P14: =IF(N14="","",IF(N14=0,0,VLOOKUP(A14,INDIRECT("'[" &Info!$B$4&"]"&Info!$B$5&"'!$A$6:$AW$1000"),49,0))) -> 515 | Q14: =IF(N14="","",IF(N14=0,0, VLOOKUP(A14,INDIRECT("'[" &Info!$B$4&"]"&Info!$B$5&"'!$A$6:$AX$1000"),50,0))) -> 0 | R14: =IF(N14="","",IF(N14=0,0, VLOOKUP(A14,INDIRECT("'[" &Info!$B$4&"]"&Info!$B$5&"'!$A$6:$AY$1000"),51,0))) -> 119 | S14: =IF(N14="","",IF(N14=0,0,VLOOKUP(A14,INDIRECT("'[" &Info!$B$4&"]"&Info!$B$5&"'!$A$6:$Ai$1000"),35,0))) -> 7 | T14: =IF(N14="","",IF(N14=0,0, VLOOKUP(A14,INDIRECT("'[" &Info!$B$4&"]"&Info!$B$5&"'!$A$6:$Az$1000"),52,0))) -> 414 | U14: =IF(N14="","",IF(N14=0,0, VLOOKUP(A14,INDIRECT("'[" &Info!$B$4&"]"&Info!$B$5&"'!$A$6:$BA$1000"),53,0))) -> 0 | V14: =IF(N14="","",IF(N14=0,0, VLOOKUP(A14,INDIRECT("'[" &Info!$B$4&"]"&Info!$B$5&"'!$A$6:$BB$1000"),54,0))) -> 49 | W14: =IF(N15="","",O14+S14) -> 15 | X14: =IF(N15="","",P14+T14) -> 929 | Y14: =IF(N15="","",Q14+U14) -> 0 | Z14: =IF(N15="","",R14+V14) -> 168
A15: =IFERROR( VLOOKUP(A14+1,INDIRECT("'[" &Info!$B$4&"]"&Info!$B$5&"'!$A$6:$A$1000"),1,0),"") -> 11 | B15: =IFERROR( IF(A15="","", VLOOKUP(A15,INDIRECT("'[" &Info!$B$4&"]"&Info!$B$5&"'!$A$6:$B$1000"),2,0)),"") -> C11 | C15: =IFERROR( IF(A15="","", VLOOKUP(A15,INDIRECT("'[" &Info!$B$4&"]"&Info!$B$5&"'!$A$6:$D$1000"),3,0)),"") -> 31100 | D15: =IF(C15="","", VLOOKUP(A15,INDIRECT("'[" &Info!$B$4&"]"&Info!$B$5&"'!$A$6:$T$1000"),20,0)) -> A6063-T5 | E15: =IF(D15="","", VLOOKUP(A15,INDIRECT("'[" &Info!$B$4&"]"&Info!$B$5&"'!$A$6:$U$1000"),21,0)) -> GW | F15: =IF(D15="","", VLOOKUP(A15,INDIRECT("'[" &Info!$B$4&"]"&Info!$B$5&"'!$A$6:$U$1000"),21,0)) -> GW | G15: =IF(D15="","", VLOOKUP(A15,INDIRECT("'[" &Info!$B$4&"]"&Info!$B$5&"'!$A$6:$V$1000"),22,0)) -> 18.15 | H15: =IF(D15="","", VLOOKUP(A15,INDIRECT("'[" &Info!$B$4&"]"&Info!$B$5&"'!$A$6:$W$1000"),23,0)) -> 8.6 | I15: =LOWER( IF(D15="","", VLOOKUP(A15,INDIRECT("'[" &Info!$B$4&"]"&Info!$B$5&"'!$A$6:$y$1000"),25,0))) -> h9 | J15: =IF(D15="","", VLOOKUP(A15,INDIRECT("'[" &Info!$B$4&"]"&Info!$B$5&"'!$A$6:$Z$1000"),26,0)) -> 3 | K15: =IF(D15="","", VLOOKUP(A15,INDIRECT("'[" &Info!$B$4&"]"&Info!$B$5&"'!$A$6:$AA$1000"),27,0)) -> J17 | L15: =IF(D15="","", VLOOKUP(A15,INDIRECT("'[" &Info!$B$4&"]"&Info!$B$5&"'!$A$6:$H$1000"),8,0)) -> 7.7 | M15: =IF(D15="","", VLOOKUP(A15,INDIRECT("'[" &Info!$B$4&"]"&Info!$B$5&"'!$A$6:$F$1000"),6,0)) -> 91 | N15: =IF(C15="","", VLOOKUP(A15,INDIRECT("'[" &Info!$B$4&"]"&Info!$B$5&"'!$A$6:$Au$1000"),47,0)) -> 12 | O15: =IF(N15="","",IF(N15=0,0,VLOOKUP(A15,INDIRECT("'[" &Info!$B$4&"]"&Info!$B$5&"'!$A$6:$AH$1000"),34,0))) -> 7 | P15: =IF(N15="","",IF(N15=0,0,VLOOKUP(A15,INDIRECT("'[" &Info!$B$4&"]"&Info!$B$5&"'!$A$6:$AW$1000"),49,0))) -> 662 | Q15: =IF(N15="","",IF(N15=0,0, VLOOKUP(A15,INDIRECT("'[" &Info!$B$4&"]"&Info!$B$5&"'!$A$6:$AX$1000"),50,0))) -> 0 | R15: =IF(N15="","",IF(N15=0,0, VLOOKUP(A15,INDIRECT("'[" &Info!$B$4&"]"&Info!$B$5&"'!$A$6:$AY$1000"),51,0))) -> 0 | S15: =IF(N15="","",IF(N15=0,0,VLOOKUP(A15,INDIRECT("'[" &Info!$B$4&"]"&Info!$B$5&"'!$A$6:$Ai$1000"),35,0))) -> 6 | T15: =IF(N15="","",IF(N15=0,0, VLOOKUP(A15,INDIRECT("'[" &Info!$B$4&"]"&Info!$B$5&"'!$A$6:$Az$1000"),52,0))) -> 545 | U15: =IF(N15="","",IF(N15=0,0, VLOOKUP(A15,INDIRECT("'[" &Info!$B$4&"]"&Info!$B$5&"'!$A$6:$BA$1000"),53,0))) -> 0 | V15: =IF(N15="","",IF(N15=0,0, VLOOKUP(A15,INDIRECT("'[" &Info!$B$4&"]"&Info!$B$5&"'!$A$6:$BB$1000"),54,0))) -> 0 | W15: =IF(N16="","",O15+S15) -> 13 | X15: =IF(N16="","",P15+T15) -> 1207 | Y15: =IF(N16="","",Q15+U15) -> 0 | Z15: =IF(N16="","",R15+V15) -> 0
A16: =IFERROR( VLOOKUP(A15+1,INDIRECT("'[" &Info!$B$4&"]"&Info!$B$5&"'!$A$6:$A$1000"),1,0),"") -> 12 | B16: =IFERROR( IF(A16="","", VLOOKUP(A16,INDIRECT("'[" &Info!$B$4&"]"&Info!$B$5&"'!$A$6:$B$1000"),2,0)),"") -> C12 | C16: =IFERROR( IF(A16="","", VLOOKUP(A16,INDIRECT("'[" &Info!$B$4&"]"&Info!$B$5&"'!$A$6:$D$1000"),3,0)),"") -> 000003 | D16: =IF(C16="","", VLOOKUP(A16,INDIRECT("'[" &Info!$B$4&"]"&Info!$B$5&"'!$A$6:$T$1000"),20,0)) -> 12L14 | E16: =IF(D16="","", VLOOKUP(A16,INDIRECT("'[" &Info!$B$4&"]"&Info!$B$5&"'!$A$6:$U$1000"),21,0)) -> LT | F16: =IF(D16="","", VLOOKUP(A16,INDIRECT("'[" &Info!$B$4&"]"&Info!$B$5&"'!$A$6:$U$1000"),21,0)) -> LT | G16: =IF(D16="","", VLOOKUP(A16,INDIRECT("'[" &Info!$B$4&"]"&Info!$B$5&"'!$A$6:$V$1000"),22,0)) -> 12 | H16: =IF(D16="","", VLOOKUP(A16,INDIRECT("'[" &Info!$B$4&"]"&Info!$B$5&"'!$A$6:$W$1000"),23,0)) -> 0 | I16: =LOWER( IF(D16="","", VLOOKUP(A16,INDIRECT("'[" &Info!$B$4&"]"&Info!$B$5&"'!$A$6:$y$1000"),25,0))) -> h9 | J16: =IF(D16="","", VLOOKUP(A16,INDIRECT("'[" &Info!$B$4&"]"&Info!$B$5&"'!$A$6:$Z$1000"),26,0)) -> 3 | K16: =IF(D16="","", VLOOKUP(A16,INDIRECT("'[" &Info!$B$4&"]"&Info!$B$5&"'!$A$6:$AA$1000"),27,0)) -> B17 | L16: =IF(D16="","", VLOOKUP(A16,INDIRECT("'[" &Info!$B$4&"]"&Info!$B$5&"'!$A$6:$H$1000"),8,0)) -> 9.413 | M16: =IF(D16="","", VLOOKUP(A16,INDIRECT("'[" &Info!$B$4&"]"&Info!$B$5&"'!$A$6:$F$1000"),6,0)) -> 118 | N16: =IF(C16="","", VLOOKUP(A16,INDIRECT("'[" &Info!$B$4&"]"&Info!$B$5&"'!$A$6:$Au$1000"),47,0)) -> 12 | O16: =IF(N16="","",IF(N16=0,0,VLOOKUP(A16,INDIRECT("'[" &Info!$B$4&"]"&Info!$B$5&"'!$A$6:$AH$1000"),34,0))) -> 10 | P16: =IF(N16="","",IF(N16=0,0,VLOOKUP(A16,INDIRECT("'[" &Info!$B$4&"]"&Info!$B$5&"'!$A$6:$AW$1000"),49,0))) -> 1026 | Q16: =IF(N16="","",IF(N16=0,0, VLOOKUP(A16,INDIRECT("'[" &Info!$B$4&"]"&Info!$B$5&"'!$A$6:$AX$1000"),50,0))) -> 53 | R16: =IF(N16="","",IF(N16=0,0, VLOOKUP(A16,INDIRECT("'[" &Info!$B$4&"]"&Info!$B$5&"'!$A$6:$AY$1000"),51,0))) -> 0 | S16: =IF(N16="","",IF(N16=0,0,VLOOKUP(A16,INDIRECT("'[" &Info!$B$4&"]"&Info!$B$5&"'!$A$6:$Ai$1000"),35,0))) -> 8 | T16: =IF(N16="","",IF(N16=0,0, VLOOKUP(A16,INDIRECT("'[" &Info!$B$4&"]"&Info!$B$5&"'!$A$6:$Az$1000"),52,0))) -> 934 | U16: =IF(N16="","",IF(N16=0,0, VLOOKUP(A16,INDIRECT("'[" &Info!$B$4&"]"&Info!$B$5&"'!$A$6:$BA$1000"),53,0))) -> 0 | V16: =IF(N16="","",IF(N16=0,0, VLOOKUP(A16,INDIRECT("'[" &Info!$B$4&"]"&Info!$B$5&"'!$A$6:$BB$1000"),54,0))) -> 0 | W16: =IF(N17="","",O16+S16) -> 18 | X16: =IF(N17="","",P16+T16) -> 1960 | Y16: =IF(N17="","",Q16+U16) -> 53 | Z16: =IF(N17="","",R16+V16) -> 0
A17: =IFERROR( VLOOKUP(A16+1,INDIRECT("'[" &Info!$B$4&"]"&Info!$B$5&"'!$A$6:$A$1000"),1,0),"") -> 13 | B17: =IFERROR( IF(A17="","", VLOOKUP(A17,INDIRECT("'[" &Info!$B$4&"]"&Info!$B$5&"'!$A$6:$B$1000"),2,0)),"") -> C12B | C17: =IFERROR( IF(A17="","", VLOOKUP(A17,INDIRECT("'[" &Info!$B$4&"]"&Info!$B$5&"'!$A$6:$D$1000"),3,0)),"") -> SM02 | D17: =IF(C17="","", VLOOKUP(A17,INDIRECT("'[" &Info!$B$4&"]"&Info!$B$5&"'!$A$6:$T$1000"),20,0)) -> A6063-T5 | E17: =IF(D17="","", VLOOKUP(A17,INDIRECT("'[" &Info!$B$4&"]"&Info!$B$5&"'!$A$6:$U$1000"),21,0)) -> GW | F17: =IF(D17="","", VLOOKUP(A17,INDIRECT("'[" &Info!$B$4&"]"&Info!$B$5&"'!$A$6:$U$1000"),21,0)) -> GW | G17: =IF(D17="","", VLOOKUP(A17,INDIRECT("'[" &Info!$B$4&"]"&Info!$B$5&"'!$A$6:$V$1000"),22,0)) -> 15 | H17: =IF(D17="","", VLOOKUP(A17,INDIRECT("'[" &Info!$B$4&"]"&Info!$B$5&"'!$A$6:$W$1000"),23,0)) -> 8.6 | I17: =LOWER( IF(D17="","", VLOOKUP(A17,INDIRECT("'[" &Info!$B$4&"]"&Info!$B$5&"'!$A$6:$y$1000"),25,0))) -> h9 | J17: =IF(D17="","", VLOOKUP(A17,INDIRECT("'[" &Info!$B$4&"]"&Info!$B$5&"'!$A$6:$Z$1000"),26,0)) -> 3 | K17: =IF(D17="","", VLOOKUP(A17,INDIRECT("'[" &Info!$B$4&"]"&Info!$B$5&"'!$A$6:$AA$1000"),27,0)) -> F17 | L17: =IF(D17="","", VLOOKUP(A17,INDIRECT("'[" &Info!$B$4&"]"&Info!$B$5&"'!$A$6:$H$1000"),8,0)) -> 3.03 | M17: =IF(D17="","", VLOOKUP(A17,INDIRECT("'[" &Info!$B$4&"]"&Info!$B$5&"'!$A$6:$F$1000"),6,0)) -> 168 | N17: =IF(C17="","", VLOOKUP(A17,INDIRECT("'[" &Info!$B$4&"]"&Info!$B$5&"'!$A$6:$Au$1000"),47,0)) -> 12 | O17: =IF(N17="","",IF(N17=0,0,VLOOKUP(A17,INDIRECT("'[" &Info!$B$4&"]"&Info!$B$5&"'!$A$6:$AH$1000"),34,0))) -> 14 | P17: =IF(N17="","",IF(N17=0,0,VLOOKUP(A17,INDIRECT("'[" &Info!$B$4&"]"&Info!$B$5&"'!$A$6:$AW$1000"),49,0))) -> 2112 | Q17: =IF(N17="","",IF(N17=0,0, VLOOKUP(A17,INDIRECT("'[" &Info!$B$4&"]"&Info!$B$5&"'!$A$6:$AX$1000"),50,0))) -> 0 | R17: =IF(N17="","",IF(N17=0,0, VLOOKUP(A17,INDIRECT("'[" &Info!$B$4&"]"&Info!$B$5&"'!$A$6:$AY$1000"),51,0))) -> 0 | S17: =IF(N17="","",IF(N17=0,0,VLOOKUP(A17,INDIRECT("'[" &Info!$B$4&"]"&Info!$B$5&"'!$A$6:$Ai$1000"),35,0))) -> 14 | T17: =IF(N17="","",IF(N17=0,0, VLOOKUP(A17,INDIRECT("'[" &Info!$B$4&"]"&Info!$B$5&"'!$A$6:$Az$1000"),52,0))) -> 2244 | U17: =IF(N17="","",IF(N17=0,0, VLOOKUP(A17,INDIRECT("'[" &Info!$B$4&"]"&Info!$B$5&"'!$A$6:$BA$1000"),53,0))) -> 0 | V17: =IF(N17="","",IF(N17=0,0, VLOOKUP(A17,INDIRECT("'[" &Info!$B$4&"]"&Info!$B$5&"'!$A$6:$BB$1000"),54,0))) -> 0 | W17: =IF(N18="","",O17+S17) -> 28 | X17: =IF(N18="","",P17+T17) -> 4356 | Y17: =IF(N18="","",Q17+U17) -> 0 | Z17: =IF(N18="","",R17+V17) -> 0
... A186: =IFERROR( VLOOKUP(A185+1,INDIRECT("'[" &Info!$B$4&"]"&Info!$B$5&"'!$A$6:$A$1000"),1,0),"") | B186: =IFERROR( IF(A186="","", VLOOKUP(A186,INDIRECT("'[" &Info!$B$4&"]"&Info!$B$5&"'!$A$6:$B$1000"),2,0)),"") | C186: =IFERROR( IF(A186="","", VLOOKUP(A186,INDIRECT("'[" &Info!$B$4&"]"&Info!$B$5&"'!$A$6:$D$1000"),3,0)),"") | D186: =IF(C186="","", VLOOKUP(A186,INDIRECT("'[" &Info!$B$4&"]"&Info!$B$5&"'!$A$6:$T$1000"),20,0)) | E186: =IF(D186="","", VLOOKUP(A186,INDIRECT("'[" &Info!$B$4&"]"&Info!$B$5&"'!$A$6:$U$1000"),21,0)) | F186: =IF(D186="","", VLOOKUP(A186,INDIRECT("'[" &Info!$B$4&"]"&Info!$B$5&"'!$A$6:$U$1000"),21,0)) | G186: =IF(D186="","", VLOOKUP(A186,INDIRECT("'[" &Info!$B$4&"]"&Info!$B$5&"'!$A$6:$V$1000"),22,0)) | H186: =IF(D186="","", VLOOKUP(A186,INDIRECT("'[" &Info!$B$4&"]"&Info!$B$5&"'!$A$6:$W$1000"),23,0)) | I186: =LOWER( IF(D186="","", VLOOKUP(A186,INDIRECT("'[" &Info!$B$4&"]"&Info!$B$5&"'!$A$6:$y$1000"),25,0))) | J186: =IF(D186="","", VLOOKUP(A186,INDIRECT("'[" &Info!$B$4&"]"&Info!$B$5&"'!$A$6:$Z$1000"),26,0)) | K186: =IF(D186="","", VLOOKUP(A186,INDIRECT("'[" &Info!$B$4&"]"&Info!$B$5&"'!$A$6:$AA$1000"),27,0)) | L186: =IF(D186="","", VLOOKUP(A186,INDIRECT("'[" &Info!$B$4&"]"&Info!$B$5&"'!$A$6:$H$1000"),8,0)) | M186: =IF(D186="","", VLOOKUP(A186,INDIRECT("'[" &Info!$B$4&"]"&Info!$B$5&"'!$A$6:$F$1000"),6,0)) | N186: =IF(C186="","", VLOOKUP(A186,INDIRECT("'[" &Info!$B$4&"]"&Info!$B$5&"'!$A$6:$Au$1000"),47,0)) | O186: =IF(N186="","",IF(N186=0,0,VLOOKUP(A186,INDIRECT("'[" &Info!$B$4&"]"&Info!$B$5&"'!$A$6:$AH$1000"),34,0))) | P186: =IF(N186="","",IF(N186=0,0,VLOOKUP(A186,INDIRECT("'[" &Info!$B$4&"]"&Info!$B$5&"'!$A$6:$AW$1000"),49,0))) | Q186: =IF(N186="","",IF(N186=0,0, VLOOKUP(A186,INDIRECT("'[" &Info!$B$4&"]"&Info!$B$5&"'!$A$6:$AX$1000"),50,0))) | R186: =IF(N186="","",IF(N186=0,0, VLOOKUP(A186,INDIRECT("'[" &Info!$B$4&"]"&Info!$B$5&"'!$A$6:$AY$1000"),51,0))) | S186: =IF(N186="","",IF(N186=0,0,VLOOKUP(A186,INDIRECT("'[" &Info!$B$4&"]"&Info!$B$5&"'!$A$6:$Ai$1000"),35,0))) | T186: =IF(N186="","",IF(N186=0,0, VLOOKUP(A186,INDIRECT("'[" &Info!$B$4&"]"&Info!$B$5&"'!$A$6:$Az$1000"),52,0))) | U186: =IF(N186="","",IF(N186=0,0, VLOOKUP(A186,INDIRECT("'[" &Info!$B$4&"]"&Info!$B$5&"'!$A$6:$BA$1000"),53,0))) | V186: =IF(N186="","",IF(N186=0,0, VLOOKUP(A186,INDIRECT("'[" &Info!$B$4&"]"&Info!$B$5&"'!$A$6:$BB$1000"),54,0))) | W186: =IF(N187="","",O186+S186) | X186: =IF(N187="","",P186+T186) | Y186: =IF(N187="","",Q186+U186) | Z186: =IF(N187="","",R186+V186)
A187: =IFERROR( VLOOKUP(A186+1,INDIRECT("'[" &Info!$B$4&"]"&Info!$B$5&"'!$A$6:$A$1000"),1,0),"") | C187: =IFERROR( IF(A187="","", VLOOKUP(A187,INDIRECT("'[" &Info!$B$4&"]"&Info!$B$5&"'!$A$6:$D$1000"),3,0)),"") | D187: =IF(C187="","", VLOOKUP(A187,INDIRECT("'[" &Info!$B$4&"]"&Info!$B$5&"'!$A$6:$T$1000"),20,0)) | E187: =IF(D187="","", VLOOKUP(A187,INDIRECT("'[" &Info!$B$4&"]"&Info!$B$5&"'!$A$6:$U$1000"),21,0)) | F187: =IF(D187="","", VLOOKUP(A187,INDIRECT("'[" &Info!$B$4&"]"&Info!$B$5&"'!$A$6:$U$1000"),21,0)) | G187: =IF(D187="","", VLOOKUP(A187,INDIRECT("'[" &Info!$B$4&"]"&Info!$B$5&"'!$A$6:$V$1000"),22,0)) | H187: =IF(D187="","", VLOOKUP(A187,INDIRECT("'[" &Info!$B$4&"]"&Info!$B$5&"'!$A$6:$W$1000"),23,0)) | I187: =LOWER( IF(D187="","", VLOOKUP(A187,INDIRECT("'[" &Info!$B$4&"]"&Info!$B$5&"'!$A$6:$y$1000"),25,0))) | J187: =IF(D187="","", VLOOKUP(A187,INDIRECT("'[" &Info!$B$4&"]"&Info!$B$5&"'!$A$6:$Z$1000"),26,0)) | K187: =IF(D187="","", VLOOKUP(A187,INDIRECT("'[" &Info!$B$4&"]"&Info!$B$5&"'!$A$6:$AA$1000"),27,0)) | L187: =IF(D187="","", VLOOKUP(A187,INDIRECT("'[" &Info!$B$4&"]"&Info!$B$5&"'!$A$6:$H$1000"),8,0)) | M187: =IF(D187="","", VLOOKUP(A187,INDIRECT("'[" &Info!$B$4&"]"&Info!$B$5&"'!$A$6:$F$1000"),6,0)) | N187: =IF(C187="","", VLOOKUP(A187,INDIRECT("'[" &Info!$B$4&"]"&Info!$B$5&"'!$A$6:$Au$1000"),47,0)) | O187: =IF(N187="","",IF(N187=0,0,VLOOKUP(A187,INDIRECT("'[" &Info!$B$4&"]"&Info!$B$5&"'!$A$6:$AH$1000"),34,0))) | P187: =IF(N187="","",IF(N187=0,0,VLOOKUP(A187,INDIRECT("'[" &Info!$B$4&"]"&Info!$B$5&"'!$A$6:$AW$1000"),49,0))) | Q187: =IF(N187="","",IF(N187=0,0, VLOOKUP(A187,INDIRECT("'[" &Info!$B$4&"]"&Info!$B$5&"'!$A$6:$AX$1000"),50,0))) | R187: =IF(N187="","",IF(N187=0,0, VLOOKUP(A187,INDIRECT("'[" &Info!$B$4&"]"&Info!$B$5&"'!$A$6:$AY$1000"),51,0))) | S187: =IF(N187="","",IF(N187=0,0,VLOOKUP(A187,INDIRECT("'[" &Info!$B$4&"]"&Info!$B$5&"'!$A$6:$Ai$1000"),35,0))) | T187: =IF(N187="","",IF(N187=0,0, VLOOKUP(A187,INDIRECT("'[" &Info!$B$4&"]"&Info!$B$5&"'!$A$6:$Az$1000"),52,0))) | U187: =IF(N187="","",IF(N187=0,0, VLOOKUP(A187,INDIRECT("'[" &Info!$B$4&"]"&Info!$B$5&"'!$A$6:$BA$1000"),53,0))) | V187: =IF(N187="","",IF(N187=0,0, VLOOKUP(A187,INDIRECT("'[" &Info!$B$4&"]"&Info!$B$5&"'!$A$6:$BB$1000"),54,0))) | W187: =IF(N187="","",O187+S187) | X187: =IF(N187="","",P187+T187) | Y187: =IF(N187="","",Q187+U187) | Z187: =IF(N187="","",R187+V187)
A188: =IFERROR( VLOOKUP(A187+1,INDIRECT("'[" &Info!$B$4&"]"&Info!$B$5&"'!$A$6:$A$1000"),1,0),"") | C188: =IFERROR( IF(A188="","", VLOOKUP(A188,INDIRECT("'[" &Info!$B$4&"]"&Info!$B$5&"'!$A$6:$D$1000"),3,0)),"") | D188: =IF(C188="","", VLOOKUP(A188,INDIRECT("'[" &Info!$B$4&"]"&Info!$B$5&"'!$A$6:$T$1000"),20,0)) | E188: =IF(D188="","", VLOOKUP(A188,INDIRECT("'[" &Info!$B$4&"]"&Info!$B$5&"'!$A$6:$U$1000"),21,0)) | F188: =IF(D188="","", VLOOKUP(A188,INDIRECT("'[" &Info!$B$4&"]"&Info!$B$5&"'!$A$6:$U$1000"),21,0)) | G188: =IF(D188="","", VLOOKUP(A188,INDIRECT("'[" &Info!$B$4&"]"&Info!$B$5&"'!$A$6:$V$1000"),22,0)) | H188: =IF(D188="","", VLOOKUP(A188,INDIRECT("'[" &Info!$B$4&"]"&Info!$B$5&"'!$A$6:$W$1000"),23,0)) | I188: =LOWER( IF(D188="","", VLOOKUP(A188,INDIRECT("'[" &Info!$B$4&"]"&Info!$B$5&"'!$A$6:$y$1000"),25,0))) | J188: =IF(D188="","", VLOOKUP(A188,INDIRECT("'[" &Info!$B$4&"]"&Info!$B$5&"'!$A$6:$Z$1000"),26,0)) | K188: =IF(D188="","", VLOOKUP(A188,INDIRECT("'[" &Info!$B$4&"]"&Info!$B$5&"'!$A$6:$AA$1000"),27,0)) | L188: =IF(D188="","", VLOOKUP(A188,INDIRECT("'[" &Info!$B$4&"]"&Info!$B$5&"'!$A$6:$H$1000"),8,0)) | M188: =IF(D188="","", VLOOKUP(A188,INDIRECT("'[" &Info!$B$4&"]"&Info!$B$5&"'!$A$6:$F$1000"),6,0)) | N188: =IF(C188="","", VLOOKUP(A188,INDIRECT("'[" &Info!$B$4&"]"&Info!$B$5&"'!$A$6:$Au$1000"),47,0)) | O188: =IF(N188="","",IF(N188=0,0,VLOOKUP(A188,INDIRECT("'[" &Info!$B$4&"]"&Info!$B$5&"'!$A$6:$AH$1000"),34,0))) | P188: =IF(N188="","",IF(N188=0,0,VLOOKUP(A188,INDIRECT("'[" &Info!$B$4&"]"&Info!$B$5&"'!$A$6:$AW$1000"),49,0))) | Q188: =IF(N188="","",IF(N188=0,0, VLOOKUP(A188,INDIRECT("'[" &Info!$B$4&"]"&Info!$B$5&"'!$A$6:$AX$1000"),50,0))) | R188: =IF(N188="","",IF(N188=0,0, VLOOKUP(A188,INDIRECT("'[" &Info!$B$4&"]"&Info!$B$5&"'!$A$6:$AY$1000"),51,0))) | S188: =IF(N188="","",IF(N188=0,0,VLOOKUP(A188,INDIRECT("'[" &Info!$B$4&"]"&Info!$B$5&"'!$A$6:$Ai$1000"),35,0))) | T188: =IF(N188="","",IF(N188=0,0, VLOOKUP(A188,INDIRECT("'[" &Info!$B$4&"]"&Info!$B$5&"'!$A$6:$Az$1000"),52,0))) | U188: =IF(N188="","",IF(N188=0,0, VLOOKUP(A188,INDIRECT("'[" &Info!$B$4&"]"&Info!$B$5&"'!$A$6:$BA$1000"),53,0))) | V188: =IF(N188="","",IF(N188=0,0, VLOOKUP(A188,INDIRECT("'[" &Info!$B$4&"]"&Info!$B$5&"'!$A$6:$BB$1000"),54,0))) | W188: =IF(N188="","",O188+S188) | X188: =IF(N188="","",P188+T188) | Y188: =IF(N188="","",Q188+U188) | Z188: =IF(N188="","",R188+V188)
A189: =IFERROR( VLOOKUP(A188+1,INDIRECT("'[" &Info!$B$4&"]"&Info!$B$5&"'!$A$6:$A$1000"),1,0),"") | C189: =IFERROR( IF(A189="","", VLOOKUP(A189,INDIRECT("'[" &Info!$B$4&"]"&Info!$B$5&"'!$A$6:$D$1000"),3,0)),"") | D189: =IF(C189="","", VLOOKUP(A189,INDIRECT("'[" &Info!$B$4&"]"&Info!$B$5&"'!$A$6:$T$1000"),20,0)) | E189: =IF(D189="","", VLOOKUP(A189,INDIRECT("'[" &Info!$B$4&"]"&Info!$B$5&"'!$A$6:$U$1000"),21,0)) | F189: =IF(D189="","", VLOOKUP(A189,INDIRECT("'[" &Info!$B$4&"]"&Info!$B$5&"'!$A$6:$U$1000"),21,0)) | G189: =IF(D189="","", VLOOKUP(A189,INDIRECT("'[" &Info!$B$4&"]"&Info!$B$5&"'!$A$6:$V$1000"),22,0)) | H189: =IF(D189="","", VLOOKUP(A189,INDIRECT("'[" &Info!$B$4&"]"&Info!$B$5&"'!$A$6:$W$1000"),23,0)) | I189: =LOWER( IF(D189="","", VLOOKUP(A189,INDIRECT("'[" &Info!$B$4&"]"&Info!$B$5&"'!$A$6:$y$1000"),25,0))) | J189: =IF(D189="","", VLOOKUP(A189,INDIRECT("'[" &Info!$B$4&"]"&Info!$B$5&"'!$A$6:$Z$1000"),26,0)) | K189: =IF(D189="","", VLOOKUP(A189,INDIRECT("'[" &Info!$B$4&"]"&Info!$B$5&"'!$A$6:$AA$1000"),27,0)) | L189: =IF(D189="","", VLOOKUP(A189,INDIRECT("'[" &Info!$B$4&"]"&Info!$B$5&"'!$A$6:$H$1000"),8,0)) | M189: =IF(D189="","", VLOOKUP(A189,INDIRECT("'[" &Info!$B$4&"]"&Info!$B$5&"'!$A$6:$F$1000"),6,0)) | N189: =IF(C189="","", VLOOKUP(A189,INDIRECT("'[" &Info!$B$4&"]"&Info!$B$5&"'!$A$6:$Au$1000"),47,0)) | O189: =IF(N189="","",IF(N189=0,0,VLOOKUP(A189,INDIRECT("'[" &Info!$B$4&"]"&Info!$B$5&"'!$A$6:$AH$1000"),34,0))) | P189: =IF(N189="","",IF(N189=0,0,VLOOKUP(A189,INDIRECT("'[" &Info!$B$4&"]"&Info!$B$5&"'!$A$6:$AW$1000"),49,0))) | Q189: =IF(N189="","",IF(N189=0,0, VLOOKUP(A189,INDIRECT("'[" &Info!$B$4&"]"&Info!$B$5&"'!$A$6:$AX$1000"),50,0))) | R189: =IF(N189="","",IF(N189=0,0, VLOOKUP(A189,INDIRECT("'[" &Info!$B$4&"]"&Info!$B$5&"'!$A$6:$AY$1000"),51,0))) | S189: =IF(N189="","",IF(N189=0,0,VLOOKUP(A189,INDIRECT("'[" &Info!$B$4&"]"&Info!$B$5&"'!$A$6:$Ai$1000"),35,0))) | T189: =IF(N189="","",IF(N189=0,0, VLOOKUP(A189,INDIRECT("'[" &Info!$B$4&"]"&Info!$B$5&"'!$A$6:$Az$1000"),52,0))) | U189: =IF(N189="","",IF(N189=0,0, VLOOKUP(A189,INDIRECT("'[" &Info!$B$4&"]"&Info!$B$5&"'!$A$6:$BA$1000"),53,0))) | V189: =IF(N189="","",IF(N189=0,0, VLOOKUP(A189,INDIRECT("'[" &Info!$B$4&"]"&Info!$B$5&"'!$A$6:$BB$1000"),54,0))) | W189: =IF(N189="","",O189+S189) | X189: =IF(N189="","",P189+T189) | Y189: =IF(N189="","",Q189+U189) | Z189: =IF(N189="","",R189+V189)
A190: =IFERROR( VLOOKUP(A189+1,INDIRECT("'[" &Info!$B$4&"]"&Info!$B$5&"'!$A$6:$A$1000"),1,0),"") | C190: =IFERROR( IF(A190="","", VLOOKUP(A190,INDIRECT("'[" &Info!$B$4&"]"&Info!$B$5&"'!$A$6:$D$1000"),3,0)),"") | D190: =IF(C190="","", VLOOKUP(A190,INDIRECT("'[" &Info!$B$4&"]"&Info!$B$5&"'!$A$6:$T$1000"),20,0)) | E190: =IF(D190="","", VLOOKUP(A190,INDIRECT("'[" &Info!$B$4&"]"&Info!$B$5&"'!$A$6:$U$1000"),21,0)) | F190: =IF(D190="","", VLOOKUP(A190,INDIRECT("'[" &Info!$B$4&"]"&Info!$B$5&"'!$A$6:$U$1000"),21,0)) | G190: =IF(D190="","", VLOOKUP(A190,INDIRECT("'[" &Info!$B$4&"]"&Info!$B$5&"'!$A$6:$V$1000"),22,0)) | H190: =IF(D190="","", VLOOKUP(A190,INDIRECT("'[" &Info!$B$4&"]"&Info!$B$5&"'!$A$6:$W$1000"),23,0)) | I190: =LOWER( IF(D190="","", VLOOKUP(A190,INDIRECT("'[" &Info!$B$4&"]"&Info!$B$5&"'!$A$6:$y$1000"),25,0))) | J190: =IF(D190="","", VLOOKUP(A190,INDIRECT("'[" &Info!$B$4&"]"&Info!$B$5&"'!$A$6:$Z$1000"),26,0)) | K190: =IF(D190="","", VLOOKUP(A190,INDIRECT("'[" &Info!$B$4&"]"&Info!$B$5&"'!$A$6:$AA$1000"),27,0)) | L190: =IF(D190="","", VLOOKUP(A190,INDIRECT("'[" &Info!$B$4&"]"&Info!$B$5&"'!$A$6:$H$1000"),8,0)) | M190: =IF(D190="","", VLOOKUP(A190,INDIRECT("'[" &Info!$B$4&"]"&Info!$B$5&"'!$A$6:$F$1000"),6,0)) | N190: =IF(C190="","", VLOOKUP(A190,INDIRECT("'[" &Info!$B$4&"]"&Info!$B$5&"'!$A$6:$Au$1000"),47,0)) | O190: =IF(N190="","",IF(N190=0,0,VLOOKUP(A190,INDIRECT("'[" &Info!$B$4&"]"&Info!$B$5&"'!$A$6:$AH$1000"),34,0))) | P190: =IF(N190="","",IF(N190=0,0,VLOOKUP(A190,INDIRECT("'[" &Info!$B$4&"]"&Info!$B$5&"'!$A$6:$AW$1000"),49,0))) | Q190: =IF(N190="","",IF(N190=0,0, VLOOKUP(A190,INDIRECT("'[" &Info!$B$4&"]"&Info!$B$5&"'!$A$6:$AX$1000"),50,0))) | R190: =IF(N190="","",IF(N190=0,0, VLOOKUP(A190,INDIRECT("'[" &Info!$B$4&"]"&Info!$B$5&"'!$A$6:$AY$1000"),51,0))) | S190: =IF(N190="","",IF(N190=0,0,VLOOKUP(A190,INDIRECT("'[" &Info!$B$4&"]"&Info!$B$5&"'!$A$6:$Ai$1000"),35,0))) | T190: =IF(N190="","",IF(N190=0,0, VLOOKUP(A190,INDIRECT("'[" &Info!$B$4&"]"&Info!$B$5&"'!$A$6:$Az$1000"),52,0))) | U190: =IF(N190="","",IF(N190=0,0, VLOOKUP(A190,INDIRECT("'[" &Info!$B$4&"]"&Info!$B$5&"'!$A$6:$BA$1000"),53,0))) | V190: =IF(N190="","",IF(N190=0,0, VLOOKUP(A190,INDIRECT("'[" &Info!$B$4&"]"&Info!$B$5&"'!$A$6:$BB$1000"),54,0))) | W190: =IF(N190="","",O190+S190) | X190: =IF(N190="","",P190+T190) | Y190: =IF(N190="","",Q190+U190) | Z190: =IF(N190="","",R190+V190)
A191: =IFERROR( VLOOKUP(A190+1,INDIRECT("'[" &Info!$B$4&"]"&Info!$B$5&"'!$A$6:$A$1000"),1,0),"") | C191: =IFERROR( IF(A191="","", VLOOKUP(A191,INDIRECT("'[" &Info!$B$4&"]"&Info!$B$5&"'!$A$6:$D$1000"),3,0)),"") | D191: =IF(C191="","", VLOOKUP(A191,INDIRECT("'[" &Info!$B$4&"]"&Info!$B$5&"'!$A$6:$T$1000"),20,0)) | E191: =IF(D191="","", VLOOKUP(A191,INDIRECT("'[" &Info!$B$4&"]"&Info!$B$5&"'!$A$6:$U$1000"),21,0)) | F191: =IF(D191="","", VLOOKUP(A191,INDIRECT("'[" &Info!$B$4&"]"&Info!$B$5&"'!$A$6:$U$1000"),21,0)) | G191: =IF(D191="","", VLOOKUP(A191,INDIRECT("'[" &Info!$B$4&"]"&Info!$B$5&"'!$A$6:$V$1000"),22,0)) | H191: =IF(D191="","", VLOOKUP(A191,INDIRECT("'[" &Info!$B$4&"]"&Info!$B$5&"'!$A$6:$W$1000"),23,0)) | I191: =LOWER( IF(D191="","", VLOOKUP(A191,INDIRECT("'[" &Info!$B$4&"]"&Info!$B$5&"'!$A$6:$y$1000"),25,0))) | J191: =IF(D191="","", VLOOKUP(A191,INDIRECT("'[" &Info!$B$4&"]"&Info!$B$5&"'!$A$6:$Z$1000"),26,0)) | K191: =IF(D191="","", VLOOKUP(A191,INDIRECT("'[" &Info!$B$4&"]"&Info!$B$5&"'!$A$6:$AA$1000"),27,0)) | L191: =IF(D191="","", VLOOKUP(A191,INDIRECT("'[" &Info!$B$4&"]"&Info!$B$5&"'!$A$6:$H$1000"),8,0)) | M191: =IF(D191="","", VLOOKUP(A191,INDIRECT("'[" &Info!$B$4&"]"&Info!$B$5&"'!$A$6:$F$1000"),6,0)) | N191: =IF(C191="","", VLOOKUP(A191,INDIRECT("'[" &Info!$B$4&"]"&Info!$B$5&"'!$A$6:$Au$1000"),47,0)) | O191: =IF(N191="","",IF(N191=0,0,VLOOKUP(A191,INDIRECT("'[" &Info!$B$4&"]"&Info!$B$5&"'!$A$6:$AH$1000"),34,0))) | P191: =IF(N191="","",IF(N191=0,0,VLOOKUP(A191,INDIRECT("'[" &Info!$B$4&"]"&Info!$B$5&"'!$A$6:$AW$1000"),49,0))) | Q191: =IF(N191="","",IF(N191=0,0, VLOOKUP(A191,INDIRECT("'[" &Info!$B$4&"]"&Info!$B$5&"'!$A$6:$AX$1000"),50,0))) | R191: =IF(N191="","",IF(N191=0,0, VLOOKUP(A191,INDIRECT("'[" &Info!$B$4&"]"&Info!$B$5&"'!$A$6:$AY$1000"),51,0))) | S191: =IF(N191="","",IF(N191=0,0,VLOOKUP(A191,INDIRECT("'[" &Info!$B$4&"]"&Info!$B$5&"'!$A$6:$Ai$1000"),35,0))) | T191: =IF(N191="","",IF(N191=0,0, VLOOKUP(A191,INDIRECT("'[" &Info!$B$4&"]"&Info!$B$5&"'!$A$6:$Az$1000"),52,0))) | U191: =IF(N191="","",IF(N191=0,0, VLOOKUP(A191,INDIRECT("'[" &Info!$B$4&"]"&Info!$B$5&"'!$A$6:$BA$1000"),53,0))) | V191: =IF(N191="","",IF(N191=0,0, VLOOKUP(A191,INDIRECT("'[" &Info!$B$4&"]"&Info!$B$5&"'!$A$6:$BB$1000"),54,0))) | W191: =IF(N191="","",O191+S191) | X191: =IF(N191="","",P191+T191) | Y191: =IF(N191="","",Q191+U191) | Z191: =IF(N191="","",R191+V191)
A192: =IFERROR( VLOOKUP(A191+1,INDIRECT("'[" &Info!$B$4&"]"&Info!$B$5&"'!$A$6:$A$1000"),1,0),"") | C192: =IFERROR( IF(A192="","", VLOOKUP(A192,INDIRECT("'[" &Info!$B$4&"]"&Info!$B$5&"'!$A$6:$D$1000"),3,0)),"") | D192: =IF(C192="","", VLOOKUP(A192,INDIRECT("'[" &Info!$B$4&"]"&Info!$B$5&"'!$A$6:$T$1000"),20,0)) | E192: =IF(D192="","", VLOOKUP(A192,INDIRECT("'[" &Info!$B$4&"]"&Info!$B$5&"'!$A$6:$U$1000"),21,0)) | F192: =IF(D192="","", VLOOKUP(A192,INDIRECT("'[" &Info!$B$4&"]"&Info!$B$5&"'!$A$6:$U$1000"),21,0)) | G192: =IF(D192="","", VLOOKUP(A192,INDIRECT("'[" &Info!$B$4&"]"&Info!$B$5&"'!$A$6:$V$1000"),22,0)) | H192: =IF(D192="","", VLOOKUP(A192,INDIRECT("'[" &Info!$B$4&"]"&Info!$B$5&"'!$A$6:$W$1000"),23,0)) | I192: =LOWER( IF(D192="","", VLOOKUP(A192,INDIRECT("'[" &Info!$B$4&"]"&Info!$B$5&"'!$A$6:$y$1000"),25,0))) | J192: =IF(D192="","", VLOOKUP(A192,INDIRECT("'[" &Info!$B$4&"]"&Info!$B$5&"'!$A$6:$Z$1000"),26,0)) | K192: =IF(D192="","", VLOOKUP(A192,INDIRECT("'[" &Info!$B$4&"]"&Info!$B$5&"'!$A$6:$AA$1000"),27,0)) | L192: =IF(D192="","", VLOOKUP(A192,INDIRECT("'[" &Info!$B$4&"]"&Info!$B$5&"'!$A$6:$H$1000"),8,0)) | M192: =IF(D192="","", VLOOKUP(A192,INDIRECT("'[" &Info!$B$4&"]"&Info!$B$5&"'!$A$6:$F$1000"),6,0)) | N192: =IF(C192="","", VLOOKUP(A192,INDIRECT("'[" &Info!$B$4&"]"&Info!$B$5&"'!$A$6:$Au$1000"),47,0)) | O192: =IF(N192="","",IF(N192=0,0,VLOOKUP(A192,INDIRECT("'[" &Info!$B$4&"]"&Info!$B$5&"'!$A$6:$AH$1000"),34,0))) | P192: =IF(N192="","",IF(N192=0,0,VLOOKUP(A192,INDIRECT("'[" &Info!$B$4&"]"&Info!$B$5&"'!$A$6:$AW$1000"),49,0))) | Q192: =IF(N192="","",IF(N192=0,0, VLOOKUP(A192,INDIRECT("'[" &Info!$B$4&"]"&Info!$B$5&"'!$A$6:$AX$1000"),50,0))) | R192: =IF(N192="","",IF(N192=0,0, VLOOKUP(A192,INDIRECT("'[" &Info!$B$4&"]"&Info!$B$5&"'!$A$6:$AY$1000"),51,0))) | S192: =IF(N192="","",IF(N192=0,0,VLOOKUP(A192,INDIRECT("'[" &Info!$B$4&"]"&Info!$B$5&"'!$A$6:$Ai$1000"),35,0))) | T192: =IF(N192="","",IF(N192=0,0, VLOOKUP(A192,INDIRECT("'[" &Info!$B$4&"]"&Info!$B$5&"'!$A$6:$Az$1000"),52,0))) | U192: =IF(N192="","",IF(N192=0,0, VLOOKUP(A192,INDIRECT("'[" &Info!$B$4&"]"&Info!$B$5&"'!$A$6:$BA$1000"),53,0))) | V192: =IF(N192="","",IF(N192=0,0, VLOOKUP(A192,INDIRECT("'[" &Info!$B$4&"]"&Info!$B$5&"'!$A$6:$BB$1000"),54,0))) | W192: =IF(N192="","",O192+S192) | X192: =IF(N192="","",P192+T192) | Y192: =IF(N192="","",Q192+U192) | Z192: =IF(N192="","",R192+V192)
A193: =IFERROR( VLOOKUP(A192+1,INDIRECT("'[" &Info!$B$4&"]"&Info!$B$5&"'!$A$6:$A$1000"),1,0),"") | C193: =IFERROR( IF(A193="","", VLOOKUP(A193,INDIRECT("'[" &Info!$B$4&"]"&Info!$B$5&"'!$A$6:$D$1000"),3,0)),"") | D193: =IF(C193="","", VLOOKUP(A193,INDIRECT("'[" &Info!$B$4&"]"&Info!$B$5&"'!$A$6:$T$1000"),20,0)) | E193: =IF(D193="","", VLOOKUP(A193,INDIRECT("'[" &Info!$B$4&"]"&Info!$B$5&"'!$A$6:$U$1000"),21,0)) | F193: =IF(D193="","", VLOOKUP(A193,INDIRECT("'[" &Info!$B$4&"]"&Info!$B$5&"'!$A$6:$U$1000"),21,0)) | G193: =IF(D193="","", VLOOKUP(A193,INDIRECT("'[" &Info!$B$4&"]"&Info!$B$5&"'!$A$6:$V$1000"),22,0)) | H193: =IF(D193="","", VLOOKUP(A193,INDIRECT("'[" &Info!$B$4&"]"&Info!$B$5&"'!$A$6:$W$1000"),23,0)) | I193: =LOWER( IF(D193="","", VLOOKUP(A193,INDIRECT("'[" &Info!$B$4&"]"&Info!$B$5&"'!$A$6:$y$1000"),25,0))) | J193: =IF(D193="","", VLOOKUP(A193,INDIRECT("'[" &Info!$B$4&"]"&Info!$B$5&"'!$A$6:$Z$1000"),26,0)) | K193: =IF(D193="","", VLOOKUP(A193,INDIRECT("'[" &Info!$B$4&"]"&Info!$B$5&"'!$A$6:$AA$1000"),27,0)) | L193: =IF(D193="","", VLOOKUP(A193,INDIRECT("'[" &Info!$B$4&"]"&Info!$B$5&"'!$A$6:$H$1000"),8,0)) | M193: =IF(D193="","", VLOOKUP(A193,INDIRECT("'[" &Info!$B$4&"]"&Info!$B$5&"'!$A$6:$F$1000"),6,0)) | N193: =IF(C193="","", VLOOKUP(A193,INDIRECT("'[" &Info!$B$4&"]"&Info!$B$5&"'!$A$6:$Au$1000"),47,0)) | O193: =IF(N193="","",IF(N193=0,0,VLOOKUP(A193,INDIRECT("'[" &Info!$B$4&"]"&Info!$B$5&"'!$A$6:$AH$1000"),34,0))) | P193: =IF(N193="","",IF(N193=0,0,VLOOKUP(A193,INDIRECT("'[" &Info!$B$4&"]"&Info!$B$5&"'!$A$6:$AW$1000"),49,0))) | Q193: =IF(N193="","",IF(N193=0,0, VLOOKUP(A193,INDIRECT("'[" &Info!$B$4&"]"&Info!$B$5&"'!$A$6:$AX$1000"),50,0))) | R193: =IF(N193="","",IF(N193=0,0, VLOOKUP(A193,INDIRECT("'[" &Info!$B$4&"]"&Info!$B$5&"'!$A$6:$AY$1000"),51,0))) | S193: =IF(N193="","",IF(N193=0,0,VLOOKUP(A193,INDIRECT("'[" &Info!$B$4&"]"&Info!$B$5&"'!$A$6:$Ai$1000"),35,0))) | T193: =IF(N193="","",IF(N193=0,0, VLOOKUP(A193,INDIRECT("'[" &Info!$B$4&"]"&Info!$B$5&"'!$A$6:$Az$1000"),52,0))) | U193: =IF(N193="","",IF(N193=0,0, VLOOKUP(A193,INDIRECT("'[" &Info!$B$4&"]"&Info!$B$5&"'!$A$6:$BA$1000"),53,0))) | V193: =IF(N193="","",IF(N193=0,0, VLOOKUP(A193,INDIRECT("'[" &Info!$B$4&"]"&Info!$B$5&"'!$A$6:$BB$1000"),54,0))) | W193: =IF(N193="","",O193+S193) | X193: =IF(N193="","",P193+T193) | Y193: =IF(N193="","",Q193+U193) | Z193: =IF(N193="","",R193+V193)
A194: =IFERROR( VLOOKUP(A193+1,INDIRECT("'[" &Info!$B$4&"]"&Info!$B$5&"'!$A$6:$A$1000"),1,0),"") | C194: =IFERROR( IF(A194="","", VLOOKUP(A194,INDIRECT("'[" &Info!$B$4&"]"&Info!$B$5&"'!$A$6:$D$1000"),3,0)),"") | D194: =IF(C194="","", VLOOKUP(A194,INDIRECT("'[" &Info!$B$4&"]"&Info!$B$5&"'!$A$6:$T$1000"),20,0)) | E194: =IF(D194="","", VLOOKUP(A194,INDIRECT("'[" &Info!$B$4&"]"&Info!$B$5&"'!$A$6:$U$1000"),21,0)) | F194: =IF(D194="","", VLOOKUP(A194,INDIRECT("'[" &Info!$B$4&"]"&Info!$B$5&"'!$A$6:$U$1000"),21,0)) | G194: =IF(D194="","", VLOOKUP(A194,INDIRECT("'[" &Info!$B$4&"]"&Info!$B$5&"'!$A$6:$V$1000"),22,0)) | H194: =IF(D194="","", VLOOKUP(A194,INDIRECT("'[" &Info!$B$4&"]"&Info!$B$5&"'!$A$6:$W$1000"),23,0)) | I194: =LOWER( IF(D194="","", VLOOKUP(A194,INDIRECT("'[" &Info!$B$4&"]"&Info!$B$5&"'!$A$6:$y$1000"),25,0))) | J194: =IF(D194="","", VLOOKUP(A194,INDIRECT("'[" &Info!$B$4&"]"&Info!$B$5&"'!$A$6:$Z$1000"),26,0)) | K194: =IF(D194="","", VLOOKUP(A194,INDIRECT("'[" &Info!$B$4&"]"&Info!$B$5&"'!$A$6:$AA$1000"),27,0)) | L194: =IF(D194="","", VLOOKUP(A194,INDIRECT("'[" &Info!$B$4&"]"&Info!$B$5&"'!$A$6:$H$1000"),8,0)) | M194: =IF(D194="","", VLOOKUP(A194,INDIRECT("'[" &Info!$B$4&"]"&Info!$B$5&"'!$A$6:$F$1000"),6,0)) | N194: =IF(C194="","", VLOOKUP(A194,INDIRECT("'[" &Info!$B$4&"]"&Info!$B$5&"'!$A$6:$Au$1000"),47,0)) | O194: =IF(N194="","",IF(N194=0,0,VLOOKUP(A194,INDIRECT("'[" &Info!$B$4&"]"&Info!$B$5&"'!$A$6:$AH$1000"),34,0))) | P194: =IF(N194="","",IF(N194=0,0,VLOOKUP(A194,INDIRECT("'[" &Info!$B$4&"]"&Info!$B$5&"'!$A$6:$AW$1000"),49,0))) | Q194: =IF(N194="","",IF(N194=0,0, VLOOKUP(A194,INDIRECT("'[" &Info!$B$4&"]"&Info!$B$5&"'!$A$6:$AX$1000"),50,0))) | R194: =IF(N194="","",IF(N194=0,0, VLOOKUP(A194,INDIRECT("'[" &Info!$B$4&"]"&Info!$B$5&"'!$A$6:$AY$1000"),51,0))) | S194: =IF(N194="","",IF(N194=0,0,VLOOKUP(A194,INDIRECT("'[" &Info!$B$4&"]"&Info!$B$5&"'!$A$6:$Ai$1000"),35,0))) | T194: =IF(N194="","",IF(N194=0,0, VLOOKUP(A194,INDIRECT("'[" &Info!$B$4&"]"&Info!$B$5&"'!$A$6:$Az$1000"),52,0))) | U194: =IF(N194="","",IF(N194=0,0, VLOOKUP(A194,INDIRECT("'[" &Info!$B$4&"]"&Info!$B$5&"'!$A$6:$BA$1000"),53,0))) | V194: =IF(N194="","",IF(N194=0,0, VLOOKUP(A194,INDIRECT("'[" &Info!$B$4&"]"&Info!$B$5&"'!$A$6:$BB$1000"),54,0))) | W194: =IF(N194="","",O194+S194) | X194: =IF(N194="","",P194+T194) | Y194: =IF(N194="","",Q194+U194) | Z194: =IF(N194="","",R194+V194)
A195: =IFERROR( VLOOKUP(A194+1,INDIRECT("'[" &Info!$B$4&"]"&Info!$B$5&"'!$A$6:$A$1000"),1,0),"") | C195: =IFERROR( IF(A195="","", VLOOKUP(A195,INDIRECT("'[" &Info!$B$4&"]"&Info!$B$5&"'!$A$6:$D$1000"),3,0)),"") | D195: =IF(C195="","", VLOOKUP(A195,INDIRECT("'[" &Info!$B$4&"]"&Info!$B$5&"'!$A$6:$T$1000"),20,0)) | E195: =IF(D195="","", VLOOKUP(A195,INDIRECT("'[" &Info!$B$4&"]"&Info!$B$5&"'!$A$6:$U$1000"),21,0)) | F195: =IF(D195="","", VLOOKUP(A195,INDIRECT("'[" &Info!$B$4&"]"&Info!$B$5&"'!$A$6:$U$1000"),21,0)) | G195: =IF(D195="","", VLOOKUP(A195,INDIRECT("'[" &Info!$B$4&"]"&Info!$B$5&"'!$A$6:$V$1000"),22,0)) | H195: =IF(D195="","", VLOOKUP(A195,INDIRECT("'[" &Info!$B$4&"]"&Info!$B$5&"'!$A$6:$W$1000"),23,0)) | I195: =LOWER( IF(D195="","", VLOOKUP(A195,INDIRECT("'[" &Info!$B$4&"]"&Info!$B$5&"'!$A$6:$y$1000"),25,0))) | J195: =IF(D195="","", VLOOKUP(A195,INDIRECT("'[" &Info!$B$4&"]"&Info!$B$5&"'!$A$6:$Z$1000"),26,0)) | K195: =IF(D195="","", VLOOKUP(A195,INDIRECT("'[" &Info!$B$4&"]"&Info!$B$5&"'!$A$6:$AA$1000"),27,0)) | L195: =IF(D195="","", VLOOKUP(A195,INDIRECT("'[" &Info!$B$4&"]"&Info!$B$5&"'!$A$6:$H$1000"),8,0)) | M195: =IF(D195="","", VLOOKUP(A195,INDIRECT("'[" &Info!$B$4&"]"&Info!$B$5&"'!$A$6:$F$1000"),6,0)) | N195: =IF(C195="","", VLOOKUP(A195,INDIRECT("'[" &Info!$B$4&"]"&Info!$B$5&"'!$A$6:$Au$1000"),47,0)) | O195: =IF(N195="","",IF(N195=0,0,VLOOKUP(A195,INDIRECT("'[" &Info!$B$4&"]"&Info!$B$5&"'!$A$6:$AH$1000"),34,0))) | P195: =IF(N195="","",IF(N195=0,0,VLOOKUP(A195,INDIRECT("'[" &Info!$B$4&"]"&Info!$B$5&"'!$A$6:$AW$1000"),49,0))) | Q195: =IF(N195="","",IF(N195=0,0, VLOOKUP(A195,INDIRECT("'[" &Info!$B$4&"]"&Info!$B$5&"'!$A$6:$AX$1000"),50,0))) | R195: =IF(N195="","",IF(N195=0,0, VLOOKUP(A195,INDIRECT("'[" &Info!$B$4&"]"&Info!$B$5&"'!$A$6:$AY$1000"),51,0))) | S195: =IF(N195="","",IF(N195=0,0,VLOOKUP(A195,INDIRECT("'[" &Info!$B$4&"]"&Info!$B$5&"'!$A$6:$Ai$1000"),35,0))) | T195: =IF(N195="","",IF(N195=0,0, VLOOKUP(A195,INDIRECT("'[" &Info!$B$4&"]"&Info!$B$5&"'!$A$6:$Az$1000"),52,0))) | U195: =IF(N195="","",IF(N195=0,0, VLOOKUP(A195,INDIRECT("'[" &Info!$B$4&"]"&Info!$B$5&"'!$A$6:$BA$1000"),53,0))) | V195: =IF(N195="","",IF(N195=0,0, VLOOKUP(A195,INDIRECT("'[" &Info!$B$4&"]"&Info!$B$5&"'!$A$6:$BB$1000"),54,0))) | W195: =IF(N195="","",O195+S195) | X195: =IF(N195="","",P195+T195) | Y195: =IF(N195="","",Q195+U195) | Z195: =IF(N195="","",R195+V195)
